Workbook

Sheet Yakuniy
A1: PDP Academy · Xadra filiali (1, 2 va 3-qavat): jami xarajatlar — yakuniy
A2: Barcha summalar «Hisob (batafsil)» varag'idan formulalar bilan olinadi; so'm — «Narxlar» varag'idagi kurs bo'yicha.
A4: 1. Xarajat turlari bo'yicha
A5: № | B5: Xarajat turi | C5: Summa, $ | D5: Summa, so'm | E5: Ulush
A6: 1 | B6: Shisha devor | C6: =SUMIFS('Hisob (batafsil)'!$J$5:$J$371,'Hisob (batafsil)'!$C$5:$C$371,"Shisha devor") -> 7720.625 | D6: =C6*Narxlar!$C$58 -> 91875438 | E6: =IF($C$25=0,0,C6/$C$25) -> 0.088521591
A7: 2 | B7: Gips karton (GKL) | C7: =SUMIFS('Hisob (batafsil)'!$J$5:$J$371,'Hisob (batafsil)'!$C$5:$C$371,"Gips karton (GKL)") -> 4077.36 | D7: =C7*Narxlar!$C$58 -> 48520584 | E7: =IF($C$25=0,0,C7/$C$25) -> 0.046749375
A8: 3 | B8: Bambuk panel | C8: =SUMIFS('Hisob (batafsil)'!$J$5:$J$371,'Hisob (batafsil)'!$C$5:$C$371,"Bambuk panel") -> 8292.035 | D8: =C8*Narxlar!$C$58 -> 98675216 | E8: =IF($C$25=0,0,C8/$C$25) -> 0.095073149
A9: 4 | B9: Interaktiv doska | C9: =SUMIFS('Hisob (batafsil)'!$J$5:$J$371,'Hisob (batafsil)'!$C$5:$C$371,"Interaktiv doska") -> 8256 | D9: =C9*Narxlar!$C$58 -> 98246400 | E9: =IF($C$25=0,0,C9/$C$25) -> 0.094659986
A10: 5 | B10: Perila | C10: =SUMIFS('Hisob (batafsil)'!$J$5:$J$371,'Hisob (batafsil)'!$C$5:$C$371,"Perila") -> 2322.6 | D10: =C10*Narxlar!$C$58 -> 27638940 | E10: =IF($C$25=0,0,C10/$C$25) -> 0.02663
A11: 6 | B11: Yoritish | C11: =SUMIFS('Hisob (batafsil)'!$J$5:$J$371,'Hisob (batafsil)'!$C$5:$C$371,"Yoritish") -> 3024 | D11: =C11*Narxlar!$C$58 -> 35985600 | E11: =IF($C$25=0,0,C11/$C$25) -> 0.034671972
A12: 7 | B12: Kamera tizimi | C12: =SUMIFS('Hisob (batafsil)'!$J$5:$J$371,'Hisob (batafsil)'!$C$5:$C$371,"Kamera tizimi") -> 3438.5 | D12: =C12*Narxlar!$C$58 -> 40918150 | E12: =IF($C$25=0,0,C12/$C$25) -> 0.039424462
A13: 8 | B13: Logotip | C13: =SUMIFS('Hisob (batafsil)'!$J$5:$J$371,'Hisob (batafsil)'!$C$5:$C$371,"Logotip") -> 3250 | D13: =C13*Narxlar!$C$58 -> 38675000 | E13: =IF($C$25=0,0,C13/$C$25) -> 0.037263197
A14: 9 | B14: Matli plyonka | C14: =SUMIFS('Hisob (batafsil)'!$J$5:$J$371,'Hisob (batafsil)'!$C$5:$C$371,"Matli plyonka") -> 537.81513 | D14: =C14*Narxlar!$C$58 -> 6400000 | E14: =IF($C$25=0,0,C14/$C$25) -> 0.0061663726
A15: 10 | B15: Yong'in xavfsizligi | C15: =SUMIFS('Hisob (batafsil)'!$J$5:$J$371,'Hisob (batafsil)'!$C$5:$C$371,"Yong'in xavfsizligi") -> 1512.605 | D15: =C15*Narxlar!$C$58 -> 18000000 | E15: =IF($C$25=0,0,C15/$C$25) -> 0.017342923
A16: 11 | B16: Buzish ishlari | C16: =SUMIFS('Hisob (batafsil)'!$J$5:$J$371,'Hisob (batafsil)'!$C$5:$C$371,"Buzish ishlari") -> 340.54622 | D16: =C16*Narxlar!$C$58 -> 4052500 | E16: =IF($C$25=0,0,C16/$C$25) -> 0.0039045664
A17: 12 | B17: Santexnika | C17: =SUMIFS('Hisob (batafsil)'!$J$5:$J$371,'Hisob (batafsil)'!$C$5:$C$371,"Santexnika") -> 3317.6471 | D17: =C17*Narxlar!$C$58 -> 39480000 | E17: =IF($C$25=0,0,C17/$C$25) -> 0.038038811
A18: 13 | B18: Kafel | C18: =SUMIFS('Hisob (batafsil)'!$J$5:$J$371,'Hisob (batafsil)'!$C$5:$C$371,"Kafel") -> 1243.6975 | D18: =C18*Narxlar!$C$58 -> 14800000 | E18: =IF($C$25=0,0,C18/$C$25) -> 0.014259737
A19: 14 | B19: Konditsioner va ventilyatsiya | C19: =SUMIFS('Hisob (batafsil)'!$J$5:$J$371,'Hisob (batafsil)'!$C$5:$C$371,"Konditsioner va ventilyatsiya") -> 18061.765 | D19: =C19*Narxlar!$C$58 -> 214935000 | E19: =IF($C$25=0,0,C19/$C$25) -> 0.20708895
A20: 15 | B20: Mebel va interyer | C20: =SUMIFS('Hisob (batafsil)'!$J$5:$J$371,'Hisob (batafsil)'!$C$5:$C$371,"Mebel va interyer") -> 13100 | D20: =C20*Narxlar!$C$58 -> 155890000 | E20: =IF($C$25=0,0,C20/$C$25) -> 0.15019935
A21: 16 | B21: E'lon va e'tirof doskalari | C21: =SUMIFS('Hisob (batafsil)'!$J$5:$J$371,'Hisob (batafsil)'!$C$5:$C$371,"E'lon va e'tirof doskalari") -> 370 | D21: =C21*Narxlar!$C$58 -> 4403000 | E21: =IF($C$25=0,0,C21/$C$25) -> 0.0042422717
A22: 17 | B22: Eshiklar | C22: =SUMIFS('Hisob (batafsil)'!$J$5:$J$371,'Hisob (batafsil)'!$C$5:$C$371,"Eshiklar") -> 2350 | D22: =C22*Narxlar!$C$58 -> 27965000 | E22: =IF($C$25=0,0,C22/$C$25) -> 0.026944158
A23: 18 | B23: Internet va Wi-Fi | C23: =SUMIFS('Hisob (batafsil)'!$J$5:$J$371,'Hisob (batafsil)'!$C$5:$C$371,"Internet va Wi-Fi") -> 2737.563 | D23: =C23*Narxlar!$C$58 -> 32577000 | E23: =IF($C$25=0,0,C23/$C$25) -> 0.0313878
A24: 19 | B24: Elektr | C24: =SUMIFS('Hisob (batafsil)'!$J$5:$J$371,'Hisob (batafsil)'!$C$5:$C$371,"Elektr") -> 3264.6639 | D24: =C24*Narxlar!$C$58 -> 38849500 | E24: =IF($C$25=0,0,C24/$C$25) -> 0.037431327
B25: JAMI | C25: =SUM(C6:C24) -> 87217.423 | D25: =C25*Narxlar!$C$58 -> 1037887328 | E25: =SUM(E6:E24) -> 1
B26: ="Kutilmagan xarajatlar ("&TEXT(Narxlar!$C$132,"0%")&")" -> Kutilmagan xarajatlar (10%) | C26: =C25*Narxlar!$C$132 -> 8721.7423 | D26: =C26*Narxlar!$C$58 -> 1.0378873e+08
B27: UMUMIY JAMI | C27: =C25+C26 -> 95939.165 | D27: =C27*Narxlar!$C$58 -> 1.1416761e+09
B28: shundan taxminiy narxlar (mebel, interyer, koworking sahnasi, koridor oxiri dekori, doskalar, 1-qavat logotiplari, kanalli konditsionerlar, diffuzor va panjaralar, eshik mexanizmlari) — kutilmagan xarajatsiz | C28: =SUMIFS('Hisob (batafsil)'!$J$5:$J$371,'Hisob (batafsil)'!$K$5:$K$371,"poeSw")+SUMIFS('Hisob (batafsil)'!$J$5:$J$371,'Hisob (batafsil)'!$K$5:$K$371,"shkaf18")+SUMIFS('Hisob (batafsil)'!$J$5:$J$371,'Hisob (batafsil)'!$K$5:$K$371,"ups")+SUMIFS('Hisob (batafsil)'!$J$5:$J$371,'Hisob (batafsil)'!$K$5:$K$371,"router")+SUMIFS('Hisob (batafsil)'!$J$5:$J$371,'Hisob (batafsil)'!$K$5:$K$371,"sw48")+SUMIFS('Hisob (batafsil)'!$J$5:$J$371,'Hisob (batafsil)'!$K$5:$K$371,"patch")+SUMIFS('Hisob (batafsil)'!$J$5:$J$371,'Hisob (batafsil)'!$K$5:$K$371,"rj45")+SUMIFS('Hisob (batafsil)'!$J$5:$J$371,'Hisob (batafsil)'!$K$5:$K$371,"ap")+SUMIFS('Hisob (batafsil)'!$J$5:$J$371,'Hisob (batafsil)'!$K$5:$K$371,"cat6")+SUMIFS('Hisob (batafsil)'!$J$5:$J$371,'Hisob (batafsil)'!$K$5:$K$371,"netMontaj")+SUMIFS('Hisob (batafsil)'!$J$5:$J$371,'Hisob (batafsil)'!$K$5:$K$371,"lotok")+SUMIFS('Hisob (batafsil)'!$J$5:$J$371,'Hisob (batafsil)'!$K$5:$K$371,"k25")+SUMIFS('Hisob (batafsil)'!$J$5:$J$371,'Hisob (batafsil)'!$K$5:$K$371,"k15")+SUMIFS('Hisob (batafsil)'!$J$5:$J$371,'Hisob (batafsil)'!$K$5:$K$371,"k54")+SUMIFS('Hisob (batafsil)'!$J$5:$J$371,'Hisob (batafsil)'!$K$5:$K$371,"gofra")+SUMIFS('Hisob (batafsil)'!$J$5:$J$371,'Hisob (batafsil)'!$K$5:$K$371,"rozetka")+SUMIFS('Hisob (batafsil)'!$J$5:$J$371,'Hisob (batafsil)'!$K$5:$K$371,"vykl")+SUMIFS('Hisob (batafsil)'!$J$5:$J$371,'Hisob (batafsil)'!$K$5:$K$371,"difavt")+SUMIFS('Hisob (batafsil)'!$J$5:$J$371,'Hisob (batafsil)'!$K$5:$K$371,"avt1")+SUMIFS('Hisob (batafsil)'!$J$5:$J$371,'Hisob (batafsil)'!$K$5:$K$371,"avt3")+SUMIFS('Hisob (batafsil)'!$J$5:$J$371,'Hisob (batafsil)'!$K$5:$K$371,"shitQuti")+SUMIFS('Hisob (batafsil)'!$J$5:$J$371,'Hisob (batafsil)'!$K$5:$K$371,"elMontaj")+SUMIFS('Hisob (batafsil)'!$J$5:$J$371,'Hisob (batafsil)'!$K$5:$K$371,"kk")+SUMIFS('Hisob (batafsil)'!$J$5:$J$371,'Hisob (batafsil)'!$K$5:$K$371,"diffuzor")+SUMIFS('Hisob (batafsil)'!$J$5:$J$371,'Hisob (batafsil)'!$K$5:$K$371,"sorPanjara")+SUMIFS('Hisob (batafsil)'!$J$5:$J$371,'Hisob (batafsil)'!$K$5:$K$371,"qPanjara")+SUMIFS('Hisob (batafsil)'!$J$5:$J$371,'Hisob (batafsil)'!$K$5:$K$371,"vv")+SUMIFS('Hisob (batafsil)'!$J$5:$J$371,'Hisob (batafsil)'!$K$5:$K$371,"surmaMex")+SUMIFS('Hisob (batafsil)'!$J$5:$J$371,'Hisob (batafsil)'!$K$5:$K$371,"eshKL")+SUMIFS('Hisob (batafsil)'!$J$5:$J$371,'Hisob (batafsil)'!$K$5:$K$371,"stolOfis")+SUMIFS('Hisob (batafsil)'!$J$5:$J$371,'Hisob (batafsil)'!$K$5:$K$371,"kreslo")+SUMIFS('Hisob (batafsil)'!$J$5:$J$371,'Hisob (batafsil)'!$K$5:$K$371,"mijozStul")+SUMIFS('Hisob (batafsil)'!$J$5:$J$371,'Hisob (batafsil)'!$K$5:$K$371,"divan")+SUMIFS('Hisob (batafsil)'!$J$5:$J$371,'Hisob (batafsil)'!$K$5:$K$371,"shkaf")+SUMIFS('Hisob (batafsil)'!$J$5:$J$371,'Hisob (batafsil)'!$K$5:$K$371,"stolcha")+SUMIFS('Hisob (batafsil)'!$J$5:$J$371,'Hisob (batafsil)'!$K$5:$K$371,"interyerXZ1")+SUMIFS('Hisob (batafsil)'!$J$5:$J$371,'Hisob (batafsil)'!$K$5:$K$371,"interyerXZ2")+SUMIFS('Hisob (batafsil)'!$J$5:$J$371,'Hisob (batafsil)'!$K$5:$K$371,"elonDoska")+SUMIFS('Hisob (batafsil)'!$J$5:$J$371,'Hisob (batafsil)'!$K$5:$K$371,"etirofDoska")+SUMIFS('Hisob (batafsil)'!$J$5:$J$371,'Hisob (batafsil)'!$K$5:$K$371,"resepshn")+SUMIFS('Hisob (batafsil)'!$J$5:$J$371,'Hisob (batafsil)'!$K$5:$K$371,"resepshnPanel")+SUMIFS('Hisob (batafsil)'!$J$5:$J$371,'Hisob (batafsil)'!$K$5:$K$371,"logoDevor1")+SUMIFS('Hisob (batafsil)'!$J$5:$J$371,'Hisob (batafsil)'!$K$5:$K$371,"logoStol1")+SUMIFS('Hisob (batafsil)'!$J$5:$J$371,'Hisob (batafsil)'!$K$5:$K$371,"sahnaDevor")+SUMIFS('Hisob (batafsil)'!$J$5:$J$371,'Hisob (batafsil)'!$K$5:$K$371,"sahnaReyka")+SUMIFS('Hisob (batafsil)'!$J$5:$J$371,'Hisob (batafsil)'!$K$5:$K$371,"sahnaLogo")+SUMIFS('Hisob (batafsil)'!$J$5:$J$371,'Hisob (batafsil)'!$K$5:$K$371,"sahnaYor")+SUMIFS('Hisob (batafsil)'!$J$5:$J$371,'Hisob (batafsil)'!$K$5:$K$371,"sahnaEkran")+SUMIFS('Hisob (batafsil)'!$J$5:$J$371,'Hisob (batafsil)'!$K$5:$K$371,"sahnaAudio")+SUMIFS('Hisob (batafsil)'!$J$5:$J$371,'Hisob (batafsil)'!$K$5:$K$371,"sahnaPol")+SUMIFS('Hisob (batafsil)'!$J$5:$J$371,'Hisob (batafsil)'!$K$5:$K$371,"minbar")+SUMIFS('Hisob (batafsil)'!$J$5:$J$371,'Hisob (batafsil)'!$K$5:$K$371,"sahnaOsimlik")+SUMIFS('Hisob (batafsil)'!$J$5:$J$371,'Hisob (batafsil)'!$K$5:$K$371,"korMarmar")+SUMIFS('Hisob (batafsil)'!$J$5:$J$371,'Hisob (batafsil)'!$K$5:$K$371,"korMox")+SUMIFS('Hisob (batafsil)'!$J$5:$J$371,'Hisob (batafsil)'!$K$5:$K$371,"korReyka")+SUMIFS('Hisob (batafsil)'!$J$5:$J$371,'Hisob (batafsil)'!$K$5:$K$371,"korYashil") -> 35902.227 | D28: =C28*Narxlar!$C$58 -> 427236500
A30: 2. Qavat va bo'limlar bo'yicha
A31: № | B31: Bo'lim | C31: Summa, $ | D31: Summa, so'm | E31: Ulush
A32: 1 | B32: 1-qavat: kirish zali | C32: ='Xonalar bo''yicha'!$Z$7 -> 3430 | D32: =C32*Narxlar!$C$58 -> 40817000 | E32: =IF($C$37=0,0,C32/$C$37) -> 0.039327005
A33: 2 | B33: 2-qavat: o'quv xonalari | C33: ='Xonalar bo''yicha'!$Z$17 -> 21453.31 | D33: =C33*Narxlar!$C$58 -> 255294389 | E33: =IF($C$37=0,0,C33/$C$37) -> 0.24597505
A34: 3 | B34: 2-qavat: ofis xonalari | C34: ='Xonalar bo''yicha'!$Z$25 -> 10760.58 | D34: =C34*Narxlar!$C$58 -> 128050902 | E34: =IF($C$37=0,0,C34/$C$37) -> 0.1233765
A35: 4 | B35: 2-qavat: umumiy joylar | C35: ='Xonalar bo''yicha'!$Z$36 -> 44014.458 | D35: =C35*Narxlar!$C$58 -> 523772050 | E35: =IF($C$37=0,0,C35/$C$37) -> 0.50465213
A36: 5 | B36: 3-qavat va hojatxonalar | C36: ='Xonalar bo''yicha'!$Z$41 -> 7559.0745 | D36: =C36*Narxlar!$C$58 -> 89952987 | E36: =IF($C$37=0,0,C36/$C$37) -> 0.086669318
B37: JAMI | C37: =SUM(C32:C36) -> 87217.423 | D37: =C37*Narxlar!$C$58 -> 1037887328 | E37: =SUM(E32:E36) -> 1
B39: Tekshiruv: ikki jadval jamisi farqi (0 bo'lishi kerak) | C39: =C25-C37 -> 0
B40: Dollar kursi (so'm/$) — «Narxlar» varag'idan | C40: =Narxlar!$C$58 -> 11900

Sheet Fazalar
A1: PDP Academy · Xadra filiali: xarajatlar fazalar bo'yicha — ishlar ketma-ketligi, sanalar va pul oqimi
A2: Boshlanish sanasini (ko'k) o'zgartirsangiz, barcha sanalar qayta hisoblanadi. Ish haftasi — dushanba–shanba, bayramlar chiqariladi. Summalar «Hisob (batafsil)» dan, fazalarga ulush bilan (pastdagi 3-jadval; ko'k ulushlarni o'zgartirish mumkin).
B4: Boshlanish sanasi | C4: 46314 | D4: Taxmin: ruxsat va shartnomalardan keyingi dushanba — aniq sana bilan almashtiring
B5: Bayramlar (ish kuni emas) | C5: 46364 | D5: 46387 | E5: 46388 | F5: 46389
A7: 1. Fazalar: ishlar va sanalar
A8: Faza | B8: Nomi | C8: Ishlar | D8: Ish kuni | E8: Boshlanishi | F8: Tugashi | G8: Xarajat, $ | H8: Kutilmagan, $ | I8: Jami, $ | J8: Jami, so'm | K8: Ulush | L8: Yig'ma, $
A9: F0 | B9: Tayyorgarlik va buyurtmalar | C9: Ijaraga beruvchining yozma roziligi (devor buzish, tomga tashqi bloklar); joyida o'lchov (oynalar, ustunlar, tom); pudratchilar bilan shartnomalar; uzoq tayyorlanadigan buyurtmalar — kanalli konditsionerlar, mebel va resepshn, logotiplar (avans) | D9: 6 | E9: =WORKDAY.INTL($C$4-1,1,"0000001",$C$5:$F$5) -> 46314 | F9: =WORKDAY.INTL(E9,D9-1,"0000001",$C$5:$F$5) -> 46319 | G9: =L129 -> 10520 | H9: =G9*Narxlar!$C$132 -> 1052 | I9: =G9+H9 -> 11572 | J9: =I9*Narxlar!$C$58 -> 137706800 | K9: =IF($I$15=0,0,I9/$I$15) -> 0.1206181 | L9: =SUM($I$9:I9) -> 11572
A10: F1 | B10: Buzish ishlari | C10: Eski devorlarni buzish, qurilish chiqindisini olib chiqish; pol, oyna va eshiklarni himoyalash | D10: 4 | E10: =WORKDAY.INTL(F9,1,"0000001",$C$5:$F$5) -> 46321 | F10: =WORKDAY.INTL(E10,D10-1,"0000001",$C$5:$F$5) -> 46324 | G10: =M129 -> 340.54622 | H10: =G10*Narxlar!$C$132 -> 34.054622 | I10: =G10+H10 -> 374.60084 | J10: =I10*Narxlar!$C$58 -> 4457750 | K10: =IF($I$15=0,0,I10/$I$15) -> 0.0039045664 | L10: =SUM($I$9:I10) -> 11946.601
A11: F2 | B11: Qora ishlar va muhandislik tarmoqlari | C11: GKL karkaslar va birinchi tomoni; elektr (yoritish, konditsioner liniyalari, kamera va yong'in signalizatsiyasi kabellari); santexnika quvurlari va nuqtalari; kanalli konditsionerlar (kladovka shifti ustida), vitechka ventilyatori, havo kanallari, freon trassalari va drenaj — shift yopilishidan oldin; tashqi blok tayanch ramalari | D11: 12 | E11: =WORKDAY.INTL(F10,1,"0000001",$C$5:$F$5) -> 46325 | F11: =WORKDAY.INTL(E11,D11-1,"0000001",$C$5:$F$5) -> 46338 | G11: =N129 -> 18139.609 | H11: =G11*Narxlar!$C$132 -> 1813.9609 | I11: =G11+H11 -> 19953.569 | J11: =I11*Narxlar!$C$58 -> 2.3744748e+08 | K11: =IF($I$15=0,0,I11/$I$15) -> 0.20798148 | L11: =SUM($I$9:I11) -> 31900.17
A12: F3 | B12: Pardoz ishlari | C12: GKL ikkinchi tomoni, shpaklyovka, bo'yoq; hojatxona kafeli; bambuk panellar; sahna poli; shisha devorlar o'lchovi va buyurtmasi (avans) | D12: 10 | E12: =WORKDAY.INTL(F11,1,"0000001",$C$5:$F$5) -> 46339 | F12: =WORKDAY.INTL(E12,D12-1,"0000001",$C$5:$F$5) -> 46350 | G12: =O129 -> 17034.725 | H12: =G12*Narxlar!$C$132 -> 1703.4725 | I12: =G12+H12 -> 18738.197 | J12: =I12*Narxlar!$C$58 -> 2.2298455e+08 | K12: =IF($I$15=0,0,I12/$I$15) -> 0.19531333 | L12: =SUM($I$9:I12) -> 50638.368
A13: F4 | B13: O'rnatish ishlari | C13: Shisha devor va suriladigan eshiklar, kladovka eshiklari, perila, yoritish, diffuzor va panjaralar, santexnika jihozlari va kabinalar, kameralar va NVR, yong'in signalizatsiyasi asboblari, interaktiv doskalar, matli plyonka, sahna yoritishi va ekran | D13: 10 | E13: =WORKDAY.INTL(F12,1,"0000001",$C$5:$F$5) -> 46351 | F13: =WORKDAY.INTL(E13,D13-1,"0000001",$C$5:$F$5) -> 46361 | G13: =P129 -> 32442.543 | H13: =G13*Narxlar!$C$132 -> 3244.2543 | I13: =G13+H13 -> 35686.797 | J13: =I13*Narxlar!$C$58 -> 4.2467288e+08 | K13: =IF($I$15=0,0,I13/$I$15) -> 0.37197319 | L13: =SUM($I$9:I13) -> 86325.165
A14: F5 | B14: Mebel, brending va ishga tushirish | C14: Mebel va resepshn (qoldiq), logotiplar, e'lon va e'tirof doskalari, sahna reykalari, ovoz, minbar; HVAC sozlash va sinov, yong'in xavfsizligi qabuli, tozalash | D14: 6 | E14: =WORKDAY.INTL(F13,1,"0000001",$C$5:$F$5) -> 46363 | F14: =WORKDAY.INTL(E14,D14-1,"0000001",$C$5:$F$5) -> 46370 | G14: =Q129 -> 8740 | H14: =G14*Narxlar!$C$132 -> 874 | I14: =G14+H14 -> 9614 | J14: =I14*Narxlar!$C$58 -> 114406600 | K14: =IF($I$15=0,0,I14/$I$15) -> 0.10020934 | L14: =SUM($I$9:I14) -> 95939.165
B15: JAMI | D15: =SUM(D9:D14) -> 48 | E15: =E9 -> 46314 | F15: =F14 -> 46370 | G15: =SUM(G9:G14) -> 87217.423 | H15: =SUM(H9:H14) -> 8721.7423 | I15: =SUM(I9:I14) -> 95939.165 | J15: =I15*Narxlar!$C$58 -> 1.1416761e+09 | K15: =SUM(K9:K14) -> 1
B16: Tekshiruv: «Yakuniy» UMUMIY JAMI bilan farq (0 bo'lishi kerak) | I16: =I15-Yakuniy!$C$27 -> 0
B17: Kalendar kunlar (boshlanishdan tugashgacha) | D17: =F15-E15+1 -> 57
A19: 2. Haftalik grafik (rangli — faza ishlaydigan hafta)
A20: Faza | B20: Hafta boshi (dushanba) | C20: =$C$4-WEEKDAY($C$4,2)+1+7*0 -> 46314 | D20: =$C$4-WEEKDAY($C$4,2)+1+7*1 -> 46321 | E20: =$C$4-WEEKDAY($C$4,2)+1+7*2 -> 46328 | F20: =$C$4-WEEKDAY($C$4,2)+1+7*3 -> 46335 | G20: =$C$4-WEEKDAY($C$4,2)+1+7*4 -> 46342 | H20: =$C$4-WEEKDAY($C$4,2)+1+7*5 -> 46349 | I20: =$C$4-WEEKDAY($C$4,2)+1+7*6 -> 46356 | J20: =$C$4-WEEKDAY($C$4,2)+1+7*7 -> 46363 | K20: =$C$4-WEEKDAY($C$4,2)+1+7*8 -> 46370 | L20: =$C$4-WEEKDAY($C$4,2)+1+7*9 -> 46377
A21: F0 | B21: Tayyorgarlik va buyurtmalar | C21: =IF(AND($E$9<=C$20+6,$F$9>=C$20),1,0) -> 1 | D21: =IF(AND($E$9<=D$20+6,$F$9>=D$20),1,0) -> 0 | E21: =IF(AND($E$9<=E$20+6,$F$9>=E$20),1,0) -> 0 | F21: =IF(AND($E$9<=F$20+6,$F$9>=F$20),1,0) -> 0 | G21: =IF(AND($E$9<=G$20+6,$F$9>=G$20),1,0) -> 0 | H21: =IF(AND($E$9<=H$20+6,$F$9>=H$20),1,0) -> 0 | I21: =IF(AND($E$9<=I$20+6,$F$9>=I$20),1,0) -> 0 | J21: =IF(AND($E$9<=J$20+6,$F$9>=J$20),1,0) -> 0 | ... L21: =IF(AND($E$9<=L$20+6,$F$9>=L$20),1,0) -> 0
A22: F1 | B22: Buzish ishlari | C22: =IF(AND($E$10<=C$20+6,$F$10>=C$20),1,0) -> 0 | D22: =IF(AND($E$10<=D$20+6,$F$10>=D$20),1,0) -> 1 | E22: =IF(AND($E$10<=E$20+6,$F$10>=E$20),1,0) -> 0 | F22: =IF(AND($E$10<=F$20+6,$F$10>=F$20),1,0) -> 0 | G22: =IF(AND($E$10<=G$20+6,$F$10>=G$20),1,0) -> 0 | H22: =IF(AND($E$10<=H$20+6,$F$10>=H$20),1,0) -> 0 | I22: =IF(AND($E$10<=I$20+6,$F$10>=I$20),1,0) -> 0 | J22: =IF(AND($E$10<=J$20+6,$F$10>=J$20),1,0) -> 0 | ... L22: =IF(AND($E$10<=L$20+6,$F$10>=L$20),1,0) -> 0
A23: F2 | B23: Qora ishlar va muhandislik tarmoqlari | C23: =IF(AND($E$11<=C$20+6,$F$11>=C$20),1,0) -> 0 | D23: =IF(AND($E$11<=D$20+6,$F$11>=D$20),1,0) -> 1 | E23: =IF(AND($E$11<=E$20+6,$F$11>=E$20),1,0) -> 1 | F23: =IF(AND($E$11<=F$20+6,$F$11>=F$20),1,0) -> 1 | G23: =IF(AND($E$11<=G$20+6,$F$11>=G$20),1,0) -> 0 | H23: =IF(AND($E$11<=H$20+6,$F$11>=H$20),1,0) -> 0 | I23: =IF(AND($E$11<=I$20+6,$F$11>=I$20),1,0) -> 0 | J23: =IF(AND($E$11<=J$20+6,$F$11>=J$20),1,0) -> 0 | ... L23: =IF(AND($E$11<=L$20+6,$F$11>=L$20),1,0) -> 0
A24: F3 | B24: Pardoz ishlari | C24: =IF(AND($E$12<=C$20+6,$F$12>=C$20),1,0) -> 0 | D24: =IF(AND($E$12<=D$20+6,$F$12>=D$20),1,0) -> 0 | E24: =IF(AND($E$12<=E$20+6,$F$12>=E$20),1,0) -> 0 | F24: =IF(AND($E$12<=F$20+6,$F$12>=F$20),1,0) -> 1 | G24: =IF(AND($E$12<=G$20+6,$F$12>=G$20),1,0) -> 1 | H24: =IF(AND($E$12<=H$20+6,$F$12>=H$20),1,0) -> 1 | I24: =IF(AND($E$12<=I$20+6,$F$12>=I$20),1,0) -> 0 | J24: =IF(AND($E$12<=J$20+6,$F$12>=J$20),1,0) -> 0 | ... L24: =IF(AND($E$12<=L$20+6,$F$12>=L$20),1,0) -> 0
A25: F4 | B25: O'rnatish ishlari | C25: =IF(AND($E$13<=C$20+6,$F$13>=C$20),1,0) -> 0 | D25: =IF(AND($E$13<=D$20+6,$F$13>=D$20),1,0) -> 0 | E25: =IF(AND($E$13<=E$20+6,$F$13>=E$20),1,0) -> 0 | F25: =IF(AND($E$13<=F$20+6,$F$13>=F$20),1,0) -> 0 | G25: =IF(AND($E$13<=G$20+6,$F$13>=G$20),1,0) -> 0 | H25: =IF(AND($E$13<=H$20+6,$F$13>=H$20),1,0) -> 1 | I25: =IF(AND($E$13<=I$20+6,$F$13>=I$20),1,0) -> 1 | J25: =IF(AND($E$13<=J$20+6,$F$13>=J$20),1,0) -> 0 | ... L25: =IF(AND($E$13<=L$20+6,$F$13>=L$20),1,0) -> 0
A26: F5 | B26: Mebel, brending va ishga tushirish | C26: =IF(AND($E$14<=C$20+6,$F$14>=C$20),1,0) -> 0 | D26: =IF(AND($E$14<=D$20+6,$F$14>=D$20),1,0) -> 0 | E26: =IF(AND($E$14<=E$20+6,$F$14>=E$20),1,0) -> 0 | F26: =IF(AND($E$14<=F$20+6,$F$14>=F$20),1,0) -> 0 | G26: =IF(AND($E$14<=G$20+6,$F$14>=G$20),1,0) -> 0 | H26: =IF(AND($E$14<=H$20+6,$F$14>=H$20),1,0) -> 0 | I26: =IF(AND($E$14<=I$20+6,$F$14>=I$20),1,0) -> 0 | J26: =IF(AND($E$14<=J$20+6,$F$14>=J$20),1,0) -> 1 | ... L26: =IF(AND($E$14<=L$20+6,$F$14>=L$20),1,0) -> 0
A28: Oylik pul oqimi: faza summasi uning kalendar kunlariga teng taqsimlanadi (avanslar faza boshida to'lanishini hisobga oling)
A29: Faza | B29: Oy | C29: =EDATE(DATE(YEAR($C$4),MONTH($C$4),1),0) -> 46296 | D29: =EDATE(DATE(YEAR($C$4),MONTH($C$4),1),1) -> 46327 | E29: =EDATE(DATE(YEAR($C$4),MONTH($C$4),1),2) -> 46357 | F29: =EDATE(DATE(YEAR($C$4),MONTH($C$4),1),3) -> 46388
A30: F0 | B30: Tayyorgarlik va buyurtmalar | C30: =$I$9*MAX(0,MIN($F$9,EOMONTH(C$29,0))-MAX($E$9,C$29)+1)/($F$9-$E$9+1) -> 11572 | D30: =$I$9*MAX(0,MIN($F$9,EOMONTH(D$29,0))-MAX($E$9,D$29)+1)/($F$9-$E$9+1) -> 0 | E30: =$I$9*MAX(0,MIN($F$9,EOMONTH(E$29,0))-MAX($E$9,E$29)+1)/($F$9-$E$9+1) -> 0 | F30: =$I$9*MAX(0,MIN($F$9,EOMONTH(F$29,0))-MAX($E$9,F$29)+1)/($F$9-$E$9+1) -> 0
A31: F1 | B31: Buzish ishlari | C31: =$I$10*MAX(0,MIN($F$10,EOMONTH(C$29,0))-MAX($E$10,C$29)+1)/($F$10-$E$10+1) -> 374.60084 | D31: =$I$10*MAX(0,MIN($F$10,EOMONTH(D$29,0))-MAX($E$10,D$29)+1)/($F$10-$E$10+1) -> 0 | E31: =$I$10*MAX(0,MIN($F$10,EOMONTH(E$29,0))-MAX($E$10,E$29)+1)/($F$10-$E$10+1) -> 0 | F31: =$I$10*MAX(0,MIN($F$10,EOMONTH(F$29,0))-MAX($E$10,F$29)+1)/($F$10-$E$10+1) -> 0
A32: F2 | B32: Qora ishlar va muhandislik tarmoqlari | C32: =$I$11*MAX(0,MIN($F$11,EOMONTH(C$29,0))-MAX($E$11,C$29)+1)/($F$11-$E$11+1) -> 2850.5099 | D32: =$I$11*MAX(0,MIN($F$11,EOMONTH(D$29,0))-MAX($E$11,D$29)+1)/($F$11-$E$11+1) -> 17103.06 | E32: =$I$11*MAX(0,MIN($F$11,EOMONTH(E$29,0))-MAX($E$11,E$29)+1)/($F$11-$E$11+1) -> 0 | F32: =$I$11*MAX(0,MIN($F$11,EOMONTH(F$29,0))-MAX($E$11,F$29)+1)/($F$11-$E$11+1) -> 0
A33: F3 | B33: Pardoz ishlari | C33: =$I$12*MAX(0,MIN($F$12,EOMONTH(C$29,0))-MAX($E$12,C$29)+1)/($F$12-$E$12+1) -> 0 | D33: =$I$12*MAX(0,MIN($F$12,EOMONTH(D$29,0))-MAX($E$12,D$29)+1)/($F$12-$E$12+1) -> 18738.197 | E33: =$I$12*MAX(0,MIN($F$12,EOMONTH(E$29,0))-MAX($E$12,E$29)+1)/($F$12-$E$12+1) -> 0 | F33: =$I$12*MAX(0,MIN($F$12,EOMONTH(F$29,0))-MAX($E$12,F$29)+1)/($F$12-$E$12+1) -> 0
A34: F4 | B34: O'rnatish ishlari | C34: =$I$13*MAX(0,MIN($F$13,EOMONTH(C$29,0))-MAX($E$13,C$29)+1)/($F$13-$E$13+1) -> 0 | D34: =$I$13*MAX(0,MIN($F$13,EOMONTH(D$29,0))-MAX($E$13,D$29)+1)/($F$13-$E$13+1) -> 19465.526 | E34: =$I$13*MAX(0,MIN($F$13,EOMONTH(E$29,0))-MAX($E$13,E$29)+1)/($F$13-$E$13+1) -> 16221.271 | F34: =$I$13*MAX(0,MIN($F$13,EOMONTH(F$29,0))-MAX($E$13,F$29)+1)/($F$13-$E$13+1) -> 0
A35: F5 | B35: Mebel, brending va ishga tushirish | C35: =$I$14*MAX(0,MIN($F$14,EOMONTH(C$29,0))-MAX($E$14,C$29)+1)/($F$14-$E$14+1) -> 0 | D35: =$I$14*MAX(0,MIN($F$14,EOMONTH(D$29,0))-MAX($E$14,D$29)+1)/($F$14-$E$14+1) -> 0 | E35: =$I$14*MAX(0,MIN($F$14,EOMONTH(E$29,0))-MAX($E$14,E$29)+1)/($F$14-$E$14+1) -> 9614 | F35: =$I$14*MAX(0,MIN($F$14,EOMONTH(F$29,0))-MAX($E$14,F$29)+1)/($F$14-$E$14+1) -> 0
B36: Jami, $ | C36: =SUM(C30:C35) -> 14797.111 | D36: =SUM(D30:D35) -> 55306.783 | E36: =SUM(E30:E35) -> 25835.271 | F36: =SUM(F30:F35) -> 0
B37: Jami, so'm | C37: =C36*Narxlar!$C$58 -> 1.7608562e+08 | D37: =D36*Narxlar!$C$58 -> 6.5815071e+08 | E37: =E36*Narxlar!$C$58 -> 3.0743973e+08 | F37: =F36*Narxlar!$C$58 -> 0
A39: 3. Xarajatlarning fazalarga taqsimoti (ulush — ko'k, o'zgartirish mumkin; har qatorda jami 100%)
A40: Kalit | B40: Xarajat | C40: Turi | D40: Jami, $ | E40: F0, % | F40: F1, % | G40: F2, % | H40: F3, % | I40: F4, % | J40: F5, % | K40: Σ % | L40: F0, $ | M40: F1, $ | N40: F2, $ | O40: F3, $ | P40: F4, $ | Q40: F5, $
A41: logoDevor1 | B41: 1-qavat: devordagi yorituvchi logotip ~1.5 m (to'q panelda) | C41: Logotip | D41: =SUMIFS('Hisob (batafsil)'!$J$5:$J$371,'Hisob (batafsil)'!$K$5:$K$371,$A41) -> 500 | E41: 0.5 | F41: 0 | G41: 0 | H41: 0 | I41: 0 | J41: 0.5 | K41: =SUM(E41:J41) -> 1 | L41: =$D41*E41 -> 250 | M41: =$D41*F41 -> 0 | N41: =$D41*G41 -> 0 | O41: =$D41*H41 -> 0 | P41: =$D41*I41 -> 0 | Q41: =$D41*J41 -> 250
A42: logoStol1 | B42: 1-qavat: resepshn stoykasidagi logotip ~1.0 m (yoritilgan) | C42: Logotip | D42: =SUMIFS('Hisob (batafsil)'!$J$5:$J$371,'Hisob (batafsil)'!$K$5:$K$371,$A42) -> 250 | E42: 0.5 | F42: 0 | G42: 0 | H42: 0 | I42: 0 | J42: 0.5 | K42: =SUM(E42:J42) -> 1 | L42: =$D42*E42 -> 125 | M42: =$D42*F42 -> 0 | N42: =$D42*G42 -> 0 | O42: =$D42*H42 -> 0 | P42: =$D42*I42 -> 0 | Q42: =$D42*J42 -> 125
A43: logo | B43: Logotiplar — 2-qavat (jami) | C43: Logotip | D43: =SUMIFS('Hisob (batafsil)'!$J$5:$J$371,'Hisob (batafsil)'!$K$5:$K$371,$A43) -> 2500 | E43: 0.5 | F43: 0 | G43: 0 | H43: 0 | I43: 0 | J43: 0.5 | K43: =SUM(E43:J43) -> 1 | L43: =$D43*E43 -> 1250 | M43: =$D43*F43 -> 0 | N43: =$D43*G43 -> 0 | O43: =$D43*H43 -> 0 | P43: =$D43*I43 -> 0 | Q43: =$D43*J43 -> 1250
A44: kk | B44: Kanalli konditsioner 96 000 BTU (ichki kanalli blok, tashqi blok, tashqi havo aralashtirish kamerasi) | C44: Konditsioner va ventilyatsiya | D44: =SUMIFS('Hisob (batafsil)'!$J$5:$J$371,'Hisob (batafsil)'!$K$5:$K$371,$A44) -> 10000 | E44: 0.5 | F44: 0 | G44: 0.5 | H44: 0 | I44: 0 | J44: 0 | K44: =SUM(E44:J44) -> 1 | L44: =$D44*E44 -> 5000 | M44: =$D44*F44 -> 0 | N44: =$D44*G44 -> 5000 | O44: =$D44*H44 -> 0 | P44: =$D44*I44 -> 0 | Q44: =$D44*J44 -> 0
A45: resepshn | B45: Resepshn stoykasi 1.8 m (buyurtma: peshtaxta 1.10 m, zal tomonidagi panelda logotip uchun joy) | C45: Mebel va interyer | D45: =SUMIFS('Hisob (batafsil)'!$J$5:$J$371,'Hisob (batafsil)'!$K$5:$K$371,$A45) -> 1500 | E45: 0.5 | F45: 0 | G45: 0 | H45: 0 | I45: 0 | J45: 0.5 | K45: =SUM(E45:J45) -> 1 | L45: =$D45*E45 -> 750 | M45: =$D45*F45 -> 0 | N45: =$D45*G45 -> 0 | O45: =$D45*H45 -> 0 | P45: =$D45*I45 -> 0 | Q45: =$D45*J45 -> 750
...

Sheet Xonalar bo'yicha
A1: PDP Academy · Xadra filiali (1, 2 va 3-qavat): xarajatlar, xonalar bo'yicha
A2: Har bir qator «Hisob (batafsil)» varag'idan olinadi (SUMIFS). Narxlarni «Narxlar» varag'ida o'zgartiring.
A4: Xona | B4: Shisha (devor va eshik), m² | C4: Shisha (devor va eshik), $ | D4: Gips karton (GKL), m² | E4: Gips karton (GKL), $ | F4: Bambuk panel, m² | G4: Bambuk panel, $ | H4: Interaktiv doska, dona | I4: Interaktiv doska, $ | J4: Perila, m | K4: Perila, $ | L4: Yoritish, $ | M4: Kamera tizimi, $ | N4: Logotip, $ | O4: Matli plyonka, $ | P4: Yong'in xavfsizligi, $ | Q4: Buzish ishlari, $ | R4: Santexnika, $ | S4: Kafel, $ | T4: Konditsioner va ventilyatsiya, $ | U4: Mebel va interyer (taxmin), $ | V4: E'lon va e'tirof doskalari (taxmin), $ | W4: Eshiklar: mexanizm, kladovka (taxmin), $ | X4: Internet va Wi-Fi (taxmin), $ | Y4: Elektr (taxmin), $ | Z4: Jami, $
A5: 1-qavat: kirish zali
A6: 1-qavat — kirish zali (resepshn, turniket) | B6: =SUMIFS('Hisob (batafsil)'!$G$5:$G$371,'Hisob (batafsil)'!$B$5:$B$371,$A6,'Hisob (batafsil)'!$C$5:$C$371,"Shisha devor") -> 0 | C6: =SUMIFS('Hisob (batafsil)'!$J$5:$J$371,'Hisob (batafsil)'!$B$5:$B$371,$A6,'Hisob (batafsil)'!$C$5:$C$371,"Shisha devor") -> 0 | D6: =SUMIFS('Hisob (batafsil)'!$G$5:$G$371,'Hisob (batafsil)'!$B$5:$B$371,$A6,'Hisob (batafsil)'!$C$5:$C$371,"Gips karton (GKL)") -> 0 | E6: =SUMIFS('Hisob (batafsil)'!$J$5:$J$371,'Hisob (batafsil)'!$B$5:$B$371,$A6,'Hisob (batafsil)'!$C$5:$C$371,"Gips karton (GKL)") -> 0 | F6: =SUMIFS('Hisob (batafsil)'!$G$5:$G$371,'Hisob (batafsil)'!$B$5:$B$371,$A6,'Hisob (batafsil)'!$C$5:$C$371,"Bambuk panel") -> 0 | G6: =SUMIFS('Hisob (batafsil)'!$J$5:$J$371,'Hisob (batafsil)'!$B$5:$B$371,$A6,'Hisob (batafsil)'!$C$5:$C$371,"Bambuk panel") -> 0 | H6: =SUMIFS('Hisob (batafsil)'!$G$5:$G$371,'Hisob (batafsil)'!$B$5:$B$371,$A6,'Hisob (batafsil)'!$C$5:$C$371,"Interaktiv doska") -> 0 | I6: =SUMIFS('Hisob (batafsil)'!$J$5:$J$371,'Hisob (batafsil)'!$B$5:$B$371,$A6,'Hisob (batafsil)'!$C$5:$C$371,"Interaktiv doska") -> 0 | J6: =SUMIFS('Hisob (batafsil)'!$G$5:$G$371,'Hisob (batafsil)'!$B$5:$B$371,$A6,'Hisob (batafsil)'!$C$5:$C$371,"Perila") -> 0 | K6: =SUMIFS('Hisob (batafsil)'!$J$5:$J$371,'Hisob (batafsil)'!$B$5:$B$371,$A6,'Hisob (batafsil)'!$C$5:$C$371,"Perila") -> 0 | L6: =SUMIFS('Hisob (batafsil)'!$J$5:$J$371,'Hisob (batafsil)'!$B$5:$B$371,$A6,'Hisob (batafsil)'!$C$5:$C$371,"Yoritish") -> 0 | M6: =SUMIFS('Hisob (batafsil)'!$J$5:$J$371,'Hisob (batafsil)'!$B$5:$B$371,$A6,'Hisob (batafsil)'!$C$5:$C$371,"Kamera tizimi") -> 0 | N6: =SUMIFS('Hisob (batafsil)'!$J$5:$J$371,'Hisob (batafsil)'!$B$5:$B$371,$A6,'Hisob (batafsil)'!$C$5:$C$371,"Logotip") -> 750 | O6: =SUMIFS('Hisob (batafsil)'!$J$5:$J$371,'Hisob (batafsil)'!$B$5:$B$371,$A6,'Hisob (batafsil)'!$C$5:$C$371,"Matli plyonka") -> 0 | P6: =SUMIFS('Hisob (batafsil)'!$J$5:$J$371,'Hisob (batafsil)'!$B$5:$B$371,$A6,'Hisob (batafsil)'!$C$5:$C$371,"Yong'in xavfsizligi") -> 0 | Q6: =SUMIFS('Hisob (batafsil)'!$J$5:$J$371,'Hisob (batafsil)'!$B$5:$B$371,$A6,'Hisob (batafsil)'!$C$5:$C$371,"Buzish ishlari") -> 0 | R6: =SUMIFS('Hisob (batafsil)'!$J$5:$J$371,'Hisob (batafsil)'!$B$5:$B$371,$A6,'Hisob (batafsil)'!$C$5:$C$371,"Santexnika") -> 0 | S6: =SUMIFS('Hisob (batafsil)'!$J$5:$J$371,'Hisob (batafsil)'!$B$5:$B$371,$A6,'Hisob (batafsil)'!$C$5:$C$371,"Kafel") -> 0 | T6: =SUMIFS('Hisob (batafsil)'!$J$5:$J$371,'Hisob (batafsil)'!$B$5:$B$371,$A6,'Hisob (batafsil)'!$C$5:$C$371,"Konditsioner va ventilyatsiya") -> 0 | U6: =SUMIFS('Hisob (batafsil)'!$J$5:$J$371,'Hisob (batafsil)'!$B$5:$B$371,$A6,'Hisob (batafsil)'!$C$5:$C$371,"Mebel va interyer") -> 2680 | V6: =SUMIFS('Hisob (batafsil)'!$J$5:$J$371,'Hisob (batafsil)'!$B$5:$B$371,$A6,'Hisob (batafsil)'!$C$5:$C$371,"E'lon va e'tirof doskalari") -> 0 | W6: =SUMIFS('Hisob (batafsil)'!$J$5:$J$371,'Hisob (batafsil)'!$B$5:$B$371,$A6,'Hisob (batafsil)'!$C$5:$C$371,"Eshiklar") -> 0 | X6: =SUMIFS('Hisob (batafsil)'!$J$5:$J$371,'Hisob (batafsil)'!$B$5:$B$371,$A6,'Hisob (batafsil)'!$C$5:$C$371,"Internet va Wi-Fi") -> 0 | Y6: =SUMIFS('Hisob (batafsil)'!$J$5:$J$371,'Hisob (batafsil)'!$B$5:$B$371,$A6,'Hisob (batafsil)'!$C$5:$C$371,"Elektr") -> 0 | Z6: =C6+E6+G6+I6+K6+L6+M6+N6+O6+P6+Q6+R6+S6+T6+U6+V6+W6+X6+Y6 -> 3430
A7: 1-qavat: kirish zali — jami | B7: =SUM(B6:B6) -> 0 | C7: =SUM(C6:C6) -> 0 | D7: =SUM(D6:D6) -> 0 | E7: =SUM(E6:E6) -> 0 | F7: =SUM(F6:F6) -> 0 | G7: =SUM(G6:G6) -> 0 | H7: =SUM(H6:H6) -> 0 | I7: =SUM(I6:I6) -> 0 | ... Z7: =SUM(Z6:Z6) -> 3430
A9: 2-qavat: o'quv xonalari
A10: 1-xona | B10: =SUMIFS('Hisob (batafsil)'!$G$5:$G$371,'Hisob (batafsil)'!$B$5:$B$371,$A10,'Hisob (batafsil)'!$C$5:$C$371,"Shisha devor") -> 13.75 | C10: =SUMIFS('Hisob (batafsil)'!$J$5:$J$371,'Hisob (batafsil)'!$B$5:$B$371,$A10,'Hisob (batafsil)'!$C$5:$C$371,"Shisha devor") -> 756.25 | D10: =SUMIFS('Hisob (batafsil)'!$G$5:$G$371,'Hisob (batafsil)'!$B$5:$B$371,$A10,'Hisob (batafsil)'!$C$5:$C$371,"Gips karton (GKL)") -> 7.25 | E10: =SUMIFS('Hisob (batafsil)'!$J$5:$J$371,'Hisob (batafsil)'!$B$5:$B$371,$A10,'Hisob (batafsil)'!$C$5:$C$371,"Gips karton (GKL)") -> 87 | F10: =SUMIFS('Hisob (batafsil)'!$G$5:$G$371,'Hisob (batafsil)'!$B$5:$B$371,$A10,'Hisob (batafsil)'!$C$5:$C$371,"Bambuk panel") -> 53.9 | G10: =SUMIFS('Hisob (batafsil)'!$J$5:$J$371,'Hisob (batafsil)'!$B$5:$B$371,$A10,'Hisob (batafsil)'!$C$5:$C$371,"Bambuk panel") -> 835.45 | H10: =SUMIFS('Hisob (batafsil)'!$G$5:$G$371,'Hisob (batafsil)'!$B$5:$B$371,$A10,'Hisob (batafsil)'!$C$5:$C$371,"Interaktiv doska") -> 1 | I10: =SUMIFS('Hisob (batafsil)'!$J$5:$J$371,'Hisob (batafsil)'!$B$5:$B$371,$A10,'Hisob (batafsil)'!$C$5:$C$371,"Interaktiv doska") -> 1032 | J10: =SUMIFS('Hisob (batafsil)'!$G$5:$G$371,'Hisob (batafsil)'!$B$5:$B$371,$A10,'Hisob (batafsil)'!$C$5:$C$371,"Perila") -> 0 | K10: =SUMIFS('Hisob (batafsil)'!$J$5:$J$371,'Hisob (batafsil)'!$B$5:$B$371,$A10,'Hisob (batafsil)'!$C$5:$C$371,"Perila") -> 0 | L10: =SUMIFS('Hisob (batafsil)'!$J$5:$J$371,'Hisob (batafsil)'!$B$5:$B$371,$A10,'Hisob (batafsil)'!$C$5:$C$371,"Yoritish") -> 168 | M10: =SUMIFS('Hisob (batafsil)'!$J$5:$J$371,'Hisob (batafsil)'!$B$5:$B$371,$A10,'Hisob (batafsil)'!$C$5:$C$371,"Kamera tizimi") -> 0 | N10: =SUMIFS('Hisob (batafsil)'!$J$5:$J$371,'Hisob (batafsil)'!$B$5:$B$371,$A10,'Hisob (batafsil)'!$C$5:$C$371,"Logotip") -> 0 | O10: =SUMIFS('Hisob (batafsil)'!$J$5:$J$371,'Hisob (batafsil)'!$B$5:$B$371,$A10,'Hisob (batafsil)'!$C$5:$C$371,"Matli plyonka") -> 0 | P10: =SUMIFS('Hisob (batafsil)'!$J$5:$J$371,'Hisob (batafsil)'!$B$5:$B$371,$A10,'Hisob (batafsil)'!$C$5:$C$371,"Yong'in xavfsizligi") -> 0 | Q10: =SUMIFS('Hisob (batafsil)'!$J$5:$J$371,'Hisob (batafsil)'!$B$5:$B$371,$A10,'Hisob (batafsil)'!$C$5:$C$371,"Buzish ishlari") -> 0 | R10: =SUMIFS('Hisob (batafsil)'!$J$5:$J$371,'Hisob (batafsil)'!$B$5:$B$371,$A10,'Hisob (batafsil)'!$C$5:$C$371,"Santexnika") -> 0 | S10: =SUMIFS('Hisob (batafsil)'!$J$5:$J$371,'Hisob (batafsil)'!$B$5:$B$371,$A10,'Hisob (batafsil)'!$C$5:$C$371,"Kafel") -> 0 | T10: =SUMIFS('Hisob (batafsil)'!$J$5:$J$371,'Hisob (batafsil)'!$B$5:$B$371,$A10,'Hisob (batafsil)'!$C$5:$C$371,"Konditsioner va ventilyatsiya") -> 0 | U10: =SUMIFS('Hisob (batafsil)'!$J$5:$J$371,'Hisob (batafsil)'!$B$5:$B$371,$A10,'Hisob (batafsil)'!$C$5:$C$371,"Mebel va interyer") -> 0 | V10: =SUMIFS('Hisob (batafsil)'!$J$5:$J$371,'Hisob (batafsil)'!$B$5:$B$371,$A10,'Hisob (batafsil)'!$C$5:$C$371,"E'lon va e'tirof doskalari") -> 0 | W10: =SUMIFS('Hisob (batafsil)'!$J$5:$J$371,'Hisob (batafsil)'!$B$5:$B$371,$A10,'Hisob (batafsil)'!$C$5:$C$371,"Eshiklar") -> 150 | X10: =SUMIFS('Hisob (batafsil)'!$J$5:$J$371,'Hisob (batafsil)'!$B$5:$B$371,$A10,'Hisob (batafsil)'!$C$5:$C$371,"Internet va Wi-Fi") -> 0 | Y10: =SUMIFS('Hisob (batafsil)'!$J$5:$J$371,'Hisob (batafsil)'!$B$5:$B$371,$A10,'Hisob (batafsil)'!$C$5:$C$371,"Elektr") -> 0 | Z10: =C10+E10+G10+I10+K10+L10+M10+N10+O10+P10+Q10+R10+S10+T10+U10+V10+W10+X10+Y10 -> 3028.7
A11: 2-xona | B11: =SUMIFS('Hisob (batafsil)'!$G$5:$G$371,'Hisob (batafsil)'!$B$5:$B$371,$A11,'Hisob (batafsil)'!$C$5:$C$371,"Shisha devor") -> 14 | C11: =SUMIFS('Hisob (batafsil)'!$J$5:$J$371,'Hisob (batafsil)'!$B$5:$B$371,$A11,'Hisob (batafsil)'!$C$5:$C$371,"Shisha devor") -> 770 | D11: =SUMIFS('Hisob (batafsil)'!$G$5:$G$371,'Hisob (batafsil)'!$B$5:$B$371,$A11,'Hisob (batafsil)'!$C$5:$C$371,"Gips karton (GKL)") -> 6.3 | E11: =SUMIFS('Hisob (batafsil)'!$J$5:$J$371,'Hisob (batafsil)'!$B$5:$B$371,$A11,'Hisob (batafsil)'!$C$5:$C$371,"Gips karton (GKL)") -> 75.6 | F11: =SUMIFS('Hisob (batafsil)'!$G$5:$G$371,'Hisob (batafsil)'!$B$5:$B$371,$A11,'Hisob (batafsil)'!$C$5:$C$371,"Bambuk panel") -> 53.9 | G11: =SUMIFS('Hisob (batafsil)'!$J$5:$J$371,'Hisob (batafsil)'!$B$5:$B$371,$A11,'Hisob (batafsil)'!$C$5:$C$371,"Bambuk panel") -> 835.45 | H11: =SUMIFS('Hisob (batafsil)'!$G$5:$G$371,'Hisob (batafsil)'!$B$5:$B$371,$A11,'Hisob (batafsil)'!$C$5:$C$371,"Interaktiv doska") -> 1 | I11: =SUMIFS('Hisob (batafsil)'!$J$5:$J$371,'Hisob (batafsil)'!$B$5:$B$371,$A11,'Hisob (batafsil)'!$C$5:$C$371,"Interaktiv doska") -> 1032 | J11: =SUMIFS('Hisob (batafsil)'!$G$5:$G$371,'Hisob (batafsil)'!$B$5:$B$371,$A11,'Hisob (batafsil)'!$C$5:$C$371,"Perila") -> 0 | K11: =SUMIFS('Hisob (batafsil)'!$J$5:$J$371,'Hisob (batafsil)'!$B$5:$B$371,$A11,'Hisob (batafsil)'!$C$5:$C$371,"Perila") -> 0 | L11: =SUMIFS('Hisob (batafsil)'!$J$5:$J$371,'Hisob (batafsil)'!$B$5:$B$371,$A11,'Hisob (batafsil)'!$C$5:$C$371,"Yoritish") -> 168 | M11: =SUMIFS('Hisob (batafsil)'!$J$5:$J$371,'Hisob (batafsil)'!$B$5:$B$371,$A11,'Hisob (batafsil)'!$C$5:$C$371,"Kamera tizimi") -> 0 | N11: =SUMIFS('Hisob (batafsil)'!$J$5:$J$371,'Hisob (batafsil)'!$B$5:$B$371,$A11,'Hisob (batafsil)'!$C$5:$C$371,"Logotip") -> 0 | O11: =SUMIFS('Hisob (batafsil)'!$J$5:$J$371,'Hisob (batafsil)'!$B$5:$B$371,$A11,'Hisob (batafsil)'!$C$5:$C$371,"Matli plyonka") -> 0 | P11: =SUMIFS('Hisob (batafsil)'!$J$5:$J$371,'Hisob (batafsil)'!$B$5:$B$371,$A11,'Hisob (batafsil)'!$C$5:$C$371,"Yong'in xavfsizligi") -> 0 | Q11: =SUMIFS('Hisob (batafsil)'!$J$5:$J$371,'Hisob (batafsil)'!$B$5:$B$371,$A11,'Hisob (batafsil)'!$C$5:$C$371,"Buzish ishlari") -> 0 | R11: =SUMIFS('Hisob (batafsil)'!$J$5:$J$371,'Hisob (batafsil)'!$B$5:$B$371,$A11,'Hisob (batafsil)'!$C$5:$C$371,"Santexnika") -> 0 | S11: =SUMIFS('Hisob (batafsil)'!$J$5:$J$371,'Hisob (batafsil)'!$B$5:$B$371,$A11,'Hisob (batafsil)'!$C$5:$C$371,"Kafel") -> 0 | T11: =SUMIFS('Hisob (batafsil)'!$J$5:$J$371,'Hisob (batafsil)'!$B$5:$B$371,$A11,'Hisob (batafsil)'!$C$5:$C$371,"Konditsioner va ventilyatsiya") -> 0 | U11: =SUMIFS('Hisob (batafsil)'!$J$5:$J$371,'Hisob (batafsil)'!$B$5:$B$371,$A11,'Hisob (batafsil)'!$C$5:$C$371,"Mebel va interyer") -> 0 | V11: =SUMIFS('Hisob (batafsil)'!$J$5:$J$371,'Hisob (batafsil)'!$B$5:$B$371,$A11,'Hisob (batafsil)'!$C$5:$C$371,"E'lon va e'tirof doskalari") -> 0 | W11: =SUMIFS('Hisob (batafsil)'!$J$5:$J$371,'Hisob (batafsil)'!$B$5:$B$371,$A11,'Hisob (batafsil)'!$C$5:$C$371,"Eshiklar") -> 150 | X11: =SUMIFS('Hisob (batafsil)'!$J$5:$J$371,'Hisob (batafsil)'!$B$5:$B$371,$A11,'Hisob (batafsil)'!$C$5:$C$371,"Internet va Wi-Fi") -> 0 | Y11: =SUMIFS('Hisob (batafsil)'!$J$5:$J$371,'Hisob (batafsil)'!$B$5:$B$371,$A11,'Hisob (batafsil)'!$C$5:$C$371,"Elektr") -> 0 | Z11: =C11+E11+G11+I11+K11+L11+M11+N11+O11+P11+Q11+R11+S11+T11+U11+V11+W11+X11+Y11 -> 3031.05
A12: 3-xona | B12: =SUMIFS('Hisob (batafsil)'!$G$5:$G$371,'Hisob (batafsil)'!$B$5:$B$371,$A12,'Hisob (batafsil)'!$C$5:$C$371,"Shisha devor") -> 6.75 | C12: =SUMIFS('Hisob (batafsil)'!$J$5:$J$371,'Hisob (batafsil)'!$B$5:$B$371,$A12,'Hisob (batafsil)'!$C$5:$C$371,"Shisha devor") -> 371.25 | D12: =SUMIFS('Hisob (batafsil)'!$G$5:$G$371,'Hisob (batafsil)'!$B$5:$B$371,$A12,'Hisob (batafsil)'!$C$5:$C$371,"Gips karton (GKL)") -> 22.035 | E12: =SUMIFS('Hisob (batafsil)'!$J$5:$J$371,'Hisob (batafsil)'!$B$5:$B$371,$A12,'Hisob (batafsil)'!$C$5:$C$371,"Gips karton (GKL)") -> 264.42 | F12: =SUMIFS('Hisob (batafsil)'!$G$5:$G$371,'Hisob (batafsil)'!$B$5:$B$371,$A12,'Hisob (batafsil)'!$C$5:$C$371,"Bambuk panel") -> 53.9 | G12: =SUMIFS('Hisob (batafsil)'!$J$5:$J$371,'Hisob (batafsil)'!$B$5:$B$371,$A12,'Hisob (batafsil)'!$C$5:$C$371,"Bambuk panel") -> 835.45 | H12: =SUMIFS('Hisob (batafsil)'!$G$5:$G$371,'Hisob (batafsil)'!$B$5:$B$371,$A12,'Hisob (batafsil)'!$C$5:$C$371,"Interaktiv doska") -> 1 | I12: =SUMIFS('Hisob (batafsil)'!$J$5:$J$371,'Hisob (batafsil)'!$B$5:$B$371,$A12,'Hisob (batafsil)'!$C$5:$C$371,"Interaktiv doska") -> 1032 | J12: =SUMIFS('Hisob (batafsil)'!$G$5:$G$371,'Hisob (batafsil)'!$B$5:$B$371,$A12,'Hisob (batafsil)'!$C$5:$C$371,"Perila") -> 0 | K12: =SUMIFS('Hisob (batafsil)'!$J$5:$J$371,'Hisob (batafsil)'!$B$5:$B$371,$A12,'Hisob (batafsil)'!$C$5:$C$371,"Perila") -> 0 | L12: =SUMIFS('Hisob (batafsil)'!$J$5:$J$371,'Hisob (batafsil)'!$B$5:$B$371,$A12,'Hisob (batafsil)'!$C$5:$C$371,"Yoritish") -> 168 | M12: =SUMIFS('Hisob (batafsil)'!$J$5:$J$371,'Hisob (batafsil)'!$B$5:$B$371,$A12,'Hisob (batafsil)'!$C$5:$C$371,"Kamera tizimi") -> 0 | N12: =SUMIFS('Hisob (batafsil)'!$J$5:$J$371,'Hisob (batafsil)'!$B$5:$B$371,$A12,'Hisob (batafsil)'!$C$5:$C$371,"Logotip") -> 0 | O12: =SUMIFS('Hisob (batafsil)'!$J$5:$J$371,'Hisob (batafsil)'!$B$5:$B$371,$A12,'Hisob (batafsil)'!$C$5:$C$371,"Matli plyonka") -> 0 | P12: =SUMIFS('Hisob (batafsil)'!$J$5:$J$371,'Hisob (batafsil)'!$B$5:$B$371,$A12,'Hisob (batafsil)'!$C$5:$C$371,"Yong'in xavfsizligi") -> 0 | Q12: =SUMIFS('Hisob (batafsil)'!$J$5:$J$371,'Hisob (batafsil)'!$B$5:$B$371,$A12,'Hisob (batafsil)'!$C$5:$C$371,"Buzish ishlari") -> 0 | R12: =SUMIFS('Hisob (batafsil)'!$J$5:$J$371,'Hisob (batafsil)'!$B$5:$B$371,$A12,'Hisob (batafsil)'!$C$5:$C$371,"Santexnika") -> 0 | S12: =SUMIFS('Hisob (batafsil)'!$J$5:$J$371,'Hisob (batafsil)'!$B$5:$B$371,$A12,'Hisob (batafsil)'!$C$5:$C$371,"Kafel") -> 0 | T12: =SUMIFS('Hisob (batafsil)'!$J$5:$J$371,'Hisob (batafsil)'!$B$5:$B$371,$A12,'Hisob (batafsil)'!$C$5:$C$371,"Konditsioner va ventilyatsiya") -> 0 | U12: =SUMIFS('Hisob (batafsil)'!$J$5:$J$371,'Hisob (batafsil)'!$B$5:$B$371,$A12,'Hisob (batafsil)'!$C$5:$C$371,"Mebel va interyer") -> 0 | V12: =SUMIFS('Hisob (batafsil)'!$J$5:$J$371,'Hisob (batafsil)'!$B$5:$B$371,$A12,'Hisob (batafsil)'!$C$5:$C$371,"E'lon va e'tirof doskalari") -> 0 | W12: =SUMIFS('Hisob (batafsil)'!$J$5:$J$371,'Hisob (batafsil)'!$B$5:$B$371,$A12,'Hisob (batafsil)'!$C$5:$C$371,"Eshiklar") -> 150 | X12: =SUMIFS('Hisob (batafsil)'!$J$5:$J$371,'Hisob (batafsil)'!$B$5:$B$371,$A12,'Hisob (batafsil)'!$C$5:$C$371,"Internet va Wi-Fi") -> 0 | Y12: =SUMIFS('Hisob (batafsil)'!$J$5:$J$371,'Hisob (batafsil)'!$B$5:$B$371,$A12,'Hisob (batafsil)'!$C$5:$C$371,"Elektr") -> 0 | Z12: =C12+E12+G12+I12+K12+L12+M12+N12+O12+P12+Q12+R12+S12+T12+U12+V12+W12+X12+Y12 -> 2821.12
A13: 4-xona | B13: =SUMIFS('Hisob (batafsil)'!$G$5:$G$371,'Hisob (batafsil)'!$B$5:$B$371,$A13,'Hisob (batafsil)'!$C$5:$C$371,"Shisha devor") -> 14 | C13: =SUMIFS('Hisob (batafsil)'!$J$5:$J$371,'Hisob (batafsil)'!$B$5:$B$371,$A13,'Hisob (batafsil)'!$C$5:$C$371,"Shisha devor") -> 770 | D13: =SUMIFS('Hisob (batafsil)'!$G$5:$G$371,'Hisob (batafsil)'!$B$5:$B$371,$A13,'Hisob (batafsil)'!$C$5:$C$371,"Gips karton (GKL)") -> 35.77 | E13: =SUMIFS('Hisob (batafsil)'!$J$5:$J$371,'Hisob (batafsil)'!$B$5:$B$371,$A13,'Hisob (batafsil)'!$C$5:$C$371,"Gips karton (GKL)") -> 429.24 | F13: =SUMIFS('Hisob (batafsil)'!$G$5:$G$371,'Hisob (batafsil)'!$B$5:$B$371,$A13,'Hisob (batafsil)'!$C$5:$C$371,"Bambuk panel") -> 39.2 | G13: =SUMIFS('Hisob (batafsil)'!$J$5:$J$371,'Hisob (batafsil)'!$B$5:$B$371,$A13,'Hisob (batafsil)'!$C$5:$C$371,"Bambuk panel") -> 607.6 | H13: =SUMIFS('Hisob (batafsil)'!$G$5:$G$371,'Hisob (batafsil)'!$B$5:$B$371,$A13,'Hisob (batafsil)'!$C$5:$C$371,"Interaktiv doska") -> 1 | I13: =SUMIFS('Hisob (batafsil)'!$J$5:$J$371,'Hisob (batafsil)'!$B$5:$B$371,$A13,'Hisob (batafsil)'!$C$5:$C$371,"Interaktiv doska") -> 1032 | J13: =SUMIFS('Hisob (batafsil)'!$G$5:$G$371,'Hisob (batafsil)'!$B$5:$B$371,$A13,'Hisob (batafsil)'!$C$5:$C$371,"Perila") -> 0 | K13: =SUMIFS('Hisob (batafsil)'!$J$5:$J$371,'Hisob (batafsil)'!$B$5:$B$371,$A13,'Hisob (batafsil)'!$C$5:$C$371,"Perila") -> 0 | L13: =SUMIFS('Hisob (batafsil)'!$J$5:$J$371,'Hisob (batafsil)'!$B$5:$B$371,$A13,'Hisob (batafsil)'!$C$5:$C$371,"Yoritish") -> 168 | M13: =SUMIFS('Hisob (batafsil)'!$J$5:$J$371,'Hisob (batafsil)'!$B$5:$B$371,$A13,'Hisob (batafsil)'!$C$5:$C$371,"Kamera tizimi") -> 0 | N13: =SUMIFS('Hisob (batafsil)'!$J$5:$J$371,'Hisob (batafsil)'!$B$5:$B$371,$A13,'Hisob (batafsil)'!$C$5:$C$371,"Logotip") -> 0 | O13: =SUMIFS('Hisob (batafsil)'!$J$5:$J$371,'Hisob (batafsil)'!$B$5:$B$371,$A13,'Hisob (batafsil)'!$C$5:$C$371,"Matli plyonka") -> 0 | P13: =SUMIFS('Hisob (batafsil)'!$J$5:$J$371,'Hisob (batafsil)'!$B$5:$B$371,$A13,'Hisob (batafsil)'!$C$5:$C$371,"Yong'in xavfsizligi") -> 0 | Q13: =SUMIFS('Hisob (batafsil)'!$J$5:$J$371,'Hisob (batafsil)'!$B$5:$B$371,$A13,'Hisob (batafsil)'!$C$5:$C$371,"Buzish ishlari") -> 0 | R13: =SUMIFS('Hisob (batafsil)'!$J$5:$J$371,'Hisob (batafsil)'!$B$5:$B$371,$A13,'Hisob (batafsil)'!$C$5:$C$371,"Santexnika") -> 0 | S13: =SUMIFS('Hisob (batafsil)'!$J$5:$J$371,'Hisob (batafsil)'!$B$5:$B$371,$A13,'Hisob (batafsil)'!$C$5:$C$371,"Kafel") -> 0 | T13: =SUMIFS('Hisob (batafsil)'!$J$5:$J$371,'Hisob (batafsil)'!$B$5:$B$371,$A13,'Hisob (batafsil)'!$C$5:$C$371,"Konditsioner va ventilyatsiya") -> 0 | U13: =SUMIFS('Hisob (batafsil)'!$J$5:$J$371,'Hisob (batafsil)'!$B$5:$B$371,$A13,'Hisob (batafsil)'!$C$5:$C$371,"Mebel va interyer") -> 0 | V13: =SUMIFS('Hisob (batafsil)'!$J$5:$J$371,'Hisob (batafsil)'!$B$5:$B$371,$A13,'Hisob (batafsil)'!$C$5:$C$371,"E'lon va e'tirof doskalari") -> 0 | W13: =SUMIFS('Hisob (batafsil)'!$J$5:$J$371,'Hisob (batafsil)'!$B$5:$B$371,$A13,'Hisob (batafsil)'!$C$5:$C$371,"Eshiklar") -> 150 | X13: =SUMIFS('Hisob (batafsil)'!$J$5:$J$371,'Hisob (batafsil)'!$B$5:$B$371,$A13,'Hisob (batafsil)'!$C$5:$C$371,"Internet va Wi-Fi") -> 0 | Y13: =SUMIFS('Hisob (batafsil)'!$J$5:$J$371,'Hisob (batafsil)'!$B$5:$B$371,$A13,'Hisob (batafsil)'!$C$5:$C$371,"Elektr") -> 0 | Z13: =C13+E13+G13+I13+K13+L13+M13+N13+O13+P13+Q13+R13+S13+T13+U13+V13+W13+X13+Y13 -> 3156.84
A14: 5-xona | B14: =SUMIFS('Hisob (batafsil)'!$G$5:$G$371,'Hisob (batafsil)'!$B$5:$B$371,$A14,'Hisob (batafsil)'!$C$5:$C$371,"Shisha devor") -> 6.75 | C14: =SUMIFS('Hisob (batafsil)'!$J$5:$J$371,'Hisob (batafsil)'!$B$5:$B$371,$A14,'Hisob (batafsil)'!$C$5:$C$371,"Shisha devor") -> 371.25 | D14: =SUMIFS('Hisob (batafsil)'!$G$5:$G$371,'Hisob (batafsil)'!$B$5:$B$371,$A14,'Hisob (batafsil)'!$C$5:$C$371,"Gips karton (GKL)") -> 23 | E14: =SUMIFS('Hisob (batafsil)'!$J$5:$J$371,'Hisob (batafsil)'!$B$5:$B$371,$A14,'Hisob (batafsil)'!$C$5:$C$371,"Gips karton (GKL)") -> 276 | F14: =SUMIFS('Hisob (batafsil)'!$G$5:$G$371,'Hisob (batafsil)'!$B$5:$B$371,$A14,'Hisob (batafsil)'!$C$5:$C$371,"Bambuk panel") -> 53.9 | G14: =SUMIFS('Hisob (batafsil)'!$J$5:$J$371,'Hisob (batafsil)'!$B$5:$B$371,$A14,'Hisob (batafsil)'!$C$5:$C$371,"Bambuk panel") -> 835.45 | H14: =SUMIFS('Hisob (batafsil)'!$G$5:$G$371,'Hisob (batafsil)'!$B$5:$B$371,$A14,'Hisob (batafsil)'!$C$5:$C$371,"Interaktiv doska") -> 1 | I14: =SUMIFS('Hisob (batafsil)'!$J$5:$J$371,'Hisob (batafsil)'!$B$5:$B$371,$A14,'Hisob (batafsil)'!$C$5:$C$371,"Interaktiv doska") -> 1032 | J14: =SUMIFS('Hisob (batafsil)'!$G$5:$G$371,'Hisob (batafsil)'!$B$5:$B$371,$A14,'Hisob (batafsil)'!$C$5:$C$371,"Perila") -> 0 | K14: =SUMIFS('Hisob (batafsil)'!$J$5:$J$371,'Hisob (batafsil)'!$B$5:$B$371,$A14,'Hisob (batafsil)'!$C$5:$C$371,"Perila") -> 0 | L14: =SUMIFS('Hisob (batafsil)'!$J$5:$J$371,'Hisob (batafsil)'!$B$5:$B$371,$A14,'Hisob (batafsil)'!$C$5:$C$371,"Yoritish") -> 168 | M14: =SUMIFS('Hisob (batafsil)'!$J$5:$J$371,'Hisob (batafsil)'!$B$5:$B$371,$A14,'Hisob (batafsil)'!$C$5:$C$371,"Kamera tizimi") -> 0 | N14: =SUMIFS('Hisob (batafsil)'!$J$5:$J$371,'Hisob (batafsil)'!$B$5:$B$371,$A14,'Hisob (batafsil)'!$C$5:$C$371,"Logotip") -> 0 | O14: =SUMIFS('Hisob (batafsil)'!$J$5:$J$371,'Hisob (batafsil)'!$B$5:$B$371,$A14,'Hisob (batafsil)'!$C$5:$C$371,"Matli plyonka") -> 0 | P14: =SUMIFS('Hisob (batafsil)'!$J$5:$J$371,'Hisob (batafsil)'!$B$5:$B$371,$A14,'Hisob (batafsil)'!$C$5:$C$371,"Yong'in xavfsizligi") -> 0 | Q14: =SUMIFS('Hisob (batafsil)'!$J$5:$J$371,'Hisob (batafsil)'!$B$5:$B$371,$A14,'Hisob (batafsil)'!$C$5:$C$371,"Buzish ishlari") -> 0 | R14: =SUMIFS('Hisob (batafsil)'!$J$5:$J$371,'Hisob (batafsil)'!$B$5:$B$371,$A14,'Hisob (batafsil)'!$C$5:$C$371,"Santexnika") -> 0 | S14: =SUMIFS('Hisob (batafsil)'!$J$5:$J$371,'Hisob (batafsil)'!$B$5:$B$371,$A14,'Hisob (batafsil)'!$C$5:$C$371,"Kafel") -> 0 | T14: =SUMIFS('Hisob (batafsil)'!$J$5:$J$371,'Hisob (batafsil)'!$B$5:$B$371,$A14,'Hisob (batafsil)'!$C$5:$C$371,"Konditsioner va ventilyatsiya") -> 0 | U14: =SUMIFS('Hisob (batafsil)'!$J$5:$J$371,'Hisob (batafsil)'!$B$5:$B$371,$A14,'Hisob (batafsil)'!$C$5:$C$371,"Mebel va interyer") -> 0 | V14: =SUMIFS('Hisob (batafsil)'!$J$5:$J$371,'Hisob (batafsil)'!$B$5:$B$371,$A14,'Hisob (batafsil)'!$C$5:$C$371,"E'lon va e'tirof doskalari") -> 0 | W14: =SUMIFS('Hisob (batafsil)'!$J$5:$J$371,'Hisob (batafsil)'!$B$5:$B$371,$A14,'Hisob (batafsil)'!$C$5:$C$371,"Eshiklar") -> 150 | X14: =SUMIFS('Hisob (batafsil)'!$J$5:$J$371,'Hisob (batafsil)'!$B$5:$B$371,$A14,'Hisob (batafsil)'!$C$5:$C$371,"Internet va Wi-Fi") -> 0 | Y14: =SUMIFS('Hisob (batafsil)'!$J$5:$J$371,'Hisob (batafsil)'!$B$5:$B$371,$A14,'Hisob (batafsil)'!$C$5:$C$371,"Elektr") -> 0 | Z14: =C14+E14+G14+I14+K14+L14+M14+N14+O14+P14+Q14+R14+S14+T14+U14+V14+W14+X14+Y14 -> 2832.7
A15: 6-xona | B15: =SUMIFS('Hisob (batafsil)'!$G$5:$G$371,'Hisob (batafsil)'!$B$5:$B$371,$A15,'Hisob (batafsil)'!$C$5:$C$371,"Shisha devor") -> 14 | C15: =SUMIFS('Hisob (batafsil)'!$J$5:$J$371,'Hisob (batafsil)'!$B$5:$B$371,$A15,'Hisob (batafsil)'!$C$5:$C$371,"Shisha devor") -> 770 | D15: =SUMIFS('Hisob (batafsil)'!$G$5:$G$371,'Hisob (batafsil)'!$B$5:$B$371,$A15,'Hisob (batafsil)'!$C$5:$C$371,"Gips karton (GKL)") -> 25.55 | E15: =SUMIFS('Hisob (batafsil)'!$J$5:$J$371,'Hisob (batafsil)'!$B$5:$B$371,$A15,'Hisob (batafsil)'!$C$5:$C$371,"Gips karton (GKL)") -> 306.6 | F15: =SUMIFS('Hisob (batafsil)'!$G$5:$G$371,'Hisob (batafsil)'!$B$5:$B$371,$A15,'Hisob (batafsil)'!$C$5:$C$371,"Bambuk panel") -> 53.9 | G15: =SUMIFS('Hisob (batafsil)'!$J$5:$J$371,'Hisob (batafsil)'!$B$5:$B$371,$A15,'Hisob (batafsil)'!$C$5:$C$371,"Bambuk panel") -> 835.45 | H15: =SUMIFS('Hisob (batafsil)'!$G$5:$G$371,'Hisob (batafsil)'!$B$5:$B$371,$A15,'Hisob (batafsil)'!$C$5:$C$371,"Interaktiv doska") -> 1 | I15: =SUMIFS('Hisob (batafsil)'!$J$5:$J$371,'Hisob (batafsil)'!$B$5:$B$371,$A15,'Hisob (batafsil)'!$C$5:$C$371,"Interaktiv doska") -> 1032 | J15: =SUMIFS('Hisob (batafsil)'!$G$5:$G$371,'Hisob (batafsil)'!$B$5:$B$371,$A15,'Hisob (batafsil)'!$C$5:$C$371,"Perila") -> 0 | K15: =SUMIFS('Hisob (batafsil)'!$J$5:$J$371,'Hisob (batafsil)'!$B$5:$B$371,$A15,'Hisob (batafsil)'!$C$5:$C$371,"Perila") -> 0 | L15: =SUMIFS('Hisob (batafsil)'!$J$5:$J$371,'Hisob (batafsil)'!$B$5:$B$371,$A15,'Hisob (batafsil)'!$C$5:$C$371,"Yoritish") -> 168 | M15: =SUMIFS('Hisob (batafsil)'!$J$5:$J$371,'Hisob (batafsil)'!$B$5:$B$371,$A15,'Hisob (batafsil)'!$C$5:$C$371,"Kamera tizimi") -> 0 | N15: =SUMIFS('Hisob (batafsil)'!$J$5:$J$371,'Hisob (batafsil)'!$B$5:$B$371,$A15,'Hisob (batafsil)'!$C$5:$C$371,"Logotip") -> 0 | O15: =SUMIFS('Hisob (batafsil)'!$J$5:$J$371,'Hisob (batafsil)'!$B$5:$B$371,$A15,'Hisob (batafsil)'!$C$5:$C$371,"Matli plyonka") -> 0 | P15: =SUMIFS('Hisob (batafsil)'!$J$5:$J$371,'Hisob (batafsil)'!$B$5:$B$371,$A15,'Hisob (batafsil)'!$C$5:$C$371,"Yong'in xavfsizligi") -> 0 | Q15: =SUMIFS('Hisob (batafsil)'!$J$5:$J$371,'Hisob (batafsil)'!$B$5:$B$371,$A15,'Hisob (batafsil)'!$C$5:$C$371,"Buzish ishlari") -> 0 | R15: =SUMIFS('Hisob (batafsil)'!$J$5:$J$371,'Hisob (batafsil)'!$B$5:$B$371,$A15,'Hisob (batafsil)'!$C$5:$C$371,"Santexnika") -> 0 | S15: =SUMIFS('Hisob (batafsil)'!$J$5:$J$371,'Hisob (batafsil)'!$B$5:$B$371,$A15,'Hisob (batafsil)'!$C$5:$C$371,"Kafel") -> 0 | T15: =SUMIFS('Hisob (batafsil)'!$J$5:$J$371,'Hisob (batafsil)'!$B$5:$B$371,$A15,'Hisob (batafsil)'!$C$5:$C$371,"Konditsioner va ventilyatsiya") -> 0 | U15: =SUMIFS('Hisob (batafsil)'!$J$5:$J$371,'Hisob (batafsil)'!$B$5:$B$371,$A15,'Hisob (batafsil)'!$C$5:$C$371,"Mebel va interyer") -> 0 | V15: =SUMIFS('Hisob (batafsil)'!$J$5:$J$371,'Hisob (batafsil)'!$B$5:$B$371,$A15,'Hisob (batafsil)'!$C$5:$C$371,"E'lon va e'tirof doskalari") -> 0 | W15: =SUMIFS('Hisob (batafsil)'!$J$5:$J$371,'Hisob (batafsil)'!$B$5:$B$371,$A15,'Hisob (batafsil)'!$C$5:$C$371,"Eshiklar") -> 150 | X15: =SUMIFS('Hisob (batafsil)'!$J$5:$J$371,'Hisob (batafsil)'!$B$5:$B$371,$A15,'Hisob (batafsil)'!$C$5:$C$371,"Internet va Wi-Fi") -> 0 | Y15: =SUMIFS('Hisob (batafsil)'!$J$5:$J$371,'Hisob (batafsil)'!$B$5:$B$371,$A15,'Hisob (batafsil)'!$C$5:$C$371,"Elektr") -> 0 | Z15: =C15+E15+G15+I15+K15+L15+M15+N15+O15+P15+Q15+R15+S15+T15+U15+V15+W15+X15+Y15 -> 3262.05
A16: 7-xona | B16: =SUMIFS('Hisob (batafsil)'!$G$5:$G$371,'Hisob (batafsil)'!$B$5:$B$371,$A16,'Hisob (batafsil)'!$C$5:$C$371,"Shisha devor") -> 14 | C16: =SUMIFS('Hisob (batafsil)'!$J$5:$J$371,'Hisob (batafsil)'!$B$5:$B$371,$A16,'Hisob (batafsil)'!$C$5:$C$371,"Shisha devor") -> 770 | D16: =SUMIFS('Hisob (batafsil)'!$G$5:$G$371,'Hisob (batafsil)'!$B$5:$B$371,$A16,'Hisob (batafsil)'!$C$5:$C$371,"Gips karton (GKL)") -> 30.45 | E16: =SUMIFS('Hisob (batafsil)'!$J$5:$J$371,'Hisob (batafsil)'!$B$5:$B$371,$A16,'Hisob (batafsil)'!$C$5:$C$371,"Gips karton (GKL)") -> 365.4 | F16: =SUMIFS('Hisob (batafsil)'!$G$5:$G$371,'Hisob (batafsil)'!$B$5:$B$371,$A16,'Hisob (batafsil)'!$C$5:$C$371,"Bambuk panel") -> 53.9 | G16: =SUMIFS('Hisob (batafsil)'!$J$5:$J$371,'Hisob (batafsil)'!$B$5:$B$371,$A16,'Hisob (batafsil)'!$C$5:$C$371,"Bambuk panel") -> 835.45 | H16: =SUMIFS('Hisob (batafsil)'!$G$5:$G$371,'Hisob (batafsil)'!$B$5:$B$371,$A16,'Hisob (batafsil)'!$C$5:$C$371,"Interaktiv doska") -> 1 | I16: =SUMIFS('Hisob (batafsil)'!$J$5:$J$371,'Hisob (batafsil)'!$B$5:$B$371,$A16,'Hisob (batafsil)'!$C$5:$C$371,"Interaktiv doska") -> 1032 | J16: =SUMIFS('Hisob (batafsil)'!$G$5:$G$371,'Hisob (batafsil)'!$B$5:$B$371,$A16,'Hisob (batafsil)'!$C$5:$C$371,"Perila") -> 0 | K16: =SUMIFS('Hisob (batafsil)'!$J$5:$J$371,'Hisob (batafsil)'!$B$5:$B$371,$A16,'Hisob (batafsil)'!$C$5:$C$371,"Perila") -> 0 | L16: =SUMIFS('Hisob (batafsil)'!$J$5:$J$371,'Hisob (batafsil)'!$B$5:$B$371,$A16,'Hisob (batafsil)'!$C$5:$C$371,"Yoritish") -> 168 | M16: =SUMIFS('Hisob (batafsil)'!$J$5:$J$371,'Hisob (batafsil)'!$B$5:$B$371,$A16,'Hisob (batafsil)'!$C$5:$C$371,"Kamera tizimi") -> 0 | N16: =SUMIFS('Hisob (batafsil)'!$J$5:$J$371,'Hisob (batafsil)'!$B$5:$B$371,$A16,'Hisob (batafsil)'!$C$5:$C$371,"Logotip") -> 0 | O16: =SUMIFS('Hisob (batafsil)'!$J$5:$J$371,'Hisob (batafsil)'!$B$5:$B$371,$A16,'Hisob (batafsil)'!$C$5:$C$371,"Matli plyonka") -> 0 | P16: =SUMIFS('Hisob (batafsil)'!$J$5:$J$371,'Hisob (batafsil)'!$B$5:$B$371,$A16,'Hisob (batafsil)'!$C$5:$C$371,"Yong'in xavfsizligi") -> 0 | Q16: =SUMIFS('Hisob (batafsil)'!$J$5:$J$371,'Hisob (batafsil)'!$B$5:$B$371,$A16,'Hisob (batafsil)'!$C$5:$C$371,"Buzish ishlari") -> 0 | R16: =SUMIFS('Hisob (batafsil)'!$J$5:$J$371,'Hisob (batafsil)'!$B$5:$B$371,$A16,'Hisob (batafsil)'!$C$5:$C$371,"Santexnika") -> 0 | S16: =SUMIFS('Hisob (batafsil)'!$J$5:$J$371,'Hisob (batafsil)'!$B$5:$B$371,$A16,'Hisob (batafsil)'!$C$5:$C$371,"Kafel") -> 0 | T16: =SUMIFS('Hisob (batafsil)'!$J$5:$J$371,'Hisob (batafsil)'!$B$5:$B$371,$A16,'Hisob (batafsil)'!$C$5:$C$371,"Konditsioner va ventilyatsiya") -> 0 | U16: =SUMIFS('Hisob (batafsil)'!$J$5:$J$371,'Hisob (batafsil)'!$B$5:$B$371,$A16,'Hisob (batafsil)'!$C$5:$C$371,"Mebel va interyer") -> 0 | V16: =SUMIFS('Hisob (batafsil)'!$J$5:$J$371,'Hisob (batafsil)'!$B$5:$B$371,$A16,'Hisob (batafsil)'!$C$5:$C$371,"E'lon va e'tirof doskalari") -> 0 | W16: =SUMIFS('Hisob (batafsil)'!$J$5:$J$371,'Hisob (batafsil)'!$B$5:$B$371,$A16,'Hisob (batafsil)'!$C$5:$C$371,"Eshiklar") -> 150 | X16: =SUMIFS('Hisob (batafsil)'!$J$5:$J$371,'Hisob (batafsil)'!$B$5:$B$371,$A16,'Hisob (batafsil)'!$C$5:$C$371,"Internet va Wi-Fi") -> 0 | Y16: =SUMIFS('Hisob (batafsil)'!$J$5:$J$371,'Hisob (batafsil)'!$B$5:$B$371,$A16,'Hisob (batafsil)'!$C$5:$C$371,"Elektr") -> 0 | Z16: =C16+E16+G16+I16+K16+L16+M16+N16+O16+P16+Q16+R16+S16+T16+U16+V16+W16+X16+Y16 -> 3320.85
A17: 2-qavat: o'quv xonalari — jami | B17: =SUM(B10:B16) -> 83.25 | C17: =SUM(C10:C16) -> 4578.75 | D17: =SUM(D10:D16) -> 150.355 | E17: =SUM(E10:E16) -> 1804.26 | F17: =SUM(F10:F16) -> 362.6 | G17: =SUM(G10:G16) -> 5620.3 | H17: =SUM(H10:H16) -> 7 | I17: =SUM(I10:I16) -> 7224 | ... Z17: =SUM(Z10:Z16) -> 21453.31
A19: 2-qavat: ofis xonalari
A20: Offline sotuv (XZ1) | B20: =SUMIFS('Hisob (batafsil)'!$G$5:$G$371,'Hisob (batafsil)'!$B$5:$B$371,$A20,'Hisob (batafsil)'!$C$5:$C$371,"Shisha devor") -> 13.875 | C20: =SUMIFS('Hisob (batafsil)'!$J$5:$J$371,'Hisob (batafsil)'!$B$5:$B$371,$A20,'Hisob (batafsil)'!$C$5:$C$371,"Shisha devor") -> 763.125 | D20: =SUMIFS('Hisob (batafsil)'!$G$5:$G$371,'Hisob (batafsil)'!$B$5:$B$371,$A20,'Hisob (batafsil)'!$C$5:$C$371,"Gips karton (GKL)") -> 6.075 | E20: =SUMIFS('Hisob (batafsil)'!$J$5:$J$371,'Hisob (batafsil)'!$B$5:$B$371,$A20,'Hisob (batafsil)'!$C$5:$C$371,"Gips karton (GKL)") -> 72.9 | F20: =SUMIFS('Hisob (batafsil)'!$G$5:$G$371,'Hisob (batafsil)'!$B$5:$B$371,$A20,'Hisob (batafsil)'!$C$5:$C$371,"Bambuk panel") -> 18.2 | G20: =SUMIFS('Hisob (batafsil)'!$J$5:$J$371,'Hisob (batafsil)'!$B$5:$B$371,$A20,'Hisob (batafsil)'!$C$5:$C$371,"Bambuk panel") -> 282.1 | H20: =SUMIFS('Hisob (batafsil)'!$G$5:$G$371,'Hisob (batafsil)'!$B$5:$B$371,$A20,'Hisob (batafsil)'!$C$5:$C$371,"Interaktiv doska") -> 0 | I20: =SUMIFS('Hisob (batafsil)'!$J$5:$J$371,'Hisob (batafsil)'!$B$5:$B$371,$A20,'Hisob (batafsil)'!$C$5:$C$371,"Interaktiv doska") -> 0 | J20: =SUMIFS('Hisob (batafsil)'!$G$5:$G$371,'Hisob (batafsil)'!$B$5:$B$371,$A20,'Hisob (batafsil)'!$C$5:$C$371,"Perila") -> 0 | K20: =SUMIFS('Hisob (batafsil)'!$J$5:$J$371,'Hisob (batafsil)'!$B$5:$B$371,$A20,'Hisob (batafsil)'!$C$5:$C$371,"Perila") -> 0 | L20: =SUMIFS('Hisob (batafsil)'!$J$5:$J$371,'Hisob (batafsil)'!$B$5:$B$371,$A20,'Hisob (batafsil)'!$C$5:$C$371,"Yoritish") -> 168 | M20: =SUMIFS('Hisob (batafsil)'!$J$5:$J$371,'Hisob (batafsil)'!$B$5:$B$371,$A20,'Hisob (batafsil)'!$C$5:$C$371,"Kamera tizimi") -> 0 | N20: =SUMIFS('Hisob (batafsil)'!$J$5:$J$371,'Hisob (batafsil)'!$B$5:$B$371,$A20,'Hisob (batafsil)'!$C$5:$C$371,"Logotip") -> 0 | O20: =SUMIFS('Hisob (batafsil)'!$J$5:$J$371,'Hisob (batafsil)'!$B$5:$B$371,$A20,'Hisob (batafsil)'!$C$5:$C$371,"Matli plyonka") -> 0 | P20: =SUMIFS('Hisob (batafsil)'!$J$5:$J$371,'Hisob (batafsil)'!$B$5:$B$371,$A20,'Hisob (batafsil)'!$C$5:$C$371,"Yong'in xavfsizligi") -> 0 | Q20: =SUMIFS('Hisob (batafsil)'!$J$5:$J$371,'Hisob (batafsil)'!$B$5:$B$371,$A20,'Hisob (batafsil)'!$C$5:$C$371,"Buzish ishlari") -> 0 | R20: =SUMIFS('Hisob (batafsil)'!$J$5:$J$371,'Hisob (batafsil)'!$B$5:$B$371,$A20,'Hisob (batafsil)'!$C$5:$C$371,"Santexnika") -> 0 | S20: =SUMIFS('Hisob (batafsil)'!$J$5:$J$371,'Hisob (batafsil)'!$B$5:$B$371,$A20,'Hisob (batafsil)'!$C$5:$C$371,"Kafel") -> 0 | T20: =SUMIFS('Hisob (batafsil)'!$J$5:$J$371,'Hisob (batafsil)'!$B$5:$B$371,$A20,'Hisob (batafsil)'!$C$5:$C$371,"Konditsioner va ventilyatsiya") -> 0 | U20: =SUMIFS('Hisob (batafsil)'!$J$5:$J$371,'Hisob (batafsil)'!$B$5:$B$371,$A20,'Hisob (batafsil)'!$C$5:$C$371,"Mebel va interyer") -> 2340 | V20: =SUMIFS('Hisob (batafsil)'!$J$5:$J$371,'Hisob (batafsil)'!$B$5:$B$371,$A20,'Hisob (batafsil)'!$C$5:$C$371,"E'lon va e'tirof doskalari") -> 0 | W20: =SUMIFS('Hisob (batafsil)'!$J$5:$J$371,'Hisob (batafsil)'!$B$5:$B$371,$A20,'Hisob (batafsil)'!$C$5:$C$371,"Eshiklar") -> 150 | X20: =SUMIFS('Hisob (batafsil)'!$J$5:$J$371,'Hisob (batafsil)'!$B$5:$B$371,$A20,'Hisob (batafsil)'!$C$5:$C$371,"Internet va Wi-Fi") -> 0 | Y20: =SUMIFS('Hisob (batafsil)'!$J$5:$J$371,'Hisob (batafsil)'!$B$5:$B$371,$A20,'Hisob (batafsil)'!$C$5:$C$371,"Elektr") -> 0 | Z20: =C20+E20+G20+I20+K20+L20+M20+N20+O20+P20+Q20+R20+S20+T20+U20+V20+W20+X20+Y20 -> 3776.125
A21: Admin (XZ2) | B21: =SUMIFS('Hisob (batafsil)'!$G$5:$G$371,'Hisob (batafsil)'!$B$5:$B$371,$A21,'Hisob (batafsil)'!$C$5:$C$371,"Shisha devor") -> 14.5 | C21: =SUMIFS('Hisob (batafsil)'!$J$5:$J$371,'Hisob (batafsil)'!$B$5:$B$371,$A21,'Hisob (batafsil)'!$C$5:$C$371,"Shisha devor") -> 797.5 | D21: =SUMIFS('Hisob (batafsil)'!$G$5:$G$371,'Hisob (batafsil)'!$B$5:$B$371,$A21,'Hisob (batafsil)'!$C$5:$C$371,"Gips karton (GKL)") -> 5.8 | E21: =SUMIFS('Hisob (batafsil)'!$J$5:$J$371,'Hisob (batafsil)'!$B$5:$B$371,$A21,'Hisob (batafsil)'!$C$5:$C$371,"Gips karton (GKL)") -> 69.6 | F21: =SUMIFS('Hisob (batafsil)'!$G$5:$G$371,'Hisob (batafsil)'!$B$5:$B$371,$A21,'Hisob (batafsil)'!$C$5:$C$371,"Bambuk panel") -> 18.2 | G21: =SUMIFS('Hisob (batafsil)'!$J$5:$J$371,'Hisob (batafsil)'!$B$5:$B$371,$A21,'Hisob (batafsil)'!$C$5:$C$371,"Bambuk panel") -> 282.1 | H21: =SUMIFS('Hisob (batafsil)'!$G$5:$G$371,'Hisob (batafsil)'!$B$5:$B$371,$A21,'Hisob (batafsil)'!$C$5:$C$371,"Interaktiv doska") -> 0 | I21: =SUMIFS('Hisob (batafsil)'!$J$5:$J$371,'Hisob (batafsil)'!$B$5:$B$371,$A21,'Hisob (batafsil)'!$C$5:$C$371,"Interaktiv doska") -> 0 | J21: =SUMIFS('Hisob (batafsil)'!$G$5:$G$371,'Hisob (batafsil)'!$B$5:$B$371,$A21,'Hisob (batafsil)'!$C$5:$C$371,"Perila") -> 0 | K21: =SUMIFS('Hisob (batafsil)'!$J$5:$J$371,'Hisob (batafsil)'!$B$5:$B$371,$A21,'Hisob (batafsil)'!$C$5:$C$371,"Perila") -> 0 | L21: =SUMIFS('Hisob (batafsil)'!$J$5:$J$371,'Hisob (batafsil)'!$B$5:$B$371,$A21,'Hisob (batafsil)'!$C$5:$C$371,"Yoritish") -> 168 | M21: =SUMIFS('Hisob (batafsil)'!$J$5:$J$371,'Hisob (batafsil)'!$B$5:$B$371,$A21,'Hisob (batafsil)'!$C$5:$C$371,"Kamera tizimi") -> 0 | N21: =SUMIFS('Hisob (batafsil)'!$J$5:$J$371,'Hisob (batafsil)'!$B$5:$B$371,$A21,'Hisob (batafsil)'!$C$5:$C$371,"Logotip") -> 0 | O21: =SUMIFS('Hisob (batafsil)'!$J$5:$J$371,'Hisob (batafsil)'!$B$5:$B$371,$A21,'Hisob (batafsil)'!$C$5:$C$371,"Matli plyonka") -> 0 | P21: =SUMIFS('Hisob (batafsil)'!$J$5:$J$371,'Hisob (batafsil)'!$B$5:$B$371,$A21,'Hisob (batafsil)'!$C$5:$C$371,"Yong'in xavfsizligi") -> 0 | Q21: =SUMIFS('Hisob (batafsil)'!$J$5:$J$371,'Hisob (batafsil)'!$B$5:$B$371,$A21,'Hisob (batafsil)'!$C$5:$C$371,"Buzish ishlari") -> 0 | R21: =SUMIFS('Hisob (batafsil)'!$J$5:$J$371,'Hisob (batafsil)'!$B$5:$B$371,$A21,'Hisob (batafsil)'!$C$5:$C$371,"Santexnika") -> 0 | S21: =SUMIFS('Hisob (batafsil)'!$J$5:$J$371,'Hisob (batafsil)'!$B$5:$B$371,$A21,'Hisob (batafsil)'!$C$5:$C$371,"Kafel") -> 0 | T21: =SUMIFS('Hisob (batafsil)'!$J$5:$J$371,'Hisob (batafsil)'!$B$5:$B$371,$A21,'Hisob (batafsil)'!$C$5:$C$371,"Konditsioner va ventilyatsiya") -> 0 | U21: =SUMIFS('Hisob (batafsil)'!$J$5:$J$371,'Hisob (batafsil)'!$B$5:$B$371,$A21,'Hisob (batafsil)'!$C$5:$C$371,"Mebel va interyer") -> 1470 | V21: =SUMIFS('Hisob (batafsil)'!$J$5:$J$371,'Hisob (batafsil)'!$B$5:$B$371,$A21,'Hisob (batafsil)'!$C$5:$C$371,"E'lon va e'tirof doskalari") -> 0 | W21: =SUMIFS('Hisob (batafsil)'!$J$5:$J$371,'Hisob (batafsil)'!$B$5:$B$371,$A21,'Hisob (batafsil)'!$C$5:$C$371,"Eshiklar") -> 150 | X21: =SUMIFS('Hisob (batafsil)'!$J$5:$J$371,'Hisob (batafsil)'!$B$5:$B$371,$A21,'Hisob (batafsil)'!$C$5:$C$371,"Internet va Wi-Fi") -> 0 | Y21: =SUMIFS('Hisob (batafsil)'!$J$5:$J$371,'Hisob (batafsil)'!$B$5:$B$371,$A21,'Hisob (batafsil)'!$C$5:$C$371,"Elektr") -> 0 | Z21: =C21+E21+G21+I21+K21+L21+M21+N21+O21+P21+Q21+R21+S21+T21+U21+V21+W21+X21+Y21 -> 2937.2
