Workbook

Sheet Xonalar bo'yicha
A1: PDP Academy · Xadra filiali (2 va 3-qavat): xarajatlar, xonalar bo'yicha
A2: Har bir qator «Hisob (batafsil)» varag'idan olinadi (SUMIFS). Narxlarni «Narxlar» varag'ida o'zgartiring.
A4: Xona | B4: Shisha (devor va eshik), m² | C4: Shisha (devor va eshik), $ | D4: Gips karton (GKL), m² | E4: Gips karton (GKL), $ | F4: Bambuk panel, m² | G4: Bambuk panel, $ | H4: Interaktiv doska, dona | I4: Interaktiv doska, $ | J4: Perila, m | K4: Perila, $ | L4: Yoritish, $ | M4: Kamera tizimi, $ | N4: Logotip, $ | O4: Matli plyonka, $ | P4: Yong'in xavfsizligi, $ | Q4: Buzish ishlari, $ | R4: Santexnika, $ | S4: Kafel, $ | T4: Jami, $
A5: 2-qavat: o'quv xonalari
A6: 1-xona | B6: =SUMIFS('Hisob (batafsil)'!$G$5:$G$271,'Hisob (batafsil)'!$B$5:$B$271,$A6,'Hisob (batafsil)'!$C$5:$C$271,"Shisha devor") -> 13.75 | C6: =SUMIFS('Hisob (batafsil)'!$J$5:$J$271,'Hisob (batafsil)'!$B$5:$B$271,$A6,'Hisob (batafsil)'!$C$5:$C$271,"Shisha devor") -> 756.25 | D6: =SUMIFS('Hisob (batafsil)'!$G$5:$G$271,'Hisob (batafsil)'!$B$5:$B$271,$A6,'Hisob (batafsil)'!$C$5:$C$271,"Gips karton (GKL)") -> 7.25 | E6: =SUMIFS('Hisob (batafsil)'!$J$5:$J$271,'Hisob (batafsil)'!$B$5:$B$271,$A6,'Hisob (batafsil)'!$C$5:$C$271,"Gips karton (GKL)") -> 87 | F6: =SUMIFS('Hisob (batafsil)'!$G$5:$G$271,'Hisob (batafsil)'!$B$5:$B$271,$A6,'Hisob (batafsil)'!$C$5:$C$271,"Bambuk panel") -> 53.9 | G6: =SUMIFS('Hisob (batafsil)'!$J$5:$J$271,'Hisob (batafsil)'!$B$5:$B$271,$A6,'Hisob (batafsil)'!$C$5:$C$271,"Bambuk panel") -> 835.45 | H6: =SUMIFS('Hisob (batafsil)'!$G$5:$G$271,'Hisob (batafsil)'!$B$5:$B$271,$A6,'Hisob (batafsil)'!$C$5:$C$271,"Interaktiv doska") -> 1 | I6: =SUMIFS('Hisob (batafsil)'!$J$5:$J$271,'Hisob (batafsil)'!$B$5:$B$271,$A6,'Hisob (batafsil)'!$C$5:$C$271,"Interaktiv doska") -> 1032 | J6: =SUMIFS('Hisob (batafsil)'!$G$5:$G$271,'Hisob (batafsil)'!$B$5:$B$271,$A6,'Hisob (batafsil)'!$C$5:$C$271,"Perila") -> 0 | K6: =SUMIFS('Hisob (batafsil)'!$J$5:$J$271,'Hisob (batafsil)'!$B$5:$B$271,$A6,'Hisob (batafsil)'!$C$5:$C$271,"Perila") -> 0 | L6: =SUMIFS('Hisob (batafsil)'!$J$5:$J$271,'Hisob (batafsil)'!$B$5:$B$271,$A6,'Hisob (batafsil)'!$C$5:$C$271,"Yoritish") -> 168 | M6: =SUMIFS('Hisob (batafsil)'!$J$5:$J$271,'Hisob (batafsil)'!$B$5:$B$271,$A6,'Hisob (batafsil)'!$C$5:$C$271,"Kamera tizimi") -> 0 | N6: =SUMIFS('Hisob (batafsil)'!$J$5:$J$271,'Hisob (batafsil)'!$B$5:$B$271,$A6,'Hisob (batafsil)'!$C$5:$C$271,"Logotip") -> 0 | O6: =SUMIFS('Hisob (batafsil)'!$J$5:$J$271,'Hisob (batafsil)'!$B$5:$B$271,$A6,'Hisob (batafsil)'!$C$5:$C$271,"Matli plyonka") -> 0 | P6: =SUMIFS('Hisob (batafsil)'!$J$5:$J$271,'Hisob (batafsil)'!$B$5:$B$271,$A6,'Hisob (batafsil)'!$C$5:$C$271,"Yong'in xavfsizligi") -> 0 | Q6: =SUMIFS('Hisob (batafsil)'!$J$5:$J$271,'Hisob (batafsil)'!$B$5:$B$271,$A6,'Hisob (batafsil)'!$C$5:$C$271,"Buzish ishlari") -> 0 | R6: =SUMIFS('Hisob (batafsil)'!$J$5:$J$271,'Hisob (batafsil)'!$B$5:$B$271,$A6,'Hisob (batafsil)'!$C$5:$C$271,"Santexnika") -> 0 | S6: =SUMIFS('Hisob (batafsil)'!$J$5:$J$271,'Hisob (batafsil)'!$B$5:$B$271,$A6,'Hisob (batafsil)'!$C$5:$C$271,"Kafel") -> 0 | T6: =C6+E6+G6+I6+K6+L6+M6+N6+O6+P6+Q6+R6+S6 -> 2878.7
A7: 2-xona | B7: =SUMIFS('Hisob (batafsil)'!$G$5:$G$271,'Hisob (batafsil)'!$B$5:$B$271,$A7,'Hisob (batafsil)'!$C$5:$C$271,"Shisha devor") -> 14 | C7: =SUMIFS('Hisob (batafsil)'!$J$5:$J$271,'Hisob (batafsil)'!$B$5:$B$271,$A7,'Hisob (batafsil)'!$C$5:$C$271,"Shisha devor") -> 770 | D7: =SUMIFS('Hisob (batafsil)'!$G$5:$G$271,'Hisob (batafsil)'!$B$5:$B$271,$A7,'Hisob (batafsil)'!$C$5:$C$271,"Gips karton (GKL)") -> 6.3 | E7: =SUMIFS('Hisob (batafsil)'!$J$5:$J$271,'Hisob (batafsil)'!$B$5:$B$271,$A7,'Hisob (batafsil)'!$C$5:$C$271,"Gips karton (GKL)") -> 75.6 | F7: =SUMIFS('Hisob (batafsil)'!$G$5:$G$271,'Hisob (batafsil)'!$B$5:$B$271,$A7,'Hisob (batafsil)'!$C$5:$C$271,"Bambuk panel") -> 53.9 | G7: =SUMIFS('Hisob (batafsil)'!$J$5:$J$271,'Hisob (batafsil)'!$B$5:$B$271,$A7,'Hisob (batafsil)'!$C$5:$C$271,"Bambuk panel") -> 835.45 | H7: =SUMIFS('Hisob (batafsil)'!$G$5:$G$271,'Hisob (batafsil)'!$B$5:$B$271,$A7,'Hisob (batafsil)'!$C$5:$C$271,"Interaktiv doska") -> 1 | I7: =SUMIFS('Hisob (batafsil)'!$J$5:$J$271,'Hisob (batafsil)'!$B$5:$B$271,$A7,'Hisob (batafsil)'!$C$5:$C$271,"Interaktiv doska") -> 1032 | J7: =SUMIFS('Hisob (batafsil)'!$G$5:$G$271,'Hisob (batafsil)'!$B$5:$B$271,$A7,'Hisob (batafsil)'!$C$5:$C$271,"Perila") -> 0 | K7: =SUMIFS('Hisob (batafsil)'!$J$5:$J$271,'Hisob (batafsil)'!$B$5:$B$271,$A7,'Hisob (batafsil)'!$C$5:$C$271,"Perila") -> 0 | L7: =SUMIFS('Hisob (batafsil)'!$J$5:$J$271,'Hisob (batafsil)'!$B$5:$B$271,$A7,'Hisob (batafsil)'!$C$5:$C$271,"Yoritish") -> 168 | M7: =SUMIFS('Hisob (batafsil)'!$J$5:$J$271,'Hisob (batafsil)'!$B$5:$B$271,$A7,'Hisob (batafsil)'!$C$5:$C$271,"Kamera tizimi") -> 0 | N7: =SUMIFS('Hisob (batafsil)'!$J$5:$J$271,'Hisob (batafsil)'!$B$5:$B$271,$A7,'Hisob (batafsil)'!$C$5:$C$271,"Logotip") -> 0 | O7: =SUMIFS('Hisob (batafsil)'!$J$5:$J$271,'Hisob (batafsil)'!$B$5:$B$271,$A7,'Hisob (batafsil)'!$C$5:$C$271,"Matli plyonka") -> 0 | P7: =SUMIFS('Hisob (batafsil)'!$J$5:$J$271,'Hisob (batafsil)'!$B$5:$B$271,$A7,'Hisob (batafsil)'!$C$5:$C$271,"Yong'in xavfsizligi") -> 0 | Q7: =SUMIFS('Hisob (batafsil)'!$J$5:$J$271,'Hisob (batafsil)'!$B$5:$B$271,$A7,'Hisob (batafsil)'!$C$5:$C$271,"Buzish ishlari") -> 0 | R7: =SUMIFS('Hisob (batafsil)'!$J$5:$J$271,'Hisob (batafsil)'!$B$5:$B$271,$A7,'Hisob (batafsil)'!$C$5:$C$271,"Santexnika") -> 0 | S7: =SUMIFS('Hisob (batafsil)'!$J$5:$J$271,'Hisob (batafsil)'!$B$5:$B$271,$A7,'Hisob (batafsil)'!$C$5:$C$271,"Kafel") -> 0 | T7: =C7+E7+G7+I7+K7+L7+M7+N7+O7+P7+Q7+R7+S7 -> 2881.05
A8: 3-xona | B8: =SUMIFS('Hisob (batafsil)'!$G$5:$G$271,'Hisob (batafsil)'!$B$5:$B$271,$A8,'Hisob (batafsil)'!$C$5:$C$271,"Shisha devor") -> 2.25 | C8: =SUMIFS('Hisob (batafsil)'!$J$5:$J$271,'Hisob (batafsil)'!$B$5:$B$271,$A8,'Hisob (batafsil)'!$C$5:$C$271,"Shisha devor") -> 123.75 | D8: =SUMIFS('Hisob (batafsil)'!$G$5:$G$271,'Hisob (batafsil)'!$B$5:$B$271,$A8,'Hisob (batafsil)'!$C$5:$C$271,"Gips karton (GKL)") -> 17.875 | E8: =SUMIFS('Hisob (batafsil)'!$J$5:$J$271,'Hisob (batafsil)'!$B$5:$B$271,$A8,'Hisob (batafsil)'!$C$5:$C$271,"Gips karton (GKL)") -> 214.5 | F8: =SUMIFS('Hisob (batafsil)'!$G$5:$G$271,'Hisob (batafsil)'!$B$5:$B$271,$A8,'Hisob (batafsil)'!$C$5:$C$271,"Bambuk panel") -> 53.9 | G8: =SUMIFS('Hisob (batafsil)'!$J$5:$J$271,'Hisob (batafsil)'!$B$5:$B$271,$A8,'Hisob (batafsil)'!$C$5:$C$271,"Bambuk panel") -> 835.45 | H8: =SUMIFS('Hisob (batafsil)'!$G$5:$G$271,'Hisob (batafsil)'!$B$5:$B$271,$A8,'Hisob (batafsil)'!$C$5:$C$271,"Interaktiv doska") -> 1 | I8: =SUMIFS('Hisob (batafsil)'!$J$5:$J$271,'Hisob (batafsil)'!$B$5:$B$271,$A8,'Hisob (batafsil)'!$C$5:$C$271,"Interaktiv doska") -> 1032 | J8: =SUMIFS('Hisob (batafsil)'!$G$5:$G$271,'Hisob (batafsil)'!$B$5:$B$271,$A8,'Hisob (batafsil)'!$C$5:$C$271,"Perila") -> 0 | K8: =SUMIFS('Hisob (batafsil)'!$J$5:$J$271,'Hisob (batafsil)'!$B$5:$B$271,$A8,'Hisob (batafsil)'!$C$5:$C$271,"Perila") -> 0 | L8: =SUMIFS('Hisob (batafsil)'!$J$5:$J$271,'Hisob (batafsil)'!$B$5:$B$271,$A8,'Hisob (batafsil)'!$C$5:$C$271,"Yoritish") -> 168 | M8: =SUMIFS('Hisob (batafsil)'!$J$5:$J$271,'Hisob (batafsil)'!$B$5:$B$271,$A8,'Hisob (batafsil)'!$C$5:$C$271,"Kamera tizimi") -> 0 | N8: =SUMIFS('Hisob (batafsil)'!$J$5:$J$271,'Hisob (batafsil)'!$B$5:$B$271,$A8,'Hisob (batafsil)'!$C$5:$C$271,"Logotip") -> 0 | O8: =SUMIFS('Hisob (batafsil)'!$J$5:$J$271,'Hisob (batafsil)'!$B$5:$B$271,$A8,'Hisob (batafsil)'!$C$5:$C$271,"Matli plyonka") -> 0 | P8: =SUMIFS('Hisob (batafsil)'!$J$5:$J$271,'Hisob (batafsil)'!$B$5:$B$271,$A8,'Hisob (batafsil)'!$C$5:$C$271,"Yong'in xavfsizligi") -> 0 | Q8: =SUMIFS('Hisob (batafsil)'!$J$5:$J$271,'Hisob (batafsil)'!$B$5:$B$271,$A8,'Hisob (batafsil)'!$C$5:$C$271,"Buzish ishlari") -> 0 | R8: =SUMIFS('Hisob (batafsil)'!$J$5:$J$271,'Hisob (batafsil)'!$B$5:$B$271,$A8,'Hisob (batafsil)'!$C$5:$C$271,"Santexnika") -> 0 | S8: =SUMIFS('Hisob (batafsil)'!$J$5:$J$271,'Hisob (batafsil)'!$B$5:$B$271,$A8,'Hisob (batafsil)'!$C$5:$C$271,"Kafel") -> 0 | T8: =C8+E8+G8+I8+K8+L8+M8+N8+O8+P8+Q8+R8+S8 -> 2373.7
A9: 4-xona | B9: =SUMIFS('Hisob (batafsil)'!$G$5:$G$271,'Hisob (batafsil)'!$B$5:$B$271,$A9,'Hisob (batafsil)'!$C$5:$C$271,"Shisha devor") -> 12.625 | C9: =SUMIFS('Hisob (batafsil)'!$J$5:$J$271,'Hisob (batafsil)'!$B$5:$B$271,$A9,'Hisob (batafsil)'!$C$5:$C$271,"Shisha devor") -> 694.375 | D9: =SUMIFS('Hisob (batafsil)'!$G$5:$G$271,'Hisob (batafsil)'!$B$5:$B$271,$A9,'Hisob (batafsil)'!$C$5:$C$271,"Gips karton (GKL)") -> 41.625 | E9: =SUMIFS('Hisob (batafsil)'!$J$5:$J$271,'Hisob (batafsil)'!$B$5:$B$271,$A9,'Hisob (batafsil)'!$C$5:$C$271,"Gips karton (GKL)") -> 499.5 | F9: =SUMIFS('Hisob (batafsil)'!$G$5:$G$271,'Hisob (batafsil)'!$B$5:$B$271,$A9,'Hisob (batafsil)'!$C$5:$C$271,"Bambuk panel") -> 50.4 | G9: =SUMIFS('Hisob (batafsil)'!$J$5:$J$271,'Hisob (batafsil)'!$B$5:$B$271,$A9,'Hisob (batafsil)'!$C$5:$C$271,"Bambuk panel") -> 781.2 | H9: =SUMIFS('Hisob (batafsil)'!$G$5:$G$271,'Hisob (batafsil)'!$B$5:$B$271,$A9,'Hisob (batafsil)'!$C$5:$C$271,"Interaktiv doska") -> 1 | I9: =SUMIFS('Hisob (batafsil)'!$J$5:$J$271,'Hisob (batafsil)'!$B$5:$B$271,$A9,'Hisob (batafsil)'!$C$5:$C$271,"Interaktiv doska") -> 1032 | J9: =SUMIFS('Hisob (batafsil)'!$G$5:$G$271,'Hisob (batafsil)'!$B$5:$B$271,$A9,'Hisob (batafsil)'!$C$5:$C$271,"Perila") -> 0 | K9: =SUMIFS('Hisob (batafsil)'!$J$5:$J$271,'Hisob (batafsil)'!$B$5:$B$271,$A9,'Hisob (batafsil)'!$C$5:$C$271,"Perila") -> 0 | L9: =SUMIFS('Hisob (batafsil)'!$J$5:$J$271,'Hisob (batafsil)'!$B$5:$B$271,$A9,'Hisob (batafsil)'!$C$5:$C$271,"Yoritish") -> 168 | M9: =SUMIFS('Hisob (batafsil)'!$J$5:$J$271,'Hisob (batafsil)'!$B$5:$B$271,$A9,'Hisob (batafsil)'!$C$5:$C$271,"Kamera tizimi") -> 0 | N9: =SUMIFS('Hisob (batafsil)'!$J$5:$J$271,'Hisob (batafsil)'!$B$5:$B$271,$A9,'Hisob (batafsil)'!$C$5:$C$271,"Logotip") -> 0 | O9: =SUMIFS('Hisob (batafsil)'!$J$5:$J$271,'Hisob (batafsil)'!$B$5:$B$271,$A9,'Hisob (batafsil)'!$C$5:$C$271,"Matli plyonka") -> 0 | P9: =SUMIFS('Hisob (batafsil)'!$J$5:$J$271,'Hisob (batafsil)'!$B$5:$B$271,$A9,'Hisob (batafsil)'!$C$5:$C$271,"Yong'in xavfsizligi") -> 0 | Q9: =SUMIFS('Hisob (batafsil)'!$J$5:$J$271,'Hisob (batafsil)'!$B$5:$B$271,$A9,'Hisob (batafsil)'!$C$5:$C$271,"Buzish ishlari") -> 0 | R9: =SUMIFS('Hisob (batafsil)'!$J$5:$J$271,'Hisob (batafsil)'!$B$5:$B$271,$A9,'Hisob (batafsil)'!$C$5:$C$271,"Santexnika") -> 0 | S9: =SUMIFS('Hisob (batafsil)'!$J$5:$J$271,'Hisob (batafsil)'!$B$5:$B$271,$A9,'Hisob (batafsil)'!$C$5:$C$271,"Kafel") -> 0 | T9: =C9+E9+G9+I9+K9+L9+M9+N9+O9+P9+Q9+R9+S9 -> 3175.075
A10: 5-xona | B10: =SUMIFS('Hisob (batafsil)'!$G$5:$G$271,'Hisob (batafsil)'!$B$5:$B$271,$A10,'Hisob (batafsil)'!$C$5:$C$271,"Shisha devor") -> 2.25 | C10: =SUMIFS('Hisob (batafsil)'!$J$5:$J$271,'Hisob (batafsil)'!$B$5:$B$271,$A10,'Hisob (batafsil)'!$C$5:$C$271,"Shisha devor") -> 123.75 | D10: =SUMIFS('Hisob (batafsil)'!$G$5:$G$271,'Hisob (batafsil)'!$B$5:$B$271,$A10,'Hisob (batafsil)'!$C$5:$C$271,"Gips karton (GKL)") -> 27.5 | E10: =SUMIFS('Hisob (batafsil)'!$J$5:$J$271,'Hisob (batafsil)'!$B$5:$B$271,$A10,'Hisob (batafsil)'!$C$5:$C$271,"Gips karton (GKL)") -> 330 | F10: =SUMIFS('Hisob (batafsil)'!$G$5:$G$271,'Hisob (batafsil)'!$B$5:$B$271,$A10,'Hisob (batafsil)'!$C$5:$C$271,"Bambuk panel") -> 53.9 | G10: =SUMIFS('Hisob (batafsil)'!$J$5:$J$271,'Hisob (batafsil)'!$B$5:$B$271,$A10,'Hisob (batafsil)'!$C$5:$C$271,"Bambuk panel") -> 835.45 | H10: =SUMIFS('Hisob (batafsil)'!$G$5:$G$271,'Hisob (batafsil)'!$B$5:$B$271,$A10,'Hisob (batafsil)'!$C$5:$C$271,"Interaktiv doska") -> 1 | I10: =SUMIFS('Hisob (batafsil)'!$J$5:$J$271,'Hisob (batafsil)'!$B$5:$B$271,$A10,'Hisob (batafsil)'!$C$5:$C$271,"Interaktiv doska") -> 1032 | J10: =SUMIFS('Hisob (batafsil)'!$G$5:$G$271,'Hisob (batafsil)'!$B$5:$B$271,$A10,'Hisob (batafsil)'!$C$5:$C$271,"Perila") -> 0 | K10: =SUMIFS('Hisob (batafsil)'!$J$5:$J$271,'Hisob (batafsil)'!$B$5:$B$271,$A10,'Hisob (batafsil)'!$C$5:$C$271,"Perila") -> 0 | L10: =SUMIFS('Hisob (batafsil)'!$J$5:$J$271,'Hisob (batafsil)'!$B$5:$B$271,$A10,'Hisob (batafsil)'!$C$5:$C$271,"Yoritish") -> 168 | M10: =SUMIFS('Hisob (batafsil)'!$J$5:$J$271,'Hisob (batafsil)'!$B$5:$B$271,$A10,'Hisob (batafsil)'!$C$5:$C$271,"Kamera tizimi") -> 0 | N10: =SUMIFS('Hisob (batafsil)'!$J$5:$J$271,'Hisob (batafsil)'!$B$5:$B$271,$A10,'Hisob (batafsil)'!$C$5:$C$271,"Logotip") -> 0 | O10: =SUMIFS('Hisob (batafsil)'!$J$5:$J$271,'Hisob (batafsil)'!$B$5:$B$271,$A10,'Hisob (batafsil)'!$C$5:$C$271,"Matli plyonka") -> 0 | P10: =SUMIFS('Hisob (batafsil)'!$J$5:$J$271,'Hisob (batafsil)'!$B$5:$B$271,$A10,'Hisob (batafsil)'!$C$5:$C$271,"Yong'in xavfsizligi") -> 0 | Q10: =SUMIFS('Hisob (batafsil)'!$J$5:$J$271,'Hisob (batafsil)'!$B$5:$B$271,$A10,'Hisob (batafsil)'!$C$5:$C$271,"Buzish ishlari") -> 0 | R10: =SUMIFS('Hisob (batafsil)'!$J$5:$J$271,'Hisob (batafsil)'!$B$5:$B$271,$A10,'Hisob (batafsil)'!$C$5:$C$271,"Santexnika") -> 0 | S10: =SUMIFS('Hisob (batafsil)'!$J$5:$J$271,'Hisob (batafsil)'!$B$5:$B$271,$A10,'Hisob (batafsil)'!$C$5:$C$271,"Kafel") -> 0 | T10: =C10+E10+G10+I10+K10+L10+M10+N10+O10+P10+Q10+R10+S10 -> 2489.2
A11: 6-xona | B11: =SUMIFS('Hisob (batafsil)'!$G$5:$G$271,'Hisob (batafsil)'!$B$5:$B$271,$A11,'Hisob (batafsil)'!$C$5:$C$271,"Shisha devor") -> 14 | C11: =SUMIFS('Hisob (batafsil)'!$J$5:$J$271,'Hisob (batafsil)'!$B$5:$B$271,$A11,'Hisob (batafsil)'!$C$5:$C$271,"Shisha devor") -> 770 | D11: =SUMIFS('Hisob (batafsil)'!$G$5:$G$271,'Hisob (batafsil)'!$B$5:$B$271,$A11,'Hisob (batafsil)'!$C$5:$C$271,"Gips karton (GKL)") -> 25.55 | E11: =SUMIFS('Hisob (batafsil)'!$J$5:$J$271,'Hisob (batafsil)'!$B$5:$B$271,$A11,'Hisob (batafsil)'!$C$5:$C$271,"Gips karton (GKL)") -> 306.6 | F11: =SUMIFS('Hisob (batafsil)'!$G$5:$G$271,'Hisob (batafsil)'!$B$5:$B$271,$A11,'Hisob (batafsil)'!$C$5:$C$271,"Bambuk panel") -> 53.9 | G11: =SUMIFS('Hisob (batafsil)'!$J$5:$J$271,'Hisob (batafsil)'!$B$5:$B$271,$A11,'Hisob (batafsil)'!$C$5:$C$271,"Bambuk panel") -> 835.45 | H11: =SUMIFS('Hisob (batafsil)'!$G$5:$G$271,'Hisob (batafsil)'!$B$5:$B$271,$A11,'Hisob (batafsil)'!$C$5:$C$271,"Interaktiv doska") -> 1 | I11: =SUMIFS('Hisob (batafsil)'!$J$5:$J$271,'Hisob (batafsil)'!$B$5:$B$271,$A11,'Hisob (batafsil)'!$C$5:$C$271,"Interaktiv doska") -> 1032 | J11: =SUMIFS('Hisob (batafsil)'!$G$5:$G$271,'Hisob (batafsil)'!$B$5:$B$271,$A11,'Hisob (batafsil)'!$C$5:$C$271,"Perila") -> 0 | K11: =SUMIFS('Hisob (batafsil)'!$J$5:$J$271,'Hisob (batafsil)'!$B$5:$B$271,$A11,'Hisob (batafsil)'!$C$5:$C$271,"Perila") -> 0 | L11: =SUMIFS('Hisob (batafsil)'!$J$5:$J$271,'Hisob (batafsil)'!$B$5:$B$271,$A11,'Hisob (batafsil)'!$C$5:$C$271,"Yoritish") -> 168 | M11: =SUMIFS('Hisob (batafsil)'!$J$5:$J$271,'Hisob (batafsil)'!$B$5:$B$271,$A11,'Hisob (batafsil)'!$C$5:$C$271,"Kamera tizimi") -> 0 | N11: =SUMIFS('Hisob (batafsil)'!$J$5:$J$271,'Hisob (batafsil)'!$B$5:$B$271,$A11,'Hisob (batafsil)'!$C$5:$C$271,"Logotip") -> 0 | O11: =SUMIFS('Hisob (batafsil)'!$J$5:$J$271,'Hisob (batafsil)'!$B$5:$B$271,$A11,'Hisob (batafsil)'!$C$5:$C$271,"Matli plyonka") -> 0 | P11: =SUMIFS('Hisob (batafsil)'!$J$5:$J$271,'Hisob (batafsil)'!$B$5:$B$271,$A11,'Hisob (batafsil)'!$C$5:$C$271,"Yong'in xavfsizligi") -> 0 | Q11: =SUMIFS('Hisob (batafsil)'!$J$5:$J$271,'Hisob (batafsil)'!$B$5:$B$271,$A11,'Hisob (batafsil)'!$C$5:$C$271,"Buzish ishlari") -> 0 | R11: =SUMIFS('Hisob (batafsil)'!$J$5:$J$271,'Hisob (batafsil)'!$B$5:$B$271,$A11,'Hisob (batafsil)'!$C$5:$C$271,"Santexnika") -> 0 | S11: =SUMIFS('Hisob (batafsil)'!$J$5:$J$271,'Hisob (batafsil)'!$B$5:$B$271,$A11,'Hisob (batafsil)'!$C$5:$C$271,"Kafel") -> 0 | T11: =C11+E11+G11+I11+K11+L11+M11+N11+O11+P11+Q11+R11+S11 -> 3112.05
A12: 7-xona | B12: =SUMIFS('Hisob (batafsil)'!$G$5:$G$271,'Hisob (batafsil)'!$B$5:$B$271,$A12,'Hisob (batafsil)'!$C$5:$C$271,"Shisha devor") -> 14 | C12: =SUMIFS('Hisob (batafsil)'!$J$5:$J$271,'Hisob (batafsil)'!$B$5:$B$271,$A12,'Hisob (batafsil)'!$C$5:$C$271,"Shisha devor") -> 770 | D12: =SUMIFS('Hisob (batafsil)'!$G$5:$G$271,'Hisob (batafsil)'!$B$5:$B$271,$A12,'Hisob (batafsil)'!$C$5:$C$271,"Gips karton (GKL)") -> 30.45 | E12: =SUMIFS('Hisob (batafsil)'!$J$5:$J$271,'Hisob (batafsil)'!$B$5:$B$271,$A12,'Hisob (batafsil)'!$C$5:$C$271,"Gips karton (GKL)") -> 365.4 | F12: =SUMIFS('Hisob (batafsil)'!$G$5:$G$271,'Hisob (batafsil)'!$B$5:$B$271,$A12,'Hisob (batafsil)'!$C$5:$C$271,"Bambuk panel") -> 53.9 | G12: =SUMIFS('Hisob (batafsil)'!$J$5:$J$271,'Hisob (batafsil)'!$B$5:$B$271,$A12,'Hisob (batafsil)'!$C$5:$C$271,"Bambuk panel") -> 835.45 | H12: =SUMIFS('Hisob (batafsil)'!$G$5:$G$271,'Hisob (batafsil)'!$B$5:$B$271,$A12,'Hisob (batafsil)'!$C$5:$C$271,"Interaktiv doska") -> 1 | I12: =SUMIFS('Hisob (batafsil)'!$J$5:$J$271,'Hisob (batafsil)'!$B$5:$B$271,$A12,'Hisob (batafsil)'!$C$5:$C$271,"Interaktiv doska") -> 1032 | J12: =SUMIFS('Hisob (batafsil)'!$G$5:$G$271,'Hisob (batafsil)'!$B$5:$B$271,$A12,'Hisob (batafsil)'!$C$5:$C$271,"Perila") -> 0 | K12: =SUMIFS('Hisob (batafsil)'!$J$5:$J$271,'Hisob (batafsil)'!$B$5:$B$271,$A12,'Hisob (batafsil)'!$C$5:$C$271,"Perila") -> 0 | L12: =SUMIFS('Hisob (batafsil)'!$J$5:$J$271,'Hisob (batafsil)'!$B$5:$B$271,$A12,'Hisob (batafsil)'!$C$5:$C$271,"Yoritish") -> 168 | M12: =SUMIFS('Hisob (batafsil)'!$J$5:$J$271,'Hisob (batafsil)'!$B$5:$B$271,$A12,'Hisob (batafsil)'!$C$5:$C$271,"Kamera tizimi") -> 0 | N12: =SUMIFS('Hisob (batafsil)'!$J$5:$J$271,'Hisob (batafsil)'!$B$5:$B$271,$A12,'Hisob (batafsil)'!$C$5:$C$271,"Logotip") -> 0 | O12: =SUMIFS('Hisob (batafsil)'!$J$5:$J$271,'Hisob (batafsil)'!$B$5:$B$271,$A12,'Hisob (batafsil)'!$C$5:$C$271,"Matli plyonka") -> 0 | P12: =SUMIFS('Hisob (batafsil)'!$J$5:$J$271,'Hisob (batafsil)'!$B$5:$B$271,$A12,'Hisob (batafsil)'!$C$5:$C$271,"Yong'in xavfsizligi") -> 0 | Q12: =SUMIFS('Hisob (batafsil)'!$J$5:$J$271,'Hisob (batafsil)'!$B$5:$B$271,$A12,'Hisob (batafsil)'!$C$5:$C$271,"Buzish ishlari") -> 0 | R12: =SUMIFS('Hisob (batafsil)'!$J$5:$J$271,'Hisob (batafsil)'!$B$5:$B$271,$A12,'Hisob (batafsil)'!$C$5:$C$271,"Santexnika") -> 0 | S12: =SUMIFS('Hisob (batafsil)'!$J$5:$J$271,'Hisob (batafsil)'!$B$5:$B$271,$A12,'Hisob (batafsil)'!$C$5:$C$271,"Kafel") -> 0 | T12: =C12+E12+G12+I12+K12+L12+M12+N12+O12+P12+Q12+R12+S12 -> 3170.85
A13: 2-qavat: o'quv xonalari — jami | B13: =SUM(B6:B12) -> 72.875 | C13: =SUM(C6:C12) -> 4008.125 | D13: =SUM(D6:D12) -> 156.55 | E13: =SUM(E6:E12) -> 1878.6 | F13: =SUM(F6:F12) -> 373.8 | G13: =SUM(G6:G12) -> 5793.9 | H13: =SUM(H6:H12) -> 7 | I13: =SUM(I6:I12) -> 7224 | ... T13: =SUM(T6:T12) -> 20080.625
A15: 2-qavat: ofis xonalari
A16: Offline sotuv (XZ1) | B16: =SUMIFS('Hisob (batafsil)'!$G$5:$G$271,'Hisob (batafsil)'!$B$5:$B$271,$A16,'Hisob (batafsil)'!$C$5:$C$271,"Shisha devor") -> 7 | C16: =SUMIFS('Hisob (batafsil)'!$J$5:$J$271,'Hisob (batafsil)'!$B$5:$B$271,$A16,'Hisob (batafsil)'!$C$5:$C$271,"Shisha devor") -> 385 | D16: =SUMIFS('Hisob (batafsil)'!$G$5:$G$271,'Hisob (batafsil)'!$B$5:$B$271,$A16,'Hisob (batafsil)'!$C$5:$C$271,"Gips karton (GKL)") -> 34.3 | E16: =SUMIFS('Hisob (batafsil)'!$J$5:$J$271,'Hisob (batafsil)'!$B$5:$B$271,$A16,'Hisob (batafsil)'!$C$5:$C$271,"Gips karton (GKL)") -> 411.6 | F16: =SUMIFS('Hisob (batafsil)'!$G$5:$G$271,'Hisob (batafsil)'!$B$5:$B$271,$A16,'Hisob (batafsil)'!$C$5:$C$271,"Bambuk panel") -> 39.2 | G16: =SUMIFS('Hisob (batafsil)'!$J$5:$J$271,'Hisob (batafsil)'!$B$5:$B$271,$A16,'Hisob (batafsil)'!$C$5:$C$271,"Bambuk panel") -> 607.6 | H16: =SUMIFS('Hisob (batafsil)'!$G$5:$G$271,'Hisob (batafsil)'!$B$5:$B$271,$A16,'Hisob (batafsil)'!$C$5:$C$271,"Interaktiv doska") -> 0 | I16: =SUMIFS('Hisob (batafsil)'!$J$5:$J$271,'Hisob (batafsil)'!$B$5:$B$271,$A16,'Hisob (batafsil)'!$C$5:$C$271,"Interaktiv doska") -> 0 | J16: =SUMIFS('Hisob (batafsil)'!$G$5:$G$271,'Hisob (batafsil)'!$B$5:$B$271,$A16,'Hisob (batafsil)'!$C$5:$C$271,"Perila") -> 0 | K16: =SUMIFS('Hisob (batafsil)'!$J$5:$J$271,'Hisob (batafsil)'!$B$5:$B$271,$A16,'Hisob (batafsil)'!$C$5:$C$271,"Perila") -> 0 | L16: =SUMIFS('Hisob (batafsil)'!$J$5:$J$271,'Hisob (batafsil)'!$B$5:$B$271,$A16,'Hisob (batafsil)'!$C$5:$C$271,"Yoritish") -> 168 | M16: =SUMIFS('Hisob (batafsil)'!$J$5:$J$271,'Hisob (batafsil)'!$B$5:$B$271,$A16,'Hisob (batafsil)'!$C$5:$C$271,"Kamera tizimi") -> 0 | N16: =SUMIFS('Hisob (batafsil)'!$J$5:$J$271,'Hisob (batafsil)'!$B$5:$B$271,$A16,'Hisob (batafsil)'!$C$5:$C$271,"Logotip") -> 0 | O16: =SUMIFS('Hisob (batafsil)'!$J$5:$J$271,'Hisob (batafsil)'!$B$5:$B$271,$A16,'Hisob (batafsil)'!$C$5:$C$271,"Matli plyonka") -> 0 | P16: =SUMIFS('Hisob (batafsil)'!$J$5:$J$271,'Hisob (batafsil)'!$B$5:$B$271,$A16,'Hisob (batafsil)'!$C$5:$C$271,"Yong'in xavfsizligi") -> 0 | Q16: =SUMIFS('Hisob (batafsil)'!$J$5:$J$271,'Hisob (batafsil)'!$B$5:$B$271,$A16,'Hisob (batafsil)'!$C$5:$C$271,"Buzish ishlari") -> 0 | R16: =SUMIFS('Hisob (batafsil)'!$J$5:$J$271,'Hisob (batafsil)'!$B$5:$B$271,$A16,'Hisob (batafsil)'!$C$5:$C$271,"Santexnika") -> 0 | S16: =SUMIFS('Hisob (batafsil)'!$J$5:$J$271,'Hisob (batafsil)'!$B$5:$B$271,$A16,'Hisob (batafsil)'!$C$5:$C$271,"Kafel") -> 0 | T16: =C16+E16+G16+I16+K16+L16+M16+N16+O16+P16+Q16+R16+S16 -> 1572.2
A17: Admin (XZ2) | B17: =SUMIFS('Hisob (batafsil)'!$G$5:$G$271,'Hisob (batafsil)'!$B$5:$B$271,$A17,'Hisob (batafsil)'!$C$5:$C$271,"Shisha devor") -> 7 | C17: =SUMIFS('Hisob (batafsil)'!$J$5:$J$271,'Hisob (batafsil)'!$B$5:$B$271,$A17,'Hisob (batafsil)'!$C$5:$C$271,"Shisha devor") -> 385 | D17: =SUMIFS('Hisob (batafsil)'!$G$5:$G$271,'Hisob (batafsil)'!$B$5:$B$271,$A17,'Hisob (batafsil)'!$C$5:$C$271,"Gips karton (GKL)") -> 35.35 | E17: =SUMIFS('Hisob (batafsil)'!$J$5:$J$271,'Hisob (batafsil)'!$B$5:$B$271,$A17,'Hisob (batafsil)'!$C$5:$C$271,"Gips karton (GKL)") -> 424.2 | F17: =SUMIFS('Hisob (batafsil)'!$G$5:$G$271,'Hisob (batafsil)'!$B$5:$B$271,$A17,'Hisob (batafsil)'!$C$5:$C$271,"Bambuk panel") -> 39.2 | G17: =SUMIFS('Hisob (batafsil)'!$J$5:$J$271,'Hisob (batafsil)'!$B$5:$B$271,$A17,'Hisob (batafsil)'!$C$5:$C$271,"Bambuk panel") -> 607.6 | H17: =SUMIFS('Hisob (batafsil)'!$G$5:$G$271,'Hisob (batafsil)'!$B$5:$B$271,$A17,'Hisob (batafsil)'!$C$5:$C$271,"Interaktiv doska") -> 0 | I17: =SUMIFS('Hisob (batafsil)'!$J$5:$J$271,'Hisob (batafsil)'!$B$5:$B$271,$A17,'Hisob (batafsil)'!$C$5:$C$271,"Interaktiv doska") -> 0 | J17: =SUMIFS('Hisob (batafsil)'!$G$5:$G$271,'Hisob (batafsil)'!$B$5:$B$271,$A17,'Hisob (batafsil)'!$C$5:$C$271,"Perila") -> 0 | K17: =SUMIFS('Hisob (batafsil)'!$J$5:$J$271,'Hisob (batafsil)'!$B$5:$B$271,$A17,'Hisob (batafsil)'!$C$5:$C$271,"Perila") -> 0 | L17: =SUMIFS('Hisob (batafsil)'!$J$5:$J$271,'Hisob (batafsil)'!$B$5:$B$271,$A17,'Hisob (batafsil)'!$C$5:$C$271,"Yoritish") -> 168 | M17: =SUMIFS('Hisob (batafsil)'!$J$5:$J$271,'Hisob (batafsil)'!$B$5:$B$271,$A17,'Hisob (batafsil)'!$C$5:$C$271,"Kamera tizimi") -> 0 | N17: =SUMIFS('Hisob (batafsil)'!$J$5:$J$271,'Hisob (batafsil)'!$B$5:$B$271,$A17,'Hisob (batafsil)'!$C$5:$C$271,"Logotip") -> 0 | O17: =SUMIFS('Hisob (batafsil)'!$J$5:$J$271,'Hisob (batafsil)'!$B$5:$B$271,$A17,'Hisob (batafsil)'!$C$5:$C$271,"Matli plyonka") -> 0 | P17: =SUMIFS('Hisob (batafsil)'!$J$5:$J$271,'Hisob (batafsil)'!$B$5:$B$271,$A17,'Hisob (batafsil)'!$C$5:$C$271,"Yong'in xavfsizligi") -> 0 | Q17: =SUMIFS('Hisob (batafsil)'!$J$5:$J$271,'Hisob (batafsil)'!$B$5:$B$271,$A17,'Hisob (batafsil)'!$C$5:$C$271,"Buzish ishlari") -> 0 | R17: =SUMIFS('Hisob (batafsil)'!$J$5:$J$271,'Hisob (batafsil)'!$B$5:$B$271,$A17,'Hisob (batafsil)'!$C$5:$C$271,"Santexnika") -> 0 | S17: =SUMIFS('Hisob (batafsil)'!$J$5:$J$271,'Hisob (batafsil)'!$B$5:$B$271,$A17,'Hisob (batafsil)'!$C$5:$C$271,"Kafel") -> 0 | T17: =C17+E17+G17+I17+K17+L17+M17+N17+O17+P17+Q17+R17+S17 -> 1584.8
A18: Ustozlar xonasi (XZ3) | B18: =SUMIFS('Hisob (batafsil)'!$G$5:$G$271,'Hisob (batafsil)'!$B$5:$B$271,$A18,'Hisob (batafsil)'!$C$5:$C$271,"Shisha devor") -> 7.125 | C18: =SUMIFS('Hisob (batafsil)'!$J$5:$J$271,'Hisob (batafsil)'!$B$5:$B$271,$A18,'Hisob (batafsil)'!$C$5:$C$271,"Shisha devor") -> 391.875 | D18: =SUMIFS('Hisob (batafsil)'!$G$5:$G$271,'Hisob (batafsil)'!$B$5:$B$271,$A18,'Hisob (batafsil)'!$C$5:$C$271,"Gips karton (GKL)") -> 35.575 | E18: =SUMIFS('Hisob (batafsil)'!$J$5:$J$271,'Hisob (batafsil)'!$B$5:$B$271,$A18,'Hisob (batafsil)'!$C$5:$C$271,"Gips karton (GKL)") -> 426.9 | F18: =SUMIFS('Hisob (batafsil)'!$G$5:$G$271,'Hisob (batafsil)'!$B$5:$B$271,$A18,'Hisob (batafsil)'!$C$5:$C$271,"Bambuk panel") -> 39.2 | G18: =SUMIFS('Hisob (batafsil)'!$J$5:$J$271,'Hisob (batafsil)'!$B$5:$B$271,$A18,'Hisob (batafsil)'!$C$5:$C$271,"Bambuk panel") -> 607.6 | H18: =SUMIFS('Hisob (batafsil)'!$G$5:$G$271,'Hisob (batafsil)'!$B$5:$B$271,$A18,'Hisob (batafsil)'!$C$5:$C$271,"Interaktiv doska") -> 0 | I18: =SUMIFS('Hisob (batafsil)'!$J$5:$J$271,'Hisob (batafsil)'!$B$5:$B$271,$A18,'Hisob (batafsil)'!$C$5:$C$271,"Interaktiv doska") -> 0 | J18: =SUMIFS('Hisob (batafsil)'!$G$5:$G$271,'Hisob (batafsil)'!$B$5:$B$271,$A18,'Hisob (batafsil)'!$C$5:$C$271,"Perila") -> 0 | K18: =SUMIFS('Hisob (batafsil)'!$J$5:$J$271,'Hisob (batafsil)'!$B$5:$B$271,$A18,'Hisob (batafsil)'!$C$5:$C$271,"Perila") -> 0 | L18: =SUMIFS('Hisob (batafsil)'!$J$5:$J$271,'Hisob (batafsil)'!$B$5:$B$271,$A18,'Hisob (batafsil)'!$C$5:$C$271,"Yoritish") -> 168 | M18: =SUMIFS('Hisob (batafsil)'!$J$5:$J$271,'Hisob (batafsil)'!$B$5:$B$271,$A18,'Hisob (batafsil)'!$C$5:$C$271,"Kamera tizimi") -> 0 | N18: =SUMIFS('Hisob (batafsil)'!$J$5:$J$271,'Hisob (batafsil)'!$B$5:$B$271,$A18,'Hisob (batafsil)'!$C$5:$C$271,"Logotip") -> 0 | O18: =SUMIFS('Hisob (batafsil)'!$J$5:$J$271,'Hisob (batafsil)'!$B$5:$B$271,$A18,'Hisob (batafsil)'!$C$5:$C$271,"Matli plyonka") -> 0 | P18: =SUMIFS('Hisob (batafsil)'!$J$5:$J$271,'Hisob (batafsil)'!$B$5:$B$271,$A18,'Hisob (batafsil)'!$C$5:$C$271,"Yong'in xavfsizligi") -> 0 | Q18: =SUMIFS('Hisob (batafsil)'!$J$5:$J$271,'Hisob (batafsil)'!$B$5:$B$271,$A18,'Hisob (batafsil)'!$C$5:$C$271,"Buzish ishlari") -> 0 | R18: =SUMIFS('Hisob (batafsil)'!$J$5:$J$271,'Hisob (batafsil)'!$B$5:$B$271,$A18,'Hisob (batafsil)'!$C$5:$C$271,"Santexnika") -> 0 | S18: =SUMIFS('Hisob (batafsil)'!$J$5:$J$271,'Hisob (batafsil)'!$B$5:$B$271,$A18,'Hisob (batafsil)'!$C$5:$C$271,"Kafel") -> 0 | T18: =C18+E18+G18+I18+K18+L18+M18+N18+O18+P18+Q18+R18+S18 -> 1594.375
A19: Call-markaz (XZ4) | B19: =SUMIFS('Hisob (batafsil)'!$G$5:$G$271,'Hisob (batafsil)'!$B$5:$B$271,$A19,'Hisob (batafsil)'!$C$5:$C$271,"Shisha devor") -> 7.125 | C19: =SUMIFS('Hisob (batafsil)'!$J$5:$J$271,'Hisob (batafsil)'!$B$5:$B$271,$A19,'Hisob (batafsil)'!$C$5:$C$271,"Shisha devor") -> 391.875 | D19: =SUMIFS('Hisob (batafsil)'!$G$5:$G$271,'Hisob (batafsil)'!$B$5:$B$271,$A19,'Hisob (batafsil)'!$C$5:$C$271,"Gips karton (GKL)") -> 35.925 | E19: =SUMIFS('Hisob (batafsil)'!$J$5:$J$271,'Hisob (batafsil)'!$B$5:$B$271,$A19,'Hisob (batafsil)'!$C$5:$C$271,"Gips karton (GKL)") -> 431.1 | F19: =SUMIFS('Hisob (batafsil)'!$G$5:$G$271,'Hisob (batafsil)'!$B$5:$B$271,$A19,'Hisob (batafsil)'!$C$5:$C$271,"Bambuk panel") -> 39.2 | G19: =SUMIFS('Hisob (batafsil)'!$J$5:$J$271,'Hisob (batafsil)'!$B$5:$B$271,$A19,'Hisob (batafsil)'!$C$5:$C$271,"Bambuk panel") -> 607.6 | H19: =SUMIFS('Hisob (batafsil)'!$G$5:$G$271,'Hisob (batafsil)'!$B$5:$B$271,$A19,'Hisob (batafsil)'!$C$5:$C$271,"Interaktiv doska") -> 0 | I19: =SUMIFS('Hisob (batafsil)'!$J$5:$J$271,'Hisob (batafsil)'!$B$5:$B$271,$A19,'Hisob (batafsil)'!$C$5:$C$271,"Interaktiv doska") -> 0 | J19: =SUMIFS('Hisob (batafsil)'!$G$5:$G$271,'Hisob (batafsil)'!$B$5:$B$271,$A19,'Hisob (batafsil)'!$C$5:$C$271,"Perila") -> 0 | K19: =SUMIFS('Hisob (batafsil)'!$J$5:$J$271,'Hisob (batafsil)'!$B$5:$B$271,$A19,'Hisob (batafsil)'!$C$5:$C$271,"Perila") -> 0 | L19: =SUMIFS('Hisob (batafsil)'!$J$5:$J$271,'Hisob (batafsil)'!$B$5:$B$271,$A19,'Hisob (batafsil)'!$C$5:$C$271,"Yoritish") -> 168 | M19: =SUMIFS('Hisob (batafsil)'!$J$5:$J$271,'Hisob (batafsil)'!$B$5:$B$271,$A19,'Hisob (batafsil)'!$C$5:$C$271,"Kamera tizimi") -> 0 | N19: =SUMIFS('Hisob (batafsil)'!$J$5:$J$271,'Hisob (batafsil)'!$B$5:$B$271,$A19,'Hisob (batafsil)'!$C$5:$C$271,"Logotip") -> 0 | O19: =SUMIFS('Hisob (batafsil)'!$J$5:$J$271,'Hisob (batafsil)'!$B$5:$B$271,$A19,'Hisob (batafsil)'!$C$5:$C$271,"Matli plyonka") -> 0 | P19: =SUMIFS('Hisob (batafsil)'!$J$5:$J$271,'Hisob (batafsil)'!$B$5:$B$271,$A19,'Hisob (batafsil)'!$C$5:$C$271,"Yong'in xavfsizligi") -> 0 | Q19: =SUMIFS('Hisob (batafsil)'!$J$5:$J$271,'Hisob (batafsil)'!$B$5:$B$271,$A19,'Hisob (batafsil)'!$C$5:$C$271,"Buzish ishlari") -> 0 | R19: =SUMIFS('Hisob (batafsil)'!$J$5:$J$271,'Hisob (batafsil)'!$B$5:$B$271,$A19,'Hisob (batafsil)'!$C$5:$C$271,"Santexnika") -> 0 | S19: =SUMIFS('Hisob (batafsil)'!$J$5:$J$271,'Hisob (batafsil)'!$B$5:$B$271,$A19,'Hisob (batafsil)'!$C$5:$C$271,"Kafel") -> 0 | T19: =C19+E19+G19+I19+K19+L19+M19+N19+O19+P19+Q19+R19+S19 -> 1598.575
A20: CEO xonasi (12-xona) | B20: =SUMIFS('Hisob (batafsil)'!$G$5:$G$271,'Hisob (batafsil)'!$B$5:$B$271,$A20,'Hisob (batafsil)'!$C$5:$C$271,"Shisha devor") -> 0 | C20: =SUMIFS('Hisob (batafsil)'!$J$5:$J$271,'Hisob (batafsil)'!$B$5:$B$271,$A20,'Hisob (batafsil)'!$C$5:$C$271,"Shisha devor") -> 0 | D20: =SUMIFS('Hisob (batafsil)'!$G$5:$G$271,'Hisob (batafsil)'!$B$5:$B$271,$A20,'Hisob (batafsil)'!$C$5:$C$271,"Gips karton (GKL)") -> 0 | E20: =SUMIFS('Hisob (batafsil)'!$J$5:$J$271,'Hisob (batafsil)'!$B$5:$B$271,$A20,'Hisob (batafsil)'!$C$5:$C$271,"Gips karton (GKL)") -> 0 | F20: =SUMIFS('Hisob (batafsil)'!$G$5:$G$271,'Hisob (batafsil)'!$B$5:$B$271,$A20,'Hisob (batafsil)'!$C$5:$C$271,"Bambuk panel") -> 29.26 | G20: =SUMIFS('Hisob (batafsil)'!$J$5:$J$271,'Hisob (batafsil)'!$B$5:$B$271,$A20,'Hisob (batafsil)'!$C$5:$C$271,"Bambuk panel") -> 453.53 | H20: =SUMIFS('Hisob (batafsil)'!$G$5:$G$271,'Hisob (batafsil)'!$B$5:$B$271,$A20,'Hisob (batafsil)'!$C$5:$C$271,"Interaktiv doska") -> 0 | I20: =SUMIFS('Hisob (batafsil)'!$J$5:$J$271,'Hisob (batafsil)'!$B$5:$B$271,$A20,'Hisob (batafsil)'!$C$5:$C$271,"Interaktiv doska") -> 0 | J20: =SUMIFS('Hisob (batafsil)'!$G$5:$G$271,'Hisob (batafsil)'!$B$5:$B$271,$A20,'Hisob (batafsil)'!$C$5:$C$271,"Perila") -> 0 | K20: =SUMIFS('Hisob (batafsil)'!$J$5:$J$271,'Hisob (batafsil)'!$B$5:$B$271,$A20,'Hisob (batafsil)'!$C$5:$C$271,"Perila") -> 0 | L20: =SUMIFS('Hisob (batafsil)'!$J$5:$J$271,'Hisob (batafsil)'!$B$5:$B$271,$A20,'Hisob (batafsil)'!$C$5:$C$271,"Yoritish") -> 168 | M20: =SUMIFS('Hisob (batafsil)'!$J$5:$J$271,'Hisob (batafsil)'!$B$5:$B$271,$A20,'Hisob (batafsil)'!$C$5:$C$271,"Kamera tizimi") -> 0 | N20: =SUMIFS('Hisob (batafsil)'!$J$5:$J$271,'Hisob (batafsil)'!$B$5:$B$271,$A20,'Hisob (batafsil)'!$C$5:$C$271,"Logotip") -> 0 | O20: =SUMIFS('Hisob (batafsil)'!$J$5:$J$271,'Hisob (batafsil)'!$B$5:$B$271,$A20,'Hisob (batafsil)'!$C$5:$C$271,"Matli plyonka") -> 0 | P20: =SUMIFS('Hisob (batafsil)'!$J$5:$J$271,'Hisob (batafsil)'!$B$5:$B$271,$A20,'Hisob (batafsil)'!$C$5:$C$271,"Yong'in xavfsizligi") -> 0 | Q20: =SUMIFS('Hisob (batafsil)'!$J$5:$J$271,'Hisob (batafsil)'!$B$5:$B$271,$A20,'Hisob (batafsil)'!$C$5:$C$271,"Buzish ishlari") -> 0 | R20: =SUMIFS('Hisob (batafsil)'!$J$5:$J$271,'Hisob (batafsil)'!$B$5:$B$271,$A20,'Hisob (batafsil)'!$C$5:$C$271,"Santexnika") -> 0 | S20: =SUMIFS('Hisob (batafsil)'!$J$5:$J$271,'Hisob (batafsil)'!$B$5:$B$271,$A20,'Hisob (batafsil)'!$C$5:$C$271,"Kafel") -> 0 | T20: =C20+E20+G20+I20+K20+L20+M20+N20+O20+P20+Q20+R20+S20 -> 621.53
A21: 2-qavat: ofis xonalari — jami | B21: =SUM(B16:B20) -> 28.25 | C21: =SUM(C16:C20) -> 1553.75 | D21: =SUM(D16:D20) -> 141.15 | E21: =SUM(E16:E20) -> 1693.8 | F21: =SUM(F16:F20) -> 186.06 | G21: =SUM(G16:G20) -> 2883.93 | H21: =SUM(H16:H20) -> 0 | I21: =SUM(I16:I20) -> 0 | ... T21: =SUM(T16:T20) -> 6971.48
A23: 2-qavat: umumiy joylar
A24: K1 koridori | B24: =SUMIFS('Hisob (batafsil)'!$G$5:$G$271,'Hisob (batafsil)'!$B$5:$B$271,$A24,'Hisob (batafsil)'!$C$5:$C$271,"Shisha devor") -> 0 | C24: =SUMIFS('Hisob (batafsil)'!$J$5:$J$271,'Hisob (batafsil)'!$B$5:$B$271,$A24,'Hisob (batafsil)'!$C$5:$C$271,"Shisha devor") -> 0 | D24: =SUMIFS('Hisob (batafsil)'!$G$5:$G$271,'Hisob (batafsil)'!$B$5:$B$271,$A24,'Hisob (batafsil)'!$C$5:$C$271,"Gips karton (GKL)") -> 45.375 | E24: =SUMIFS('Hisob (batafsil)'!$J$5:$J$271,'Hisob (batafsil)'!$B$5:$B$271,$A24,'Hisob (batafsil)'!$C$5:$C$271,"Gips karton (GKL)") -> 544.5 | F24: =SUMIFS('Hisob (batafsil)'!$G$5:$G$271,'Hisob (batafsil)'!$B$5:$B$271,$A24,'Hisob (batafsil)'!$C$5:$C$271,"Bambuk panel") -> 0 | G24: =SUMIFS('Hisob (batafsil)'!$J$5:$J$271,'Hisob (batafsil)'!$B$5:$B$271,$A24,'Hisob (batafsil)'!$C$5:$C$271,"Bambuk panel") -> 0 | H24: =SUMIFS('Hisob (batafsil)'!$G$5:$G$271,'Hisob (batafsil)'!$B$5:$B$271,$A24,'Hisob (batafsil)'!$C$5:$C$271,"Interaktiv doska") -> 0 | I24: =SUMIFS('Hisob (batafsil)'!$J$5:$J$271,'Hisob (batafsil)'!$B$5:$B$271,$A24,'Hisob (batafsil)'!$C$5:$C$271,"Interaktiv doska") -> 0 | J24: =SUMIFS('Hisob (batafsil)'!$G$5:$G$271,'Hisob (batafsil)'!$B$5:$B$271,$A24,'Hisob (batafsil)'!$C$5:$C$271,"Perila") -> 0 | K24: =SUMIFS('Hisob (batafsil)'!$J$5:$J$271,'Hisob (batafsil)'!$B$5:$B$271,$A24,'Hisob (batafsil)'!$C$5:$C$271,"Perila") -> 0 | L24: =SUMIFS('Hisob (batafsil)'!$J$5:$J$271,'Hisob (batafsil)'!$B$5:$B$271,$A24,'Hisob (batafsil)'!$C$5:$C$271,"Yoritish") -> 336 | M24: =SUMIFS('Hisob (batafsil)'!$J$5:$J$271,'Hisob (batafsil)'!$B$5:$B$271,$A24,'Hisob (batafsil)'!$C$5:$C$271,"Kamera tizimi") -> 0 | N24: =SUMIFS('Hisob (batafsil)'!$J$5:$J$271,'Hisob (batafsil)'!$B$5:$B$271,$A24,'Hisob (batafsil)'!$C$5:$C$271,"Logotip") -> 0 | O24: =SUMIFS('Hisob (batafsil)'!$J$5:$J$271,'Hisob (batafsil)'!$B$5:$B$271,$A24,'Hisob (batafsil)'!$C$5:$C$271,"Matli plyonka") -> 0 | P24: =SUMIFS('Hisob (batafsil)'!$J$5:$J$271,'Hisob (batafsil)'!$B$5:$B$271,$A24,'Hisob (batafsil)'!$C$5:$C$271,"Yong'in xavfsizligi") -> 0 | Q24: =SUMIFS('Hisob (batafsil)'!$J$5:$J$271,'Hisob (batafsil)'!$B$5:$B$271,$A24,'Hisob (batafsil)'!$C$5:$C$271,"Buzish ishlari") -> 0 | R24: =SUMIFS('Hisob (batafsil)'!$J$5:$J$271,'Hisob (batafsil)'!$B$5:$B$271,$A24,'Hisob (batafsil)'!$C$5:$C$271,"Santexnika") -> 0 | S24: =SUMIFS('Hisob (batafsil)'!$J$5:$J$271,'Hisob (batafsil)'!$B$5:$B$271,$A24,'Hisob (batafsil)'!$C$5:$C$271,"Kafel") -> 0 | T24: =C24+E24+G24+I24+K24+L24+M24+N24+O24+P24+Q24+R24+S24 -> 880.5
A25: K2 koridori | B25: =SUMIFS('Hisob (batafsil)'!$G$5:$G$271,'Hisob (batafsil)'!$B$5:$B$271,$A25,'Hisob (batafsil)'!$C$5:$C$271,"Shisha devor") -> 0 | C25: =SUMIFS('Hisob (batafsil)'!$J$5:$J$271,'Hisob (batafsil)'!$B$5:$B$271,$A25,'Hisob (batafsil)'!$C$5:$C$271,"Shisha devor") -> 0 | D25: =SUMIFS('Hisob (batafsil)'!$G$5:$G$271,'Hisob (batafsil)'!$B$5:$B$271,$A25,'Hisob (batafsil)'!$C$5:$C$271,"Gips karton (GKL)") -> 46.35 | E25: =SUMIFS('Hisob (batafsil)'!$J$5:$J$271,'Hisob (batafsil)'!$B$5:$B$271,$A25,'Hisob (batafsil)'!$C$5:$C$271,"Gips karton (GKL)") -> 556.2 | F25: =SUMIFS('Hisob (batafsil)'!$G$5:$G$271,'Hisob (batafsil)'!$B$5:$B$271,$A25,'Hisob (batafsil)'!$C$5:$C$271,"Bambuk panel") -> 0 | G25: =SUMIFS('Hisob (batafsil)'!$J$5:$J$271,'Hisob (batafsil)'!$B$5:$B$271,$A25,'Hisob (batafsil)'!$C$5:$C$271,"Bambuk panel") -> 0 | H25: =SUMIFS('Hisob (batafsil)'!$G$5:$G$271,'Hisob (batafsil)'!$B$5:$B$271,$A25,'Hisob (batafsil)'!$C$5:$C$271,"Interaktiv doska") -> 0 | I25: =SUMIFS('Hisob (batafsil)'!$J$5:$J$271,'Hisob (batafsil)'!$B$5:$B$271,$A25,'Hisob (batafsil)'!$C$5:$C$271,"Interaktiv doska") -> 0 | J25: =SUMIFS('Hisob (batafsil)'!$G$5:$G$271,'Hisob (batafsil)'!$B$5:$B$271,$A25,'Hisob (batafsil)'!$C$5:$C$271,"Perila") -> 0 | K25: =SUMIFS('Hisob (batafsil)'!$J$5:$J$271,'Hisob (batafsil)'!$B$5:$B$271,$A25,'Hisob (batafsil)'!$C$5:$C$271,"Perila") -> 0 | L25: =SUMIFS('Hisob (batafsil)'!$J$5:$J$271,'Hisob (batafsil)'!$B$5:$B$271,$A25,'Hisob (batafsil)'!$C$5:$C$271,"Yoritish") -> 336 | M25: =SUMIFS('Hisob (batafsil)'!$J$5:$J$271,'Hisob (batafsil)'!$B$5:$B$271,$A25,'Hisob (batafsil)'!$C$5:$C$271,"Kamera tizimi") -> 0 | N25: =SUMIFS('Hisob (batafsil)'!$J$5:$J$271,'Hisob (batafsil)'!$B$5:$B$271,$A25,'Hisob (batafsil)'!$C$5:$C$271,"Logotip") -> 0 | O25: =SUMIFS('Hisob (batafsil)'!$J$5:$J$271,'Hisob (batafsil)'!$B$5:$B$271,$A25,'Hisob (batafsil)'!$C$5:$C$271,"Matli plyonka") -> 0 | P25: =SUMIFS('Hisob (batafsil)'!$J$5:$J$271,'Hisob (batafsil)'!$B$5:$B$271,$A25,'Hisob (batafsil)'!$C$5:$C$271,"Yong'in xavfsizligi") -> 0 | Q25: =SUMIFS('Hisob (batafsil)'!$J$5:$J$271,'Hisob (batafsil)'!$B$5:$B$271,$A25,'Hisob (batafsil)'!$C$5:$C$271,"Buzish ishlari") -> 0 | R25: =SUMIFS('Hisob (batafsil)'!$J$5:$J$271,'Hisob (batafsil)'!$B$5:$B$271,$A25,'Hisob (batafsil)'!$C$5:$C$271,"Santexnika") -> 0 | S25: =SUMIFS('Hisob (batafsil)'!$J$5:$J$271,'Hisob (batafsil)'!$B$5:$B$271,$A25,'Hisob (batafsil)'!$C$5:$C$271,"Kafel") -> 0 | T25: =C25+E25+G25+I25+K25+L25+M25+N25+O25+P25+Q25+R25+S25 -> 892.2
A26: Koworking zali | B26: =SUMIFS('Hisob (batafsil)'!$G$5:$G$271,'Hisob (batafsil)'!$B$5:$B$271,$A26,'Hisob (batafsil)'!$C$5:$C$271,"Shisha devor") -> 0 | C26: =SUMIFS('Hisob (batafsil)'!$J$5:$J$271,'Hisob (batafsil)'!$B$5:$B$271,$A26,'Hisob (batafsil)'!$C$5:$C$271,"Shisha devor") -> 0 | D26: =SUMIFS('Hisob (batafsil)'!$G$5:$G$271,'Hisob (batafsil)'!$B$5:$B$271,$A26,'Hisob (batafsil)'!$C$5:$C$271,"Gips karton (GKL)") -> 9.625 | E26: =SUMIFS('Hisob (batafsil)'!$J$5:$J$271,'Hisob (batafsil)'!$B$5:$B$271,$A26,'Hisob (batafsil)'!$C$5:$C$271,"Gips karton (GKL)") -> 115.5 | F26: =SUMIFS('Hisob (batafsil)'!$G$5:$G$271,'Hisob (batafsil)'!$B$5:$B$271,$A26,'Hisob (batafsil)'!$C$5:$C$271,"Bambuk panel") -> 0 | G26: =SUMIFS('Hisob (batafsil)'!$J$5:$J$271,'Hisob (batafsil)'!$B$5:$B$271,$A26,'Hisob (batafsil)'!$C$5:$C$271,"Bambuk panel") -> 0 | H26: =SUMIFS('Hisob (batafsil)'!$G$5:$G$271,'Hisob (batafsil)'!$B$5:$B$271,$A26,'Hisob (batafsil)'!$C$5:$C$271,"Interaktiv doska") -> 0 | I26: =SUMIFS('Hisob (batafsil)'!$J$5:$J$271,'Hisob (batafsil)'!$B$5:$B$271,$A26,'Hisob (batafsil)'!$C$5:$C$271,"Interaktiv doska") -> 0 | J26: =SUMIFS('Hisob (batafsil)'!$G$5:$G$271,'Hisob (batafsil)'!$B$5:$B$271,$A26,'Hisob (batafsil)'!$C$5:$C$271,"Perila") -> 0 | K26: =SUMIFS('Hisob (batafsil)'!$J$5:$J$271,'Hisob (batafsil)'!$B$5:$B$271,$A26,'Hisob (batafsil)'!$C$5:$C$271,"Perila") -> 0 | L26: =SUMIFS('Hisob (batafsil)'!$J$5:$J$271,'Hisob (batafsil)'!$B$5:$B$271,$A26,'Hisob (batafsil)'!$C$5:$C$271,"Yoritish") -> 336 | M26: =SUMIFS('Hisob (batafsil)'!$J$5:$J$271,'Hisob (batafsil)'!$B$5:$B$271,$A26,'Hisob (batafsil)'!$C$5:$C$271,"Kamera tizimi") -> 0 | N26: =SUMIFS('Hisob (batafsil)'!$J$5:$J$271,'Hisob (batafsil)'!$B$5:$B$271,$A26,'Hisob (batafsil)'!$C$5:$C$271,"Logotip") -> 0 | O26: =SUMIFS('Hisob (batafsil)'!$J$5:$J$271,'Hisob (batafsil)'!$B$5:$B$271,$A26,'Hisob (batafsil)'!$C$5:$C$271,"Matli plyonka") -> 0 | P26: =SUMIFS('Hisob (batafsil)'!$J$5:$J$271,'Hisob (batafsil)'!$B$5:$B$271,$A26,'Hisob (batafsil)'!$C$5:$C$271,"Yong'in xavfsizligi") -> 0 | Q26: =SUMIFS('Hisob (batafsil)'!$J$5:$J$271,'Hisob (batafsil)'!$B$5:$B$271,$A26,'Hisob (batafsil)'!$C$5:$C$271,"Buzish ishlari") -> 0 | R26: =SUMIFS('Hisob (batafsil)'!$J$5:$J$271,'Hisob (batafsil)'!$B$5:$B$271,$A26,'Hisob (batafsil)'!$C$5:$C$271,"Santexnika") -> 0 | S26: =SUMIFS('Hisob (batafsil)'!$J$5:$J$271,'Hisob (batafsil)'!$B$5:$B$271,$A26,'Hisob (batafsil)'!$C$5:$C$271,"Kafel") -> 0 | T26: =C26+E26+G26+I26+K26+L26+M26+N26+O26+P26+Q26+R26+S26 -> 451.5
A27: Kirish zali | B27: =SUMIFS('Hisob (batafsil)'!$G$5:$G$271,'Hisob (batafsil)'!$B$5:$B$271,$A27,'Hisob (batafsil)'!$C$5:$C$271,"Shisha devor") -> 0 | C27: =SUMIFS('Hisob (batafsil)'!$J$5:$J$271,'Hisob (batafsil)'!$B$5:$B$271,$A27,'Hisob (batafsil)'!$C$5:$C$271,"Shisha devor") -> 0 | D27: =SUMIFS('Hisob (batafsil)'!$G$5:$G$271,'Hisob (batafsil)'!$B$5:$B$271,$A27,'Hisob (batafsil)'!$C$5:$C$271,"Gips karton (GKL)") -> 9.1 | E27: =SUMIFS('Hisob (batafsil)'!$J$5:$J$271,'Hisob (batafsil)'!$B$5:$B$271,$A27,'Hisob (batafsil)'!$C$5:$C$271,"Gips karton (GKL)") -> 109.2 | F27: =SUMIFS('Hisob (batafsil)'!$G$5:$G$271,'Hisob (batafsil)'!$B$5:$B$271,$A27,'Hisob (batafsil)'!$C$5:$C$271,"Bambuk panel") -> 0 | G27: =SUMIFS('Hisob (batafsil)'!$J$5:$J$271,'Hisob (batafsil)'!$B$5:$B$271,$A27,'Hisob (batafsil)'!$C$5:$C$271,"Bambuk panel") -> 0 | H27: =SUMIFS('Hisob (batafsil)'!$G$5:$G$271,'Hisob (batafsil)'!$B$5:$B$271,$A27,'Hisob (batafsil)'!$C$5:$C$271,"Interaktiv doska") -> 0 | I27: =SUMIFS('Hisob (batafsil)'!$J$5:$J$271,'Hisob (batafsil)'!$B$5:$B$271,$A27,'Hisob (batafsil)'!$C$5:$C$271,"Interaktiv doska") -> 0 | J27: =SUMIFS('Hisob (batafsil)'!$G$5:$G$271,'Hisob (batafsil)'!$B$5:$B$271,$A27,'Hisob (batafsil)'!$C$5:$C$271,"Perila") -> 0 | K27: =SUMIFS('Hisob (batafsil)'!$J$5:$J$271,'Hisob (batafsil)'!$B$5:$B$271,$A27,'Hisob (batafsil)'!$C$5:$C$271,"Perila") -> 0 | L27: =SUMIFS('Hisob (batafsil)'!$J$5:$J$271,'Hisob (batafsil)'!$B$5:$B$271,$A27,'Hisob (batafsil)'!$C$5:$C$271,"Yoritish") -> 0 | M27: =SUMIFS('Hisob (batafsil)'!$J$5:$J$271,'Hisob (batafsil)'!$B$5:$B$271,$A27,'Hisob (batafsil)'!$C$5:$C$271,"Kamera tizimi") -> 0 | N27: =SUMIFS('Hisob (batafsil)'!$J$5:$J$271,'Hisob (batafsil)'!$B$5:$B$271,$A27,'Hisob (batafsil)'!$C$5:$C$271,"Logotip") -> 0 | O27: =SUMIFS('Hisob (batafsil)'!$J$5:$J$271,'Hisob (batafsil)'!$B$5:$B$271,$A27,'Hisob (batafsil)'!$C$5:$C$271,"Matli plyonka") -> 0 | P27: =SUMIFS('Hisob (batafsil)'!$J$5:$J$271,'Hisob (batafsil)'!$B$5:$B$271,$A27,'Hisob (batafsil)'!$C$5:$C$271,"Yong'in xavfsizligi") -> 0 | Q27: =SUMIFS('Hisob (batafsil)'!$J$5:$J$271,'Hisob (batafsil)'!$B$5:$B$271,$A27,'Hisob (batafsil)'!$C$5:$C$271,"Buzish ishlari") -> 0 | R27: =SUMIFS('Hisob (batafsil)'!$J$5:$J$271,'Hisob (batafsil)'!$B$5:$B$271,$A27,'Hisob (batafsil)'!$C$5:$C$271,"Santexnika") -> 0 | S27: =SUMIFS('Hisob (batafsil)'!$J$5:$J$271,'Hisob (batafsil)'!$B$5:$B$271,$A27,'Hisob (batafsil)'!$C$5:$C$271,"Kafel") -> 0 | T27: =C27+E27+G27+I27+K27+L27+M27+N27+O27+P27+Q27+R27+S27 -> 109.2
A28: Zinapoya | B28: =SUMIFS('Hisob (batafsil)'!$G$5:$G$271,'Hisob (batafsil)'!$B$5:$B$271,$A28,'Hisob (batafsil)'!$C$5:$C$271,"Shisha devor") -> 0 | C28: =SUMIFS('Hisob (batafsil)'!$J$5:$J$271,'Hisob (batafsil)'!$B$5:$B$271,$A28,'Hisob (batafsil)'!$C$5:$C$271,"Shisha devor") -> 0 | D28: =SUMIFS('Hisob (batafsil)'!$G$5:$G$271,'Hisob (batafsil)'!$B$5:$B$271,$A28,'Hisob (batafsil)'!$C$5:$C$271,"Gips karton (GKL)") -> 0 | E28: =SUMIFS('Hisob (batafsil)'!$J$5:$J$271,'Hisob (batafsil)'!$B$5:$B$271,$A28,'Hisob (batafsil)'!$C$5:$C$271,"Gips karton (GKL)") -> 0 | F28: =SUMIFS('Hisob (batafsil)'!$G$5:$G$271,'Hisob (batafsil)'!$B$5:$B$271,$A28,'Hisob (batafsil)'!$C$5:$C$271,"Bambuk panel") -> 0 | G28: =SUMIFS('Hisob (batafsil)'!$J$5:$J$271,'Hisob (batafsil)'!$B$5:$B$271,$A28,'Hisob (batafsil)'!$C$5:$C$271,"Bambuk panel") -> 0 | H28: =SUMIFS('Hisob (batafsil)'!$G$5:$G$271,'Hisob (batafsil)'!$B$5:$B$271,$A28,'Hisob (batafsil)'!$C$5:$C$271,"Interaktiv doska") -> 0 | I28: =SUMIFS('Hisob (batafsil)'!$J$5:$J$271,'Hisob (batafsil)'!$B$5:$B$271,$A28,'Hisob (batafsil)'!$C$5:$C$271,"Interaktiv doska") -> 0 | J28: =SUMIFS('Hisob (batafsil)'!$G$5:$G$271,'Hisob (batafsil)'!$B$5:$B$271,$A28,'Hisob (batafsil)'!$C$5:$C$271,"Perila") -> 24 | K28: =SUMIFS('Hisob (batafsil)'!$J$5:$J$271,'Hisob (batafsil)'!$B$5:$B$271,$A28,'Hisob (batafsil)'!$C$5:$C$271,"Perila") -> 2016 | L28: =SUMIFS('Hisob (batafsil)'!$J$5:$J$271,'Hisob (batafsil)'!$B$5:$B$271,$A28,'Hisob (batafsil)'!$C$5:$C$271,"Yoritish") -> 0 | M28: =SUMIFS('Hisob (batafsil)'!$J$5:$J$271,'Hisob (batafsil)'!$B$5:$B$271,$A28,'Hisob (batafsil)'!$C$5:$C$271,"Kamera tizimi") -> 0 | N28: =SUMIFS('Hisob (batafsil)'!$J$5:$J$271,'Hisob (batafsil)'!$B$5:$B$271,$A28,'Hisob (batafsil)'!$C$5:$C$271,"Logotip") -> 0 | O28: =SUMIFS('Hisob (batafsil)'!$J$5:$J$271,'Hisob (batafsil)'!$B$5:$B$271,$A28,'Hisob (batafsil)'!$C$5:$C$271,"Matli plyonka") -> 0 | P28: =SUMIFS('Hisob (batafsil)'!$J$5:$J$271,'Hisob (batafsil)'!$B$5:$B$271,$A28,'Hisob (batafsil)'!$C$5:$C$271,"Yong'in xavfsizligi") -> 0 | Q28: =SUMIFS('Hisob (batafsil)'!$J$5:$J$271,'Hisob (batafsil)'!$B$5:$B$271,$A28,'Hisob (batafsil)'!$C$5:$C$271,"Buzish ishlari") -> 0 | R28: =SUMIFS('Hisob (batafsil)'!$J$5:$J$271,'Hisob (batafsil)'!$B$5:$B$271,$A28,'Hisob (batafsil)'!$C$5:$C$271,"Santexnika") -> 0 | S28: =SUMIFS('Hisob (batafsil)'!$J$5:$J$271,'Hisob (batafsil)'!$B$5:$B$271,$A28,'Hisob (batafsil)'!$C$5:$C$271,"Kafel") -> 0 | T28: =C28+E28+G28+I28+K28+L28+M28+N28+O28+P28+Q28+R28+S28 -> 2016
A29: Butun qavat (umumiy ishlar) | B29: =SUMIFS('Hisob (batafsil)'!$G$5:$G$271,'Hisob (batafsil)'!$B$5:$B$271,$A29,'Hisob (batafsil)'!$C$5:$C$271,"Shisha devor") -> 0 | C29: =SUMIFS('Hisob (batafsil)'!$J$5:$J$271,'Hisob (batafsil)'!$B$5:$B$271,$A29,'Hisob (batafsil)'!$C$5:$C$271,"Shisha devor") -> 0 | D29: =SUMIFS('Hisob (batafsil)'!$G$5:$G$271,'Hisob (batafsil)'!$B$5:$B$271,$A29,'Hisob (batafsil)'!$C$5:$C$271,"Gips karton (GKL)") -> 0 | E29: =SUMIFS('Hisob (batafsil)'!$J$5:$J$271,'Hisob (batafsil)'!$B$5:$B$271,$A29,'Hisob (batafsil)'!$C$5:$C$271,"Gips karton (GKL)") -> 0 | F29: =SUMIFS('Hisob (batafsil)'!$G$5:$G$271,'Hisob (batafsil)'!$B$5:$B$271,$A29,'Hisob (batafsil)'!$C$5:$C$271,"Bambuk panel") -> 0 | G29: =SUMIFS('Hisob (batafsil)'!$J$5:$J$271,'Hisob (batafsil)'!$B$5:$B$271,$A29,'Hisob (batafsil)'!$C$5:$C$271,"Bambuk panel") -> 0 | H29: =SUMIFS('Hisob (batafsil)'!$G$5:$G$271,'Hisob (batafsil)'!$B$5:$B$271,$A29,'Hisob (batafsil)'!$C$5:$C$271,"Interaktiv doska") -> 0 | I29: =SUMIFS('Hisob (batafsil)'!$J$5:$J$271,'Hisob (batafsil)'!$B$5:$B$271,$A29,'Hisob (batafsil)'!$C$5:$C$271,"Interaktiv doska") -> 0 | J29: =SUMIFS('Hisob (batafsil)'!$G$5:$G$271,'Hisob (batafsil)'!$B$5:$B$271,$A29,'Hisob (batafsil)'!$C$5:$C$271,"Perila") -> 0 | K29: =SUMIFS('Hisob (batafsil)'!$J$5:$J$271,'Hisob (batafsil)'!$B$5:$B$271,$A29,'Hisob (batafsil)'!$C$5:$C$271,"Perila") -> 0 | L29: =SUMIFS('Hisob (batafsil)'!$J$5:$J$271,'Hisob (batafsil)'!$B$5:$B$271,$A29,'Hisob (batafsil)'!$C$5:$C$271,"Yoritish") -> 0 | M29: =SUMIFS('Hisob (batafsil)'!$J$5:$J$271,'Hisob (batafsil)'!$B$5:$B$271,$A29,'Hisob (batafsil)'!$C$5:$C$271,"Kamera tizimi") -> 2119 | N29: =SUMIFS('Hisob (batafsil)'!$J$5:$J$271,'Hisob (batafsil)'!$B$5:$B$271,$A29,'Hisob (batafsil)'!$C$5:$C$271,"Logotip") -> 2500 | O29: =SUMIFS('Hisob (batafsil)'!$J$5:$J$271,'Hisob (batafsil)'!$B$5:$B$271,$A29,'Hisob (batafsil)'!$C$5:$C$271,"Matli plyonka") -> 537.81513 | P29: =SUMIFS('Hisob (batafsil)'!$J$5:$J$271,'Hisob (batafsil)'!$B$5:$B$271,$A29,'Hisob (batafsil)'!$C$5:$C$271,"Yong'in xavfsizligi") -> 1512.605 | Q29: =SUMIFS('Hisob (batafsil)'!$J$5:$J$271,'Hisob (batafsil)'!$B$5:$B$271,$A29,'Hisob (batafsil)'!$C$5:$C$271,"Buzish ishlari") -> 451.57563 | R29: =SUMIFS('Hisob (batafsil)'!$J$5:$J$271,'Hisob (batafsil)'!$B$5:$B$271,$A29,'Hisob (batafsil)'!$C$5:$C$271,"Santexnika") -> 0 | S29: =SUMIFS('Hisob (batafsil)'!$J$5:$J$271,'Hisob (batafsil)'!$B$5:$B$271,$A29,'Hisob (batafsil)'!$C$5:$C$271,"Kafel") -> 0 | T29: =C29+E29+G29+I29+K29+L29+M29+N29+O29+P29+Q29+R29+S29 -> 7120.9958
A30: 2-qavat: umumiy joylar — jami | B30: =SUM(B24:B29) -> 0 | C30: =SUM(C24:C29) -> 0 | D30: =SUM(D24:D29) -> 110.45 | E30: =SUM(E24:E29) -> 1325.4 | F30: =SUM(F24:F29) -> 0 | G30: =SUM(G24:G29) -> 0 | H30: =SUM(H24:H29) -> 0 | I30: =SUM(I24:I29) -> 0 | ... T30: =SUM(T24:T29) -> 11470.396
A32: 3-qavat va hojatxonalar
A33: 3-qavat 5-xona — o'quv xonasi (24 o'rin) | B33: =SUMIFS('Hisob (batafsil)'!$G$5:$G$271,'Hisob (batafsil)'!$B$5:$B$271,$A33,'Hisob (batafsil)'!$C$5:$C$271,"Shisha devor") -> 0 | C33: =SUMIFS('Hisob (batafsil)'!$J$5:$J$271,'Hisob (batafsil)'!$B$5:$B$271,$A33,'Hisob (batafsil)'!$C$5:$C$271,"Shisha devor") -> 0 | D33: =SUMIFS('Hisob (batafsil)'!$G$5:$G$271,'Hisob (batafsil)'!$B$5:$B$271,$A33,'Hisob (batafsil)'!$C$5:$C$271,"Gips karton (GKL)") -> 0 | E33: =SUMIFS('Hisob (batafsil)'!$J$5:$J$271,'Hisob (batafsil)'!$B$5:$B$271,$A33,'Hisob (batafsil)'!$C$5:$C$271,"Gips karton (GKL)") -> 0 | F33: =SUMIFS('Hisob (batafsil)'!$G$5:$G$271,'Hisob (batafsil)'!$B$5:$B$271,$A33,'Hisob (batafsil)'!$C$5:$C$271,"Bambuk panel") -> 46.86 | G33: =SUMIFS('Hisob (batafsil)'!$J$5:$J$271,'Hisob (batafsil)'!$B$5:$B$271,$A33,'Hisob (batafsil)'!$C$5:$C$271,"Bambuk panel") -> 726.33 | H33: =SUMIFS('Hisob (batafsil)'!$G$5:$G$271,'Hisob (batafsil)'!$B$5:$B$271,$A33,'Hisob (batafsil)'!$C$5:$C$271,"Interaktiv doska") -> 1 | I33: =SUMIFS('Hisob (batafsil)'!$J$5:$J$271,'Hisob (batafsil)'!$B$5:$B$271,$A33,'Hisob (batafsil)'!$C$5:$C$271,"Interaktiv doska") -> 1032 | J33: =SUMIFS('Hisob (batafsil)'!$G$5:$G$271,'Hisob (batafsil)'!$B$5:$B$271,$A33,'Hisob (batafsil)'!$C$5:$C$271,"Perila") -> 0 | K33: =SUMIFS('Hisob (batafsil)'!$J$5:$J$271,'Hisob (batafsil)'!$B$5:$B$271,$A33,'Hisob (batafsil)'!$C$5:$C$271,"Perila") -> 0 | L33: =SUMIFS('Hisob (batafsil)'!$J$5:$J$271,'Hisob (batafsil)'!$B$5:$B$271,$A33,'Hisob (batafsil)'!$C$5:$C$271,"Yoritish") -> 0 | M33: =SUMIFS('Hisob (batafsil)'!$J$5:$J$271,'Hisob (batafsil)'!$B$5:$B$271,$A33,'Hisob (batafsil)'!$C$5:$C$271,"Kamera tizimi") -> 0 | N33: =SUMIFS('Hisob (batafsil)'!$J$5:$J$271,'Hisob (batafsil)'!$B$5:$B$271,$A33,'Hisob (batafsil)'!$C$5:$C$271,"Logotip") -> 0 | O33: =SUMIFS('Hisob (batafsil)'!$J$5:$J$271,'Hisob (batafsil)'!$B$5:$B$271,$A33,'Hisob (batafsil)'!$C$5:$C$271,"Matli plyonka") -> 0 | P33: =SUMIFS('Hisob (batafsil)'!$J$5:$J$271,'Hisob (batafsil)'!$B$5:$B$271,$A33,'Hisob (batafsil)'!$C$5:$C$271,"Yong'in xavfsizligi") -> 0 | Q33: =SUMIFS('Hisob (batafsil)'!$J$5:$J$271,'Hisob (batafsil)'!$B$5:$B$271,$A33,'Hisob (batafsil)'!$C$5:$C$271,"Buzish ishlari") -> 0 | R33: =SUMIFS('Hisob (batafsil)'!$J$5:$J$271,'Hisob (batafsil)'!$B$5:$B$271,$A33,'Hisob (batafsil)'!$C$5:$C$271,"Santexnika") -> 0 | S33: =SUMIFS('Hisob (batafsil)'!$J$5:$J$271,'Hisob (batafsil)'!$B$5:$B$271,$A33,'Hisob (batafsil)'!$C$5:$C$271,"Kafel") -> 0 | T33: =C33+E33+G33+I33+K33+L33+M33+N33+O33+P33+Q33+R33+S33 -> 1758.33
A34: Hojatxonalar (3-qavat erkaklar, 2-qavat ayollar) | B34: =SUMIFS('Hisob (batafsil)'!$G$5:$G$271,'Hisob (batafsil)'!$B$5:$B$271,$A34,'Hisob (batafsil)'!$C$5:$C$271,"Shisha devor") -> 0 | C34: =SUMIFS('Hisob (batafsil)'!$J$5:$J$271,'Hisob (batafsil)'!$B$5:$B$271,$A34,'Hisob (batafsil)'!$C$5:$C$271,"Shisha devor") -> 0 | D34: =SUMIFS('Hisob (batafsil)'!$G$5:$G$271,'Hisob (batafsil)'!$B$5:$B$271,$A34,'Hisob (batafsil)'!$C$5:$C$271,"Gips karton (GKL)") -> 0 | E34: =SUMIFS('Hisob (batafsil)'!$J$5:$J$271,'Hisob (batafsil)'!$B$5:$B$271,$A34,'Hisob (batafsil)'!$C$5:$C$271,"Gips karton (GKL)") -> 0 | F34: =SUMIFS('Hisob (batafsil)'!$G$5:$G$271,'Hisob (batafsil)'!$B$5:$B$271,$A34,'Hisob (batafsil)'!$C$5:$C$271,"Bambuk panel") -> 0 | G34: =SUMIFS('Hisob (batafsil)'!$J$5:$J$271,'Hisob (batafsil)'!$B$5:$B$271,$A34,'Hisob (batafsil)'!$C$5:$C$271,"Bambuk panel") -> 0 | H34: =SUMIFS('Hisob (batafsil)'!$G$5:$G$271,'Hisob (batafsil)'!$B$5:$B$271,$A34,'Hisob (batafsil)'!$C$5:$C$271,"Interaktiv doska") -> 0 | I34: =SUMIFS('Hisob (batafsil)'!$J$5:$J$271,'Hisob (batafsil)'!$B$5:$B$271,$A34,'Hisob (batafsil)'!$C$5:$C$271,"Interaktiv doska") -> 0 | J34: =SUMIFS('Hisob (batafsil)'!$G$5:$G$271,'Hisob (batafsil)'!$B$5:$B$271,$A34,'Hisob (batafsil)'!$C$5:$C$271,"Perila") -> 0 | K34: =SUMIFS('Hisob (batafsil)'!$J$5:$J$271,'Hisob (batafsil)'!$B$5:$B$271,$A34,'Hisob (batafsil)'!$C$5:$C$271,"Perila") -> 0 | L34: =SUMIFS('Hisob (batafsil)'!$J$5:$J$271,'Hisob (batafsil)'!$B$5:$B$271,$A34,'Hisob (batafsil)'!$C$5:$C$271,"Yoritish") -> 0 | M34: =SUMIFS('Hisob (batafsil)'!$J$5:$J$271,'Hisob (batafsil)'!$B$5:$B$271,$A34,'Hisob (batafsil)'!$C$5:$C$271,"Kamera tizimi") -> 0 | N34: =SUMIFS('Hisob (batafsil)'!$J$5:$J$271,'Hisob (batafsil)'!$B$5:$B$271,$A34,'Hisob (batafsil)'!$C$5:$C$271,"Logotip") -> 0 | O34: =SUMIFS('Hisob (batafsil)'!$J$5:$J$271,'Hisob (batafsil)'!$B$5:$B$271,$A34,'Hisob (batafsil)'!$C$5:$C$271,"Matli plyonka") -> 0 | P34: =SUMIFS('Hisob (batafsil)'!$J$5:$J$271,'Hisob (batafsil)'!$B$5:$B$271,$A34,'Hisob (batafsil)'!$C$5:$C$271,"Yong'in xavfsizligi") -> 0 | Q34: =SUMIFS('Hisob (batafsil)'!$J$5:$J$271,'Hisob (batafsil)'!$B$5:$B$271,$A34,'Hisob (batafsil)'!$C$5:$C$271,"Buzish ishlari") -> 0 | R34: =SUMIFS('Hisob (batafsil)'!$J$5:$J$271,'Hisob (batafsil)'!$B$5:$B$271,$A34,'Hisob (batafsil)'!$C$5:$C$271,"Santexnika") -> 2487.395 | S34: =SUMIFS('Hisob (batafsil)'!$J$5:$J$271,'Hisob (batafsil)'!$B$5:$B$271,$A34,'Hisob (batafsil)'!$C$5:$C$271,"Kafel") -> 1243.6975 | T34: =C34+E34+G34+I34+K34+L34+M34+N34+O34+P34+Q34+R34+S34 -> 3731.0924
A35: 3-qavat va hojatxonalar — jami | B35: =SUM(B33:B34) -> 0 | C35: =SUM(C33:C34) -> 0 | D35: =SUM(D33:D34) -> 0 | E35: =SUM(E33:E34) -> 0 | F35: =SUM(F33:F34) -> 46.86 | G35: =SUM(G33:G34) -> 726.33 | H35: =SUM(H33:H34) -> 1 | I35: =SUM(I33:I34) -> 1032 | ... T35: =SUM(T33:T34) -> 5489.4224
A37: JAMI | B37: =B13+B21+B30+B35 -> 101.125 | C37: =C13+C21+C30+C35 -> 5561.875 | D37: =D13+D21+D30+D35 -> 408.15 | E37: =E13+E21+E30+E35 -> 4897.8 | F37: =F13+F21+F30+F35 -> 606.72 | G37: =G13+G21+G30+G35 -> 9404.16 | H37: =H13+H21+H30+H35 -> 8 | I37: =I13+I21+I30+I35 -> 8256 | ... T37: =T13+T21+T30+T35 -> 44011.923
A38: ="Kutilmagan xarajatlar ("&TEXT(Narxlar!$C$43,"0%")&" — «Narxlar» varag'idan)" -> Kutilmagan xarajatlar (10% — «Narxlar» varag'idan) | T38: =T37*Narxlar!$C$43 -> 4401.1923
A39: UMUMIY JAMI (kutilmagan xarajatlar bilan), $ | T39: =T37+T38 -> 48413.116
A40: UMUMIY JAMI, so'm (kurs bo'yicha) | T40: =T39*Narxlar!$C$19 -> 5.7611608e+08
A42: Tekshiruv: batafsil varaqdagi jami bilan farq (0 bo'lishi kerak) | T42: =T37-'Hisob (batafsil)'!J272 -> 0

Sheet Narxlar
A1: PDP Academy · Xadra filiali (2 va 3-qavat): narxlar va o'lchamlar
A2: Sariq kataklardagi narx va balandliklarni o'zgartirsangiz, «Hisob (batafsil)» va «Xonalar bo'yicha» varaqlari avtomatik qayta hisoblanadi.
A4: № | B4: Ko'rsatkich | C4: Qiymat | D4: Birlik | E4: Manba / izoh
A5: 1 | B5: Shisha devor | C5: 55 | D5: $/m² | E5: Buyurtmachi
A6: 2 | B6: Gips karton devor (bir tomoni) | C6: 12 | D6: $/m² | E6: Buyurtmachi; devorning har tomoni alohida hisoblanadi
A7: 3 | B7: Bambuk panel | C7: 15.5 | D7: $/m² | E7: Buyurtmachi
A8: 4 | B8: Interaktiv doska | C8: 1032 | D8: $/dona | E8: Buyurtmachi; 7 ta shu qavat sinflariga + 1 ta yuqori qavatdagi sinfga = 8 ta
A9: 5 | B9: Perila | C9: 84 | D9: $/m | E9: Buyurtmachi
A10: 6 | B10: Perila uzunligi | C10: 24 | D10: m | E10: Buyurtmachi
A11: 7 | B11: Yoritish — koridor va koworking (har biriga) | C11: 336 | D11: $/joy | E11: Buyurtmachi: K1, K2 koridorlari va koworking zali
A12: 8 | B12: Yoritish — xona (har biriga) | C12: 168 | D12: $/xona | E12: Buyurtmachi: 7 ta o'quv xonasi, 4 ta ofis xonasi va CEO xonasi
A13: 9 | B13: Videokamera | C13: 40 | D13: $/dona | E13: Buyurtmachi
A14: 10 | B14: Videokameralar soni | C14: 16 | D14: dona | E14: Buyurtmachi
A15: 11 | B15: Kamera o'rnatish (har biri) | C15: 21 | D15: $/dona | E15: Buyurtmachi
A16: 12 | B16: NVR (videoregistrator) | C16: 840 | D16: $/dona | E16: Buyurtmachi
... A45: 41 | B45: Shisha qism balandligi | C45: 2.5 | D45: m | E45: Buyurtmachi
A46: 42 | B46: Shisha ustidagi GKL | C46: =C44-C45 -> 1 | D46: m | E46: Hisob: devor balandligi − shisha
A47: 43 | B47: Eshik balandligi | C47: 2.1 | D47: m | E47: Taxmin: standart eshik 900 × 2100
A48: 44 | B48: Eshik ustidagi GKL | C48: =C44-C47 -> 1.4 | D48: m | E48: Hisob: devor balandligi − eshik
A49: 45 | B49: Eshik eni | C49: 0.9 | D49: m | E49: Chizmadan
A50: 46 | B50: Bambuk panel balandligi | C50: =C44 -> 3.5 | D50: m | E50: Taxmin: poldan shiftgacha. Pastroq bo'lsa, shu katakka raqam yozing
A51: 47 | B51: Bambuk panel balandligi — yuqori qavat o'quv xonasi | C51: 2.5 | D51: m | E51: Buyurtmachi
B53: Hisoblash qoidalari
B54: • Gips karton (GKL) devor: uzunlik × balandlik. Devorning har bir tomoni o'zi qaragan xonaga yoziladi (xona tomoni — xonaga, koridor tomoni — koridorga).
B55: • Shisha devor: shisha qism (2.5 m) xonaga yoziladi; ustidagi GKL (1 m) ikki tomonlama — xona va koridor tomoni alohida.
B56: • Eshiklar shisha: eshik (2.1 m) va ustidagi shisha (0.4 m) — 2.5 m gacha shisha narxida; ustida 1 m GKL ikki tomondan. Eshik furniturasi (ilgak, qulf, tutqich, dovodchik) kirmagan.
B57: • Bambuk panel, poldan shiftgacha: o'quv xonalarida doska devori va orqa devor (interaktiv doska orqasi ayirilmagan); ofis xonalarida ikkala uzun yon devor; CEO xonasida ikkita ichki kar devor, eshik o'rni ayiriladi. Derazali tashqi va shisha devorlarga qilinmaydi.
B58: • Yuqori qavat o'quv xonasi (5.45 × 8.60 m, buyurtmachi chizmasi): bambuk panel 3 devorga, 2.5 m balandlikda — doska devori, orqa devor va eshikli uzun devor (eshik o'rni ayiriladi); derazali uzun devorga qilinmaydi.
B59: • Interaktiv doska: 7 ta shu qavat sinflariga va 1 ta yuqori qavatdagi o'quv xonasiga — jami 8 ta.
B60: • Perila: buyurtmachi bergan uzunlik (24 m), «Zinapoya» qatorida.
B61: • Uzunliklar chizma v1.0 dan (mavjud holat chizmasining fotosi asosida) — ish boshlanishidan oldin joyida o'lchanadi.
B62: • Yoritish: koridorlar (K1, K2) va koworking zaliga 336 $ dan, o'quv xonalari (7), ofis xonalari (4) va CEO xonasiga 168 $ dan. Kirish zali, WC va yuqori qavat xonasi kiritilmagan.
B63: • Videokuzatuv: 16 ta kamera (40 $) va o'rnatish (21 $ dan), NVR, kabellar jami; logotiplar jami — «Butun qavat» qatorida.
B64: • So'mdagi narxlar (matli plyonka, yong'in xavfsizligi, devor buzish va chiqindi) «Dollar kursi» katagi bo'yicha (11 900 so'm/$) $ ga o'tkaziladi.
... B69: Ranglar: ko'k — qo'lda kiritilgan qiymat; yashil — boshqa varaqdan olingan; qora — formula; sariq fon — o'zgartirish mumkin bo'lgan kataklar.

Sheet Hisob (batafsil)
A1: PDP Academy · Xadra filiali (2 va 3-qavat): xarajatlar hisobi, xonalar bo'yicha batafsil
A2: Uzunliklar chizmadan (m). Balandlik va narx «Narxlar» varag'idan olinadi (yashil). Miqdor = uzunlik × balandlik; summa = miqdor × narx.
A4: № | B4: Xona | C4: Ish turi | D4: Joyi / izoh | E4: Uzunlik, m | F4: Balandlik, m | G4: Miqdor | H4: Birlik | I4: Narx, $ | J4: Summa, $
A5: 1-xona
A6: 1 | B6: 1-xona | C6: Shisha devor | D6: Shisha devor (K1 koridori tomoni) | E6: 4.6 | F6: =Narxlar!$C$45 -> 2.5 | G6: =E6*F6 -> 11.5 | H6: m² | I6: =Narxlar!$C$5 -> 55 | J6: =G6*I6 -> 632.5
A7: 2 | B7: 1-xona | C7: Shisha devor | D7: Shisha eshik va ustidagi shisha (K1 koridori tomoni) | E7: =Narxlar!$C$49 -> 0.9 | F7: =Narxlar!$C$45 -> 2.5 | G7: =E7*F7 -> 2.25 | H7: m² | I7: =Narxlar!$C$5 -> 55 | J7: =G7*I7 -> 123.75
A8: 3 | B8: 1-xona | C8: Gips karton (GKL) | D8: Koworking zali bilan orasidagi devor — mavjud devordagi bo'shliqni yopish | E8: 0.3 | F8: =Narxlar!$C$44 -> 3.5 | G8: =E8*F8 -> 1.05 | H8: m² | I8: =Narxlar!$C$6 -> 12 | J8: =G8*I8 -> 12.6
A9: 4 | B9: 1-xona | C9: Gips karton (GKL) | D9: Shisha ustidagi GKL (K1 koridori bilan orasida) | E9: 4.6 | F9: =Narxlar!$C$46 -> 1 | G9: =E9*F9 -> 4.6 | H9: m² | I9: =Narxlar!$C$6 -> 12 | J9: =G9*I9 -> 55.2
A10: 5 | B10: 1-xona | C10: Gips karton (GKL) | D10: Eshik yonidagi kesak (K1 koridori tomoni) | E10: 0.2 | F10: =Narxlar!$C$44 -> 3.5 | G10: =E10*F10 -> 0.7 | H10: m² | I10: =Narxlar!$C$6 -> 12 | J10: =G10*I10 -> 8.4
A11: 6 | B11: 1-xona | C11: Gips karton (GKL) | D11: Eshik ustidagi GKL (K1 koridori bilan orasida) | E11: =Narxlar!$C$49 -> 0.9 | F11: =Narxlar!$C$46 -> 1 | G11: =E11*F11 -> 0.9 | H11: m² | I11: =Narxlar!$C$6 -> 12 | J11: =G11*I11 -> 10.8
A12: 7 | B12: 1-xona | C12: Bambuk panel | D12: Doska devori | E12: 7.7 | F12: =Narxlar!$C$50 -> 3.5 | G12: =E12*F12 -> 26.95 | H12: m² | I12: =Narxlar!$C$7 -> 15.5 | J12: =G12*I12 -> 417.725
A13: 8 | B13: 1-xona | C13: Bambuk panel | D13: Orqa devor | E13: 7.7 | F13: =Narxlar!$C$50 -> 3.5 | G13: =E13*F13 -> 26.95 | H13: m² | I13: =Narxlar!$C$7 -> 15.5 | J13: =G13*I13 -> 417.725
A14: 9 | B14: 1-xona | C14: Interaktiv doska | D14: Doska devoriga | G14: 1 | H14: dona | I14: =Narxlar!$C$8 -> 1032 | J14: =G14*I14 -> 1032
A15: 10 | B15: 1-xona | C15: Yoritish | D15: Lampalar (xona uchun) | G15: 1 | H15: komplekt | I15: =Narxlar!$C$12 -> 168 | J15: =G15*I15 -> 168
D16: Jami: 1-xona | J16: =SUM(J6:J15) -> 2878.7
A18: 2-xona
A19: 11 | B19: 2-xona | C19: Shisha devor | D19: Shisha devor (K1 koridori tomoni) | E19: 4.7 | F19: =Narxlar!$C$45 -> 2.5 | G19: =E19*F19 -> 11.75 | H19: m² | I19: =Narxlar!$C$5 -> 55 | J19: =G19*I19 -> 646.25
A20: 12 | B20: 2-xona | C20: Shisha devor | D20: Shisha eshik va ustidagi shisha (K1 koridori tomoni) | E20: =Narxlar!$C$49 -> 0.9 | F20: =Narxlar!$C$45 -> 2.5 | G20: =E20*F20 -> 2.25 | H20: m² | I20: =Narxlar!$C$5 -> 55 | J20: =G20*I20 -> 123.75
