Workbook

Sheet Yakuniy
A1: PDP Academy · Xadra filiali (1, 2 va 3-qavat): jami xarajatlar — yakuniy
A2: Barcha summalar «Hisob (batafsil)» varag'idan formulalar bilan olinadi; so'm — «Narxlar» varag'idagi kurs bo'yicha.
A4: 1. Xarajat turlari bo'yicha
A5: № | B5: Xarajat turi | C5: Summa, $ | D5: Summa, so'm | E5: Ulush
A6: 1 | B6: Shisha devor | C6: =SUMIFS('Hisob (batafsil)'!$J$5:$J$301,'Hisob (batafsil)'!$C$5:$C$301,"Shisha devor") -> 4991.25 | D6: =C6*Narxlar!$C$19 -> 59395875 | E6: =IF($C$22=0,0,C6/$C$22) -> 0.073861085
A7: 2 | B7: Gips karton (GKL) | C7: =SUMIFS('Hisob (batafsil)'!$J$5:$J$301,'Hisob (batafsil)'!$C$5:$C$301,"Gips karton (GKL)") -> 5146.8 | D7: =C7*Narxlar!$C$19 -> 61246920 | E7: =IF($C$22=0,0,C7/$C$22) -> 0.076162931
A8: 3 | B8: Bambuk panel | C8: =SUMIFS('Hisob (batafsil)'!$J$5:$J$301,'Hisob (batafsil)'!$C$5:$C$301,"Bambuk panel") -> 9404.16 | D8: =C8*Narxlar!$C$19 -> 111909504 | E8: =IF($C$22=0,0,C8/$C$22) -> 0.13916383
A9: 4 | B9: Interaktiv doska | C9: =SUMIFS('Hisob (batafsil)'!$J$5:$J$301,'Hisob (batafsil)'!$C$5:$C$301,"Interaktiv doska") -> 8256 | D9: =C9*Narxlar!$C$19 -> 98246400 | E9: =IF($C$22=0,0,C9/$C$22) -> 0.12217323
A10: 5 | B10: Perila | C10: =SUMIFS('Hisob (batafsil)'!$J$5:$J$301,'Hisob (batafsil)'!$C$5:$C$301,"Perila") -> 2016 | D10: =C10*Narxlar!$C$19 -> 23990400 | E10: =IF($C$22=0,0,C10/$C$22) -> 0.029832997
A11: 6 | B11: Yoritish | C11: =SUMIFS('Hisob (batafsil)'!$J$5:$J$301,'Hisob (batafsil)'!$C$5:$C$301,"Yoritish") -> 3024 | D11: =C11*Narxlar!$C$19 -> 35985600 | E11: =IF($C$22=0,0,C11/$C$22) -> 0.044749496
A12: 7 | B12: Kamera tizimi | C12: =SUMIFS('Hisob (batafsil)'!$J$5:$J$301,'Hisob (batafsil)'!$C$5:$C$301,"Kamera tizimi") -> 2119 | D12: =C12*Narxlar!$C$19 -> 25216100 | E12: =IF($C$22=0,0,C12/$C$22) -> 0.031357203
A13: 8 | B13: Logotip | C13: =SUMIFS('Hisob (batafsil)'!$J$5:$J$301,'Hisob (batafsil)'!$C$5:$C$301,"Logotip") -> 3250 | D13: =C13*Narxlar!$C$19 -> 38675000 | E13: =IF($C$22=0,0,C13/$C$22) -> 0.048093869
A14: 9 | B14: Matli plyonka | C14: =SUMIFS('Hisob (batafsil)'!$J$5:$J$301,'Hisob (batafsil)'!$C$5:$C$301,"Matli plyonka") -> 537.81513 | D14: =C14*Narxlar!$C$19 -> 6400000 | E14: =IF($C$22=0,0,C14/$C$22) -> 0.0079586494
A15: 10 | B15: Yong'in xavfsizligi | C15: =SUMIFS('Hisob (batafsil)'!$J$5:$J$301,'Hisob (batafsil)'!$C$5:$C$301,"Yong'in xavfsizligi") -> 1512.605 | D15: =C15*Narxlar!$C$19 -> 18000000 | E15: =IF($C$22=0,0,C15/$C$22) -> 0.022383701
A16: 11 | B16: Buzish ishlari | C16: =SUMIFS('Hisob (batafsil)'!$J$5:$J$301,'Hisob (batafsil)'!$C$5:$C$301,"Buzish ishlari") -> 451.57563 | D16: =C16*Narxlar!$C$19 -> 5373750 | E16: =IF($C$22=0,0,C16/$C$22) -> 0.0066824675
A17: 12 | B17: Santexnika | C17: =SUMIFS('Hisob (batafsil)'!$J$5:$J$301,'Hisob (batafsil)'!$C$5:$C$301,"Santexnika") -> 3393.2773 | D17: =C17*Narxlar!$C$19 -> 40380000 | E17: =IF($C$22=0,0,C17/$C$22) -> 0.050214103
A18: 13 | B18: Kafel | C18: =SUMIFS('Hisob (batafsil)'!$J$5:$J$301,'Hisob (batafsil)'!$C$5:$C$301,"Kafel") -> 1243.6975 | D18: =C18*Narxlar!$C$19 -> 14800000 | E18: =IF($C$22=0,0,C18/$C$22) -> 0.018404377
A19: 14 | B19: Konditsioner va ventilyatsiya | C19: =SUMIFS('Hisob (batafsil)'!$J$5:$J$301,'Hisob (batafsil)'!$C$5:$C$301,"Konditsioner va ventilyatsiya") -> 15000 | D19: =C19*Narxlar!$C$19 -> 178500000 | E19: =IF($C$22=0,0,C19/$C$22) -> 0.2219717
A20: 15 | B20: Mebel va interyer | C20: =SUMIFS('Hisob (batafsil)'!$J$5:$J$301,'Hisob (batafsil)'!$C$5:$C$301,"Mebel va interyer") -> 6490 | D20: =C20*Narxlar!$C$19 -> 77231000 | E20: =IF($C$22=0,0,C20/$C$22) -> 0.096039758
A21: 16 | B21: E'lon va e'tirof doskalari | C21: =SUMIFS('Hisob (batafsil)'!$J$5:$J$301,'Hisob (batafsil)'!$C$5:$C$301,"E'lon va e'tirof doskalari") -> 740 | D21: =C21*Narxlar!$C$19 -> 8806000 | E21: =IF($C$22=0,0,C21/$C$22) -> 0.010950604
B22: JAMI | C22: =SUM(C6:C21) -> 67576.181 | D22: =C22*Narxlar!$C$19 -> 804156549 | E22: =SUM(E6:E21) -> 1
B23: ="Kutilmagan xarajatlar ("&TEXT(Narxlar!$C$70,"0%")&")" -> Kutilmagan xarajatlar (10%) | C23: =C22*Narxlar!$C$70 -> 6757.6181 | D23: =C23*Narxlar!$C$19 -> 80415655
B24: UMUMIY JAMI | C24: =C22+C23 -> 74333.799 | D24: =C24*Narxlar!$C$19 -> 8.845722e+08
B25: shundan taxminiy narxlar (mebel, interyer, doskalar, 1-qavat logotiplari) — kutilmagan xarajatsiz | C25: =SUMIFS('Hisob (batafsil)'!$J$5:$J$301,'Hisob (batafsil)'!$C$5:$C$301,"Mebel va interyer")+SUMIFS('Hisob (batafsil)'!$J$5:$J$301,'Hisob (batafsil)'!$C$5:$C$301,"E'lon va e'tirof doskalari")+SUMIFS('Hisob (batafsil)'!$J$5:$J$301,'Hisob (batafsil)'!$B$5:$B$301,"1-qavat — kirish zali (resepshn, turniket)",'Hisob (batafsil)'!$C$5:$C$301,"Logotip") -> 7980 | D25: =C25*Narxlar!$C$19 -> 94962000
A27: 2. Qavat va bo'limlar bo'yicha
A28: № | B28: Bo'lim | C28: Summa, $ | D28: Summa, so'm | E28: Ulush
A29: 1 | B29: 1-qavat: kirish zali | C29: ='Xonalar bo''yicha'!$W$7 -> 3430 | D29: =C29*Narxlar!$C$19 -> 40817000 | E29: =IF($C$34=0,0,C29/$C$34) -> 0.05075753
A30: 2 | B30: 2-qavat: o'quv xonalari | C30: ='Xonalar bo''yicha'!$W$17 -> 19634.5 | D30: =C30*Narxlar!$C$19 -> 233650550 | E30: =IF($C$34=0,0,C30/$C$34) -> 0.29055356
A31: 3 | B31: 2-qavat: ofis xonalari | C31: ='Xonalar bo''yicha'!$W$25 -> 10781.48 | D31: =C31*Narxlar!$C$19 -> 128299612 | E31: =IF($C$34=0,0,C31/$C$34) -> 0.15954557
A32: 4 | B32: 2-qavat: umumiy joylar | C32: ='Xonalar bo''yicha'!$W$34 -> 26334.896 | D32: =C32*Narxlar!$C$19 -> 313385260 | E32: =IF($C$34=0,0,C32/$C$34) -> 0.38970678
A33: 5 | B33: 3-qavat va hojatxonalar | C33: ='Xonalar bo''yicha'!$W$39 -> 7395.3048 | D33: =C33*Narxlar!$C$19 -> 88004127 | E33: =IF($C$34=0,0,C33/$C$34) -> 0.10943656
B34: JAMI | C34: =SUM(C29:C33) -> 67576.181 | D34: =C34*Narxlar!$C$19 -> 804156549 | E34: =SUM(E29:E33) -> 1
B36: Tekshiruv: ikki jadval jamisi farqi (0 bo'lishi kerak) | C36: =C22-C34 -> 0
B37: Dollar kursi (so'm/$) — «Narxlar» varag'idan | C37: =Narxlar!$C$19 -> 11900

Sheet Xonalar bo'yicha
A1: PDP Academy · Xadra filiali (1, 2 va 3-qavat): xarajatlar, xonalar bo'yicha
A2: Har bir qator «Hisob (batafsil)» varag'idan olinadi (SUMIFS). Narxlarni «Narxlar» varag'ida o'zgartiring.
A4: Xona | B4: Shisha (devor va eshik), m² | C4: Shisha (devor va eshik), $ | D4: Gips karton (GKL), m² | E4: Gips karton (GKL), $ | F4: Bambuk panel, m² | G4: Bambuk panel, $ | H4: Interaktiv doska, dona | I4: Interaktiv doska, $ | J4: Perila, m | K4: Perila, $ | L4: Yoritish, $ | M4: Kamera tizimi, $ | N4: Logotip, $ | O4: Matli plyonka, $ | P4: Yong'in xavfsizligi, $ | Q4: Buzish ishlari, $ | R4: Santexnika, $ | S4: Kafel, $ | T4: Konditsioner va ventilyatsiya, $ | U4: Mebel va interyer (taxmin), $ | V4: E'lon va e'tirof doskalari (taxmin), $ | W4: Jami, $
A5: 1-qavat: kirish zali
A6: 1-qavat — kirish zali (resepshn, turniket) | B6: =SUMIFS('Hisob (batafsil)'!$G$5:$G$301,'Hisob (batafsil)'!$B$5:$B$301,$A6,'Hisob (batafsil)'!$C$5:$C$301,"Shisha devor") -> 0 | C6: =SUMIFS('Hisob (batafsil)'!$J$5:$J$301,'Hisob (batafsil)'!$B$5:$B$301,$A6,'Hisob (batafsil)'!$C$5:$C$301,"Shisha devor") -> 0 | D6: =SUMIFS('Hisob (batafsil)'!$G$5:$G$301,'Hisob (batafsil)'!$B$5:$B$301,$A6,'Hisob (batafsil)'!$C$5:$C$301,"Gips karton (GKL)") -> 0 | E6: =SUMIFS('Hisob (batafsil)'!$J$5:$J$301,'Hisob (batafsil)'!$B$5:$B$301,$A6,'Hisob (batafsil)'!$C$5:$C$301,"Gips karton (GKL)") -> 0 | F6: =SUMIFS('Hisob (batafsil)'!$G$5:$G$301,'Hisob (batafsil)'!$B$5:$B$301,$A6,'Hisob (batafsil)'!$C$5:$C$301,"Bambuk panel") -> 0 | G6: =SUMIFS('Hisob (batafsil)'!$J$5:$J$301,'Hisob (batafsil)'!$B$5:$B$301,$A6,'Hisob (batafsil)'!$C$5:$C$301,"Bambuk panel") -> 0 | H6: =SUMIFS('Hisob (batafsil)'!$G$5:$G$301,'Hisob (batafsil)'!$B$5:$B$301,$A6,'Hisob (batafsil)'!$C$5:$C$301,"Interaktiv doska") -> 0 | I6: =SUMIFS('Hisob (batafsil)'!$J$5:$J$301,'Hisob (batafsil)'!$B$5:$B$301,$A6,'Hisob (batafsil)'!$C$5:$C$301,"Interaktiv doska") -> 0 | J6: =SUMIFS('Hisob (batafsil)'!$G$5:$G$301,'Hisob (batafsil)'!$B$5:$B$301,$A6,'Hisob (batafsil)'!$C$5:$C$301,"Perila") -> 0 | K6: =SUMIFS('Hisob (batafsil)'!$J$5:$J$301,'Hisob (batafsil)'!$B$5:$B$301,$A6,'Hisob (batafsil)'!$C$5:$C$301,"Perila") -> 0 | L6: =SUMIFS('Hisob (batafsil)'!$J$5:$J$301,'Hisob (batafsil)'!$B$5:$B$301,$A6,'Hisob (batafsil)'!$C$5:$C$301,"Yoritish") -> 0 | M6: =SUMIFS('Hisob (batafsil)'!$J$5:$J$301,'Hisob (batafsil)'!$B$5:$B$301,$A6,'Hisob (batafsil)'!$C$5:$C$301,"Kamera tizimi") -> 0 | N6: =SUMIFS('Hisob (batafsil)'!$J$5:$J$301,'Hisob (batafsil)'!$B$5:$B$301,$A6,'Hisob (batafsil)'!$C$5:$C$301,"Logotip") -> 750 | O6: =SUMIFS('Hisob (batafsil)'!$J$5:$J$301,'Hisob (batafsil)'!$B$5:$B$301,$A6,'Hisob (batafsil)'!$C$5:$C$301,"Matli plyonka") -> 0 | P6: =SUMIFS('Hisob (batafsil)'!$J$5:$J$301,'Hisob (batafsil)'!$B$5:$B$301,$A6,'Hisob (batafsil)'!$C$5:$C$301,"Yong'in xavfsizligi") -> 0 | Q6: =SUMIFS('Hisob (batafsil)'!$J$5:$J$301,'Hisob (batafsil)'!$B$5:$B$301,$A6,'Hisob (batafsil)'!$C$5:$C$301,"Buzish ishlari") -> 0 | R6: =SUMIFS('Hisob (batafsil)'!$J$5:$J$301,'Hisob (batafsil)'!$B$5:$B$301,$A6,'Hisob (batafsil)'!$C$5:$C$301,"Santexnika") -> 0 | S6: =SUMIFS('Hisob (batafsil)'!$J$5:$J$301,'Hisob (batafsil)'!$B$5:$B$301,$A6,'Hisob (batafsil)'!$C$5:$C$301,"Kafel") -> 0 | T6: =SUMIFS('Hisob (batafsil)'!$J$5:$J$301,'Hisob (batafsil)'!$B$5:$B$301,$A6,'Hisob (batafsil)'!$C$5:$C$301,"Konditsioner va ventilyatsiya") -> 0 | U6: =SUMIFS('Hisob (batafsil)'!$J$5:$J$301,'Hisob (batafsil)'!$B$5:$B$301,$A6,'Hisob (batafsil)'!$C$5:$C$301,"Mebel va interyer") -> 2680 | V6: =SUMIFS('Hisob (batafsil)'!$J$5:$J$301,'Hisob (batafsil)'!$B$5:$B$301,$A6,'Hisob (batafsil)'!$C$5:$C$301,"E'lon va e'tirof doskalari") -> 0 | W6: =C6+E6+G6+I6+K6+L6+M6+N6+O6+P6+Q6+R6+S6+T6+U6+V6 -> 3430
A7: 1-qavat: kirish zali — jami | B7: =SUM(B6:B6) -> 0 | C7: =SUM(C6:C6) -> 0 | D7: =SUM(D6:D6) -> 0 | E7: =SUM(E6:E6) -> 0 | F7: =SUM(F6:F6) -> 0 | G7: =SUM(G6:G6) -> 0 | H7: =SUM(H6:H6) -> 0 | I7: =SUM(I6:I6) -> 0 | ... W7: =SUM(W6:W6) -> 3430
A9: 2-qavat: o'quv xonalari
A10: 1-xona | B10: =SUMIFS('Hisob (batafsil)'!$G$5:$G$301,'Hisob (batafsil)'!$B$5:$B$301,$A10,'Hisob (batafsil)'!$C$5:$C$301,"Shisha devor") -> 13.75 | C10: =SUMIFS('Hisob (batafsil)'!$J$5:$J$301,'Hisob (batafsil)'!$B$5:$B$301,$A10,'Hisob (batafsil)'!$C$5:$C$301,"Shisha devor") -> 756.25 | D10: =SUMIFS('Hisob (batafsil)'!$G$5:$G$301,'Hisob (batafsil)'!$B$5:$B$301,$A10,'Hisob (batafsil)'!$C$5:$C$301,"Gips karton (GKL)") -> 7.25 | E10: =SUMIFS('Hisob (batafsil)'!$J$5:$J$301,'Hisob (batafsil)'!$B$5:$B$301,$A10,'Hisob (batafsil)'!$C$5:$C$301,"Gips karton (GKL)") -> 87 | F10: =SUMIFS('Hisob (batafsil)'!$G$5:$G$301,'Hisob (batafsil)'!$B$5:$B$301,$A10,'Hisob (batafsil)'!$C$5:$C$301,"Bambuk panel") -> 53.9 | G10: =SUMIFS('Hisob (batafsil)'!$J$5:$J$301,'Hisob (batafsil)'!$B$5:$B$301,$A10,'Hisob (batafsil)'!$C$5:$C$301,"Bambuk panel") -> 835.45 | H10: =SUMIFS('Hisob (batafsil)'!$G$5:$G$301,'Hisob (batafsil)'!$B$5:$B$301,$A10,'Hisob (batafsil)'!$C$5:$C$301,"Interaktiv doska") -> 1 | I10: =SUMIFS('Hisob (batafsil)'!$J$5:$J$301,'Hisob (batafsil)'!$B$5:$B$301,$A10,'Hisob (batafsil)'!$C$5:$C$301,"Interaktiv doska") -> 1032 | J10: =SUMIFS('Hisob (batafsil)'!$G$5:$G$301,'Hisob (batafsil)'!$B$5:$B$301,$A10,'Hisob (batafsil)'!$C$5:$C$301,"Perila") -> 0 | K10: =SUMIFS('Hisob (batafsil)'!$J$5:$J$301,'Hisob (batafsil)'!$B$5:$B$301,$A10,'Hisob (batafsil)'!$C$5:$C$301,"Perila") -> 0 | L10: =SUMIFS('Hisob (batafsil)'!$J$5:$J$301,'Hisob (batafsil)'!$B$5:$B$301,$A10,'Hisob (batafsil)'!$C$5:$C$301,"Yoritish") -> 168 | M10: =SUMIFS('Hisob (batafsil)'!$J$5:$J$301,'Hisob (batafsil)'!$B$5:$B$301,$A10,'Hisob (batafsil)'!$C$5:$C$301,"Kamera tizimi") -> 0 | N10: =SUMIFS('Hisob (batafsil)'!$J$5:$J$301,'Hisob (batafsil)'!$B$5:$B$301,$A10,'Hisob (batafsil)'!$C$5:$C$301,"Logotip") -> 0 | O10: =SUMIFS('Hisob (batafsil)'!$J$5:$J$301,'Hisob (batafsil)'!$B$5:$B$301,$A10,'Hisob (batafsil)'!$C$5:$C$301,"Matli plyonka") -> 0 | P10: =SUMIFS('Hisob (batafsil)'!$J$5:$J$301,'Hisob (batafsil)'!$B$5:$B$301,$A10,'Hisob (batafsil)'!$C$5:$C$301,"Yong'in xavfsizligi") -> 0 | Q10: =SUMIFS('Hisob (batafsil)'!$J$5:$J$301,'Hisob (batafsil)'!$B$5:$B$301,$A10,'Hisob (batafsil)'!$C$5:$C$301,"Buzish ishlari") -> 0 | R10: =SUMIFS('Hisob (batafsil)'!$J$5:$J$301,'Hisob (batafsil)'!$B$5:$B$301,$A10,'Hisob (batafsil)'!$C$5:$C$301,"Santexnika") -> 0 | S10: =SUMIFS('Hisob (batafsil)'!$J$5:$J$301,'Hisob (batafsil)'!$B$5:$B$301,$A10,'Hisob (batafsil)'!$C$5:$C$301,"Kafel") -> 0 | T10: =SUMIFS('Hisob (batafsil)'!$J$5:$J$301,'Hisob (batafsil)'!$B$5:$B$301,$A10,'Hisob (batafsil)'!$C$5:$C$301,"Konditsioner va ventilyatsiya") -> 0 | U10: =SUMIFS('Hisob (batafsil)'!$J$5:$J$301,'Hisob (batafsil)'!$B$5:$B$301,$A10,'Hisob (batafsil)'!$C$5:$C$301,"Mebel va interyer") -> 0 | V10: =SUMIFS('Hisob (batafsil)'!$J$5:$J$301,'Hisob (batafsil)'!$B$5:$B$301,$A10,'Hisob (batafsil)'!$C$5:$C$301,"E'lon va e'tirof doskalari") -> 0 | W10: =C10+E10+G10+I10+K10+L10+M10+N10+O10+P10+Q10+R10+S10+T10+U10+V10 -> 2878.7
A11: 2-xona | B11: =SUMIFS('Hisob (batafsil)'!$G$5:$G$301,'Hisob (batafsil)'!$B$5:$B$301,$A11,'Hisob (batafsil)'!$C$5:$C$301,"Shisha devor") -> 14 | C11: =SUMIFS('Hisob (batafsil)'!$J$5:$J$301,'Hisob (batafsil)'!$B$5:$B$301,$A11,'Hisob (batafsil)'!$C$5:$C$301,"Shisha devor") -> 770 | D11: =SUMIFS('Hisob (batafsil)'!$G$5:$G$301,'Hisob (batafsil)'!$B$5:$B$301,$A11,'Hisob (batafsil)'!$C$5:$C$301,"Gips karton (GKL)") -> 6.3 | E11: =SUMIFS('Hisob (batafsil)'!$J$5:$J$301,'Hisob (batafsil)'!$B$5:$B$301,$A11,'Hisob (batafsil)'!$C$5:$C$301,"Gips karton (GKL)") -> 75.6 | F11: =SUMIFS('Hisob (batafsil)'!$G$5:$G$301,'Hisob (batafsil)'!$B$5:$B$301,$A11,'Hisob (batafsil)'!$C$5:$C$301,"Bambuk panel") -> 53.9 | G11: =SUMIFS('Hisob (batafsil)'!$J$5:$J$301,'Hisob (batafsil)'!$B$5:$B$301,$A11,'Hisob (batafsil)'!$C$5:$C$301,"Bambuk panel") -> 835.45 | H11: =SUMIFS('Hisob (batafsil)'!$G$5:$G$301,'Hisob (batafsil)'!$B$5:$B$301,$A11,'Hisob (batafsil)'!$C$5:$C$301,"Interaktiv doska") -> 1 | I11: =SUMIFS('Hisob (batafsil)'!$J$5:$J$301,'Hisob (batafsil)'!$B$5:$B$301,$A11,'Hisob (batafsil)'!$C$5:$C$301,"Interaktiv doska") -> 1032 | J11: =SUMIFS('Hisob (batafsil)'!$G$5:$G$301,'Hisob (batafsil)'!$B$5:$B$301,$A11,'Hisob (batafsil)'!$C$5:$C$301,"Perila") -> 0 | K11: =SUMIFS('Hisob (batafsil)'!$J$5:$J$301,'Hisob (batafsil)'!$B$5:$B$301,$A11,'Hisob (batafsil)'!$C$5:$C$301,"Perila") -> 0 | L11: =SUMIFS('Hisob (batafsil)'!$J$5:$J$301,'Hisob (batafsil)'!$B$5:$B$301,$A11,'Hisob (batafsil)'!$C$5:$C$301,"Yoritish") -> 168 | M11: =SUMIFS('Hisob (batafsil)'!$J$5:$J$301,'Hisob (batafsil)'!$B$5:$B$301,$A11,'Hisob (batafsil)'!$C$5:$C$301,"Kamera tizimi") -> 0 | N11: =SUMIFS('Hisob (batafsil)'!$J$5:$J$301,'Hisob (batafsil)'!$B$5:$B$301,$A11,'Hisob (batafsil)'!$C$5:$C$301,"Logotip") -> 0 | O11: =SUMIFS('Hisob (batafsil)'!$J$5:$J$301,'Hisob (batafsil)'!$B$5:$B$301,$A11,'Hisob (batafsil)'!$C$5:$C$301,"Matli plyonka") -> 0 | P11: =SUMIFS('Hisob (batafsil)'!$J$5:$J$301,'Hisob (batafsil)'!$B$5:$B$301,$A11,'Hisob (batafsil)'!$C$5:$C$301,"Yong'in xavfsizligi") -> 0 | Q11: =SUMIFS('Hisob (batafsil)'!$J$5:$J$301,'Hisob (batafsil)'!$B$5:$B$301,$A11,'Hisob (batafsil)'!$C$5:$C$301,"Buzish ishlari") -> 0 | R11: =SUMIFS('Hisob (batafsil)'!$J$5:$J$301,'Hisob (batafsil)'!$B$5:$B$301,$A11,'Hisob (batafsil)'!$C$5:$C$301,"Santexnika") -> 0 | S11: =SUMIFS('Hisob (batafsil)'!$J$5:$J$301,'Hisob (batafsil)'!$B$5:$B$301,$A11,'Hisob (batafsil)'!$C$5:$C$301,"Kafel") -> 0 | T11: =SUMIFS('Hisob (batafsil)'!$J$5:$J$301,'Hisob (batafsil)'!$B$5:$B$301,$A11,'Hisob (batafsil)'!$C$5:$C$301,"Konditsioner va ventilyatsiya") -> 0 | U11: =SUMIFS('Hisob (batafsil)'!$J$5:$J$301,'Hisob (batafsil)'!$B$5:$B$301,$A11,'Hisob (batafsil)'!$C$5:$C$301,"Mebel va interyer") -> 0 | V11: =SUMIFS('Hisob (batafsil)'!$J$5:$J$301,'Hisob (batafsil)'!$B$5:$B$301,$A11,'Hisob (batafsil)'!$C$5:$C$301,"E'lon va e'tirof doskalari") -> 0 | W11: =C11+E11+G11+I11+K11+L11+M11+N11+O11+P11+Q11+R11+S11+T11+U11+V11 -> 2881.05
A12: 3-xona | B12: =SUMIFS('Hisob (batafsil)'!$G$5:$G$301,'Hisob (batafsil)'!$B$5:$B$301,$A12,'Hisob (batafsil)'!$C$5:$C$301,"Shisha devor") -> 2.25 | C12: =SUMIFS('Hisob (batafsil)'!$J$5:$J$301,'Hisob (batafsil)'!$B$5:$B$301,$A12,'Hisob (batafsil)'!$C$5:$C$301,"Shisha devor") -> 123.75 | D12: =SUMIFS('Hisob (batafsil)'!$G$5:$G$301,'Hisob (batafsil)'!$B$5:$B$301,$A12,'Hisob (batafsil)'!$C$5:$C$301,"Gips karton (GKL)") -> 17.875 | E12: =SUMIFS('Hisob (batafsil)'!$J$5:$J$301,'Hisob (batafsil)'!$B$5:$B$301,$A12,'Hisob (batafsil)'!$C$5:$C$301,"Gips karton (GKL)") -> 214.5 | F12: =SUMIFS('Hisob (batafsil)'!$G$5:$G$301,'Hisob (batafsil)'!$B$5:$B$301,$A12,'Hisob (batafsil)'!$C$5:$C$301,"Bambuk panel") -> 53.9 | G12: =SUMIFS('Hisob (batafsil)'!$J$5:$J$301,'Hisob (batafsil)'!$B$5:$B$301,$A12,'Hisob (batafsil)'!$C$5:$C$301,"Bambuk panel") -> 835.45 | H12: =SUMIFS('Hisob (batafsil)'!$G$5:$G$301,'Hisob (batafsil)'!$B$5:$B$301,$A12,'Hisob (batafsil)'!$C$5:$C$301,"Interaktiv doska") -> 1 | I12: =SUMIFS('Hisob (batafsil)'!$J$5:$J$301,'Hisob (batafsil)'!$B$5:$B$301,$A12,'Hisob (batafsil)'!$C$5:$C$301,"Interaktiv doska") -> 1032 | J12: =SUMIFS('Hisob (batafsil)'!$G$5:$G$301,'Hisob (batafsil)'!$B$5:$B$301,$A12,'Hisob (batafsil)'!$C$5:$C$301,"Perila") -> 0 | K12: =SUMIFS('Hisob (batafsil)'!$J$5:$J$301,'Hisob (batafsil)'!$B$5:$B$301,$A12,'Hisob (batafsil)'!$C$5:$C$301,"Perila") -> 0 | L12: =SUMIFS('Hisob (batafsil)'!$J$5:$J$301,'Hisob (batafsil)'!$B$5:$B$301,$A12,'Hisob (batafsil)'!$C$5:$C$301,"Yoritish") -> 168 | M12: =SUMIFS('Hisob (batafsil)'!$J$5:$J$301,'Hisob (batafsil)'!$B$5:$B$301,$A12,'Hisob (batafsil)'!$C$5:$C$301,"Kamera tizimi") -> 0 | N12: =SUMIFS('Hisob (batafsil)'!$J$5:$J$301,'Hisob (batafsil)'!$B$5:$B$301,$A12,'Hisob (batafsil)'!$C$5:$C$301,"Logotip") -> 0 | O12: =SUMIFS('Hisob (batafsil)'!$J$5:$J$301,'Hisob (batafsil)'!$B$5:$B$301,$A12,'Hisob (batafsil)'!$C$5:$C$301,"Matli plyonka") -> 0 | P12: =SUMIFS('Hisob (batafsil)'!$J$5:$J$301,'Hisob (batafsil)'!$B$5:$B$301,$A12,'Hisob (batafsil)'!$C$5:$C$301,"Yong'in xavfsizligi") -> 0 | Q12: =SUMIFS('Hisob (batafsil)'!$J$5:$J$301,'Hisob (batafsil)'!$B$5:$B$301,$A12,'Hisob (batafsil)'!$C$5:$C$301,"Buzish ishlari") -> 0 | R12: =SUMIFS('Hisob (batafsil)'!$J$5:$J$301,'Hisob (batafsil)'!$B$5:$B$301,$A12,'Hisob (batafsil)'!$C$5:$C$301,"Santexnika") -> 0 | S12: =SUMIFS('Hisob (batafsil)'!$J$5:$J$301,'Hisob (batafsil)'!$B$5:$B$301,$A12,'Hisob (batafsil)'!$C$5:$C$301,"Kafel") -> 0 | T12: =SUMIFS('Hisob (batafsil)'!$J$5:$J$301,'Hisob (batafsil)'!$B$5:$B$301,$A12,'Hisob (batafsil)'!$C$5:$C$301,"Konditsioner va ventilyatsiya") -> 0 | U12: =SUMIFS('Hisob (batafsil)'!$J$5:$J$301,'Hisob (batafsil)'!$B$5:$B$301,$A12,'Hisob (batafsil)'!$C$5:$C$301,"Mebel va interyer") -> 0 | V12: =SUMIFS('Hisob (batafsil)'!$J$5:$J$301,'Hisob (batafsil)'!$B$5:$B$301,$A12,'Hisob (batafsil)'!$C$5:$C$301,"E'lon va e'tirof doskalari") -> 0 | W12: =C12+E12+G12+I12+K12+L12+M12+N12+O12+P12+Q12+R12+S12+T12+U12+V12 -> 2373.7
A13: 4-xona | B13: =SUMIFS('Hisob (batafsil)'!$G$5:$G$301,'Hisob (batafsil)'!$B$5:$B$301,$A13,'Hisob (batafsil)'!$C$5:$C$301,"Shisha devor") -> 2.25 | C13: =SUMIFS('Hisob (batafsil)'!$J$5:$J$301,'Hisob (batafsil)'!$B$5:$B$301,$A13,'Hisob (batafsil)'!$C$5:$C$301,"Shisha devor") -> 123.75 | D13: =SUMIFS('Hisob (batafsil)'!$G$5:$G$301,'Hisob (batafsil)'!$B$5:$B$301,$A13,'Hisob (batafsil)'!$C$5:$C$301,"Gips karton (GKL)") -> 52 | E13: =SUMIFS('Hisob (batafsil)'!$J$5:$J$301,'Hisob (batafsil)'!$B$5:$B$301,$A13,'Hisob (batafsil)'!$C$5:$C$301,"Gips karton (GKL)") -> 624 | F13: =SUMIFS('Hisob (batafsil)'!$G$5:$G$301,'Hisob (batafsil)'!$B$5:$B$301,$A13,'Hisob (batafsil)'!$C$5:$C$301,"Bambuk panel") -> 50.4 | G13: =SUMIFS('Hisob (batafsil)'!$J$5:$J$301,'Hisob (batafsil)'!$B$5:$B$301,$A13,'Hisob (batafsil)'!$C$5:$C$301,"Bambuk panel") -> 781.2 | H13: =SUMIFS('Hisob (batafsil)'!$G$5:$G$301,'Hisob (batafsil)'!$B$5:$B$301,$A13,'Hisob (batafsil)'!$C$5:$C$301,"Interaktiv doska") -> 1 | I13: =SUMIFS('Hisob (batafsil)'!$J$5:$J$301,'Hisob (batafsil)'!$B$5:$B$301,$A13,'Hisob (batafsil)'!$C$5:$C$301,"Interaktiv doska") -> 1032 | J13: =SUMIFS('Hisob (batafsil)'!$G$5:$G$301,'Hisob (batafsil)'!$B$5:$B$301,$A13,'Hisob (batafsil)'!$C$5:$C$301,"Perila") -> 0 | K13: =SUMIFS('Hisob (batafsil)'!$J$5:$J$301,'Hisob (batafsil)'!$B$5:$B$301,$A13,'Hisob (batafsil)'!$C$5:$C$301,"Perila") -> 0 | L13: =SUMIFS('Hisob (batafsil)'!$J$5:$J$301,'Hisob (batafsil)'!$B$5:$B$301,$A13,'Hisob (batafsil)'!$C$5:$C$301,"Yoritish") -> 168 | M13: =SUMIFS('Hisob (batafsil)'!$J$5:$J$301,'Hisob (batafsil)'!$B$5:$B$301,$A13,'Hisob (batafsil)'!$C$5:$C$301,"Kamera tizimi") -> 0 | N13: =SUMIFS('Hisob (batafsil)'!$J$5:$J$301,'Hisob (batafsil)'!$B$5:$B$301,$A13,'Hisob (batafsil)'!$C$5:$C$301,"Logotip") -> 0 | O13: =SUMIFS('Hisob (batafsil)'!$J$5:$J$301,'Hisob (batafsil)'!$B$5:$B$301,$A13,'Hisob (batafsil)'!$C$5:$C$301,"Matli plyonka") -> 0 | P13: =SUMIFS('Hisob (batafsil)'!$J$5:$J$301,'Hisob (batafsil)'!$B$5:$B$301,$A13,'Hisob (batafsil)'!$C$5:$C$301,"Yong'in xavfsizligi") -> 0 | Q13: =SUMIFS('Hisob (batafsil)'!$J$5:$J$301,'Hisob (batafsil)'!$B$5:$B$301,$A13,'Hisob (batafsil)'!$C$5:$C$301,"Buzish ishlari") -> 0 | R13: =SUMIFS('Hisob (batafsil)'!$J$5:$J$301,'Hisob (batafsil)'!$B$5:$B$301,$A13,'Hisob (batafsil)'!$C$5:$C$301,"Santexnika") -> 0 | S13: =SUMIFS('Hisob (batafsil)'!$J$5:$J$301,'Hisob (batafsil)'!$B$5:$B$301,$A13,'Hisob (batafsil)'!$C$5:$C$301,"Kafel") -> 0 | T13: =SUMIFS('Hisob (batafsil)'!$J$5:$J$301,'Hisob (batafsil)'!$B$5:$B$301,$A13,'Hisob (batafsil)'!$C$5:$C$301,"Konditsioner va ventilyatsiya") -> 0 | U13: =SUMIFS('Hisob (batafsil)'!$J$5:$J$301,'Hisob (batafsil)'!$B$5:$B$301,$A13,'Hisob (batafsil)'!$C$5:$C$301,"Mebel va interyer") -> 0 | V13: =SUMIFS('Hisob (batafsil)'!$J$5:$J$301,'Hisob (batafsil)'!$B$5:$B$301,$A13,'Hisob (batafsil)'!$C$5:$C$301,"E'lon va e'tirof doskalari") -> 0 | W13: =C13+E13+G13+I13+K13+L13+M13+N13+O13+P13+Q13+R13+S13+T13+U13+V13 -> 2728.95
A14: 5-xona | B14: =SUMIFS('Hisob (batafsil)'!$G$5:$G$301,'Hisob (batafsil)'!$B$5:$B$301,$A14,'Hisob (batafsil)'!$C$5:$C$301,"Shisha devor") -> 2.25 | C14: =SUMIFS('Hisob (batafsil)'!$J$5:$J$301,'Hisob (batafsil)'!$B$5:$B$301,$A14,'Hisob (batafsil)'!$C$5:$C$301,"Shisha devor") -> 123.75 | D14: =SUMIFS('Hisob (batafsil)'!$G$5:$G$301,'Hisob (batafsil)'!$B$5:$B$301,$A14,'Hisob (batafsil)'!$C$5:$C$301,"Gips karton (GKL)") -> 27.5 | E14: =SUMIFS('Hisob (batafsil)'!$J$5:$J$301,'Hisob (batafsil)'!$B$5:$B$301,$A14,'Hisob (batafsil)'!$C$5:$C$301,"Gips karton (GKL)") -> 330 | F14: =SUMIFS('Hisob (batafsil)'!$G$5:$G$301,'Hisob (batafsil)'!$B$5:$B$301,$A14,'Hisob (batafsil)'!$C$5:$C$301,"Bambuk panel") -> 53.9 | G14: =SUMIFS('Hisob (batafsil)'!$J$5:$J$301,'Hisob (batafsil)'!$B$5:$B$301,$A14,'Hisob (batafsil)'!$C$5:$C$301,"Bambuk panel") -> 835.45 | H14: =SUMIFS('Hisob (batafsil)'!$G$5:$G$301,'Hisob (batafsil)'!$B$5:$B$301,$A14,'Hisob (batafsil)'!$C$5:$C$301,"Interaktiv doska") -> 1 | I14: =SUMIFS('Hisob (batafsil)'!$J$5:$J$301,'Hisob (batafsil)'!$B$5:$B$301,$A14,'Hisob (batafsil)'!$C$5:$C$301,"Interaktiv doska") -> 1032 | J14: =SUMIFS('Hisob (batafsil)'!$G$5:$G$301,'Hisob (batafsil)'!$B$5:$B$301,$A14,'Hisob (batafsil)'!$C$5:$C$301,"Perila") -> 0 | K14: =SUMIFS('Hisob (batafsil)'!$J$5:$J$301,'Hisob (batafsil)'!$B$5:$B$301,$A14,'Hisob (batafsil)'!$C$5:$C$301,"Perila") -> 0 | L14: =SUMIFS('Hisob (batafsil)'!$J$5:$J$301,'Hisob (batafsil)'!$B$5:$B$301,$A14,'Hisob (batafsil)'!$C$5:$C$301,"Yoritish") -> 168 | M14: =SUMIFS('Hisob (batafsil)'!$J$5:$J$301,'Hisob (batafsil)'!$B$5:$B$301,$A14,'Hisob (batafsil)'!$C$5:$C$301,"Kamera tizimi") -> 0 | N14: =SUMIFS('Hisob (batafsil)'!$J$5:$J$301,'Hisob (batafsil)'!$B$5:$B$301,$A14,'Hisob (batafsil)'!$C$5:$C$301,"Logotip") -> 0 | O14: =SUMIFS('Hisob (batafsil)'!$J$5:$J$301,'Hisob (batafsil)'!$B$5:$B$301,$A14,'Hisob (batafsil)'!$C$5:$C$301,"Matli plyonka") -> 0 | P14: =SUMIFS('Hisob (batafsil)'!$J$5:$J$301,'Hisob (batafsil)'!$B$5:$B$301,$A14,'Hisob (batafsil)'!$C$5:$C$301,"Yong'in xavfsizligi") -> 0 | Q14: =SUMIFS('Hisob (batafsil)'!$J$5:$J$301,'Hisob (batafsil)'!$B$5:$B$301,$A14,'Hisob (batafsil)'!$C$5:$C$301,"Buzish ishlari") -> 0 | R14: =SUMIFS('Hisob (batafsil)'!$J$5:$J$301,'Hisob (batafsil)'!$B$5:$B$301,$A14,'Hisob (batafsil)'!$C$5:$C$301,"Santexnika") -> 0 | S14: =SUMIFS('Hisob (batafsil)'!$J$5:$J$301,'Hisob (batafsil)'!$B$5:$B$301,$A14,'Hisob (batafsil)'!$C$5:$C$301,"Kafel") -> 0 | T14: =SUMIFS('Hisob (batafsil)'!$J$5:$J$301,'Hisob (batafsil)'!$B$5:$B$301,$A14,'Hisob (batafsil)'!$C$5:$C$301,"Konditsioner va ventilyatsiya") -> 0 | U14: =SUMIFS('Hisob (batafsil)'!$J$5:$J$301,'Hisob (batafsil)'!$B$5:$B$301,$A14,'Hisob (batafsil)'!$C$5:$C$301,"Mebel va interyer") -> 0 | V14: =SUMIFS('Hisob (batafsil)'!$J$5:$J$301,'Hisob (batafsil)'!$B$5:$B$301,$A14,'Hisob (batafsil)'!$C$5:$C$301,"E'lon va e'tirof doskalari") -> 0 | W14: =C14+E14+G14+I14+K14+L14+M14+N14+O14+P14+Q14+R14+S14+T14+U14+V14 -> 2489.2
A15: 6-xona | B15: =SUMIFS('Hisob (batafsil)'!$G$5:$G$301,'Hisob (batafsil)'!$B$5:$B$301,$A15,'Hisob (batafsil)'!$C$5:$C$301,"Shisha devor") -> 14 | C15: =SUMIFS('Hisob (batafsil)'!$J$5:$J$301,'Hisob (batafsil)'!$B$5:$B$301,$A15,'Hisob (batafsil)'!$C$5:$C$301,"Shisha devor") -> 770 | D15: =SUMIFS('Hisob (batafsil)'!$G$5:$G$301,'Hisob (batafsil)'!$B$5:$B$301,$A15,'Hisob (batafsil)'!$C$5:$C$301,"Gips karton (GKL)") -> 25.55 | E15: =SUMIFS('Hisob (batafsil)'!$J$5:$J$301,'Hisob (batafsil)'!$B$5:$B$301,$A15,'Hisob (batafsil)'!$C$5:$C$301,"Gips karton (GKL)") -> 306.6 | F15: =SUMIFS('Hisob (batafsil)'!$G$5:$G$301,'Hisob (batafsil)'!$B$5:$B$301,$A15,'Hisob (batafsil)'!$C$5:$C$301,"Bambuk panel") -> 53.9 | G15: =SUMIFS('Hisob (batafsil)'!$J$5:$J$301,'Hisob (batafsil)'!$B$5:$B$301,$A15,'Hisob (batafsil)'!$C$5:$C$301,"Bambuk panel") -> 835.45 | H15: =SUMIFS('Hisob (batafsil)'!$G$5:$G$301,'Hisob (batafsil)'!$B$5:$B$301,$A15,'Hisob (batafsil)'!$C$5:$C$301,"Interaktiv doska") -> 1 | I15: =SUMIFS('Hisob (batafsil)'!$J$5:$J$301,'Hisob (batafsil)'!$B$5:$B$301,$A15,'Hisob (batafsil)'!$C$5:$C$301,"Interaktiv doska") -> 1032 | J15: =SUMIFS('Hisob (batafsil)'!$G$5:$G$301,'Hisob (batafsil)'!$B$5:$B$301,$A15,'Hisob (batafsil)'!$C$5:$C$301,"Perila") -> 0 | K15: =SUMIFS('Hisob (batafsil)'!$J$5:$J$301,'Hisob (batafsil)'!$B$5:$B$301,$A15,'Hisob (batafsil)'!$C$5:$C$301,"Perila") -> 0 | L15: =SUMIFS('Hisob (batafsil)'!$J$5:$J$301,'Hisob (batafsil)'!$B$5:$B$301,$A15,'Hisob (batafsil)'!$C$5:$C$301,"Yoritish") -> 168 | M15: =SUMIFS('Hisob (batafsil)'!$J$5:$J$301,'Hisob (batafsil)'!$B$5:$B$301,$A15,'Hisob (batafsil)'!$C$5:$C$301,"Kamera tizimi") -> 0 | N15: =SUMIFS('Hisob (batafsil)'!$J$5:$J$301,'Hisob (batafsil)'!$B$5:$B$301,$A15,'Hisob (batafsil)'!$C$5:$C$301,"Logotip") -> 0 | O15: =SUMIFS('Hisob (batafsil)'!$J$5:$J$301,'Hisob (batafsil)'!$B$5:$B$301,$A15,'Hisob (batafsil)'!$C$5:$C$301,"Matli plyonka") -> 0 | P15: =SUMIFS('Hisob (batafsil)'!$J$5:$J$301,'Hisob (batafsil)'!$B$5:$B$301,$A15,'Hisob (batafsil)'!$C$5:$C$301,"Yong'in xavfsizligi") -> 0 | Q15: =SUMIFS('Hisob (batafsil)'!$J$5:$J$301,'Hisob (batafsil)'!$B$5:$B$301,$A15,'Hisob (batafsil)'!$C$5:$C$301,"Buzish ishlari") -> 0 | R15: =SUMIFS('Hisob (batafsil)'!$J$5:$J$301,'Hisob (batafsil)'!$B$5:$B$301,$A15,'Hisob (batafsil)'!$C$5:$C$301,"Santexnika") -> 0 | S15: =SUMIFS('Hisob (batafsil)'!$J$5:$J$301,'Hisob (batafsil)'!$B$5:$B$301,$A15,'Hisob (batafsil)'!$C$5:$C$301,"Kafel") -> 0 | T15: =SUMIFS('Hisob (batafsil)'!$J$5:$J$301,'Hisob (batafsil)'!$B$5:$B$301,$A15,'Hisob (batafsil)'!$C$5:$C$301,"Konditsioner va ventilyatsiya") -> 0 | U15: =SUMIFS('Hisob (batafsil)'!$J$5:$J$301,'Hisob (batafsil)'!$B$5:$B$301,$A15,'Hisob (batafsil)'!$C$5:$C$301,"Mebel va interyer") -> 0 | V15: =SUMIFS('Hisob (batafsil)'!$J$5:$J$301,'Hisob (batafsil)'!$B$5:$B$301,$A15,'Hisob (batafsil)'!$C$5:$C$301,"E'lon va e'tirof doskalari") -> 0 | W15: =C15+E15+G15+I15+K15+L15+M15+N15+O15+P15+Q15+R15+S15+T15+U15+V15 -> 3112.05
A16: 7-xona | B16: =SUMIFS('Hisob (batafsil)'!$G$5:$G$301,'Hisob (batafsil)'!$B$5:$B$301,$A16,'Hisob (batafsil)'!$C$5:$C$301,"Shisha devor") -> 14 | C16: =SUMIFS('Hisob (batafsil)'!$J$5:$J$301,'Hisob (batafsil)'!$B$5:$B$301,$A16,'Hisob (batafsil)'!$C$5:$C$301,"Shisha devor") -> 770 | D16: =SUMIFS('Hisob (batafsil)'!$G$5:$G$301,'Hisob (batafsil)'!$B$5:$B$301,$A16,'Hisob (batafsil)'!$C$5:$C$301,"Gips karton (GKL)") -> 30.45 | E16: =SUMIFS('Hisob (batafsil)'!$J$5:$J$301,'Hisob (batafsil)'!$B$5:$B$301,$A16,'Hisob (batafsil)'!$C$5:$C$301,"Gips karton (GKL)") -> 365.4 | F16: =SUMIFS('Hisob (batafsil)'!$G$5:$G$301,'Hisob (batafsil)'!$B$5:$B$301,$A16,'Hisob (batafsil)'!$C$5:$C$301,"Bambuk panel") -> 53.9 | G16: =SUMIFS('Hisob (batafsil)'!$J$5:$J$301,'Hisob (batafsil)'!$B$5:$B$301,$A16,'Hisob (batafsil)'!$C$5:$C$301,"Bambuk panel") -> 835.45 | H16: =SUMIFS('Hisob (batafsil)'!$G$5:$G$301,'Hisob (batafsil)'!$B$5:$B$301,$A16,'Hisob (batafsil)'!$C$5:$C$301,"Interaktiv doska") -> 1 | I16: =SUMIFS('Hisob (batafsil)'!$J$5:$J$301,'Hisob (batafsil)'!$B$5:$B$301,$A16,'Hisob (batafsil)'!$C$5:$C$301,"Interaktiv doska") -> 1032 | J16: =SUMIFS('Hisob (batafsil)'!$G$5:$G$301,'Hisob (batafsil)'!$B$5:$B$301,$A16,'Hisob (batafsil)'!$C$5:$C$301,"Perila") -> 0 | K16: =SUMIFS('Hisob (batafsil)'!$J$5:$J$301,'Hisob (batafsil)'!$B$5:$B$301,$A16,'Hisob (batafsil)'!$C$5:$C$301,"Perila") -> 0 | L16: =SUMIFS('Hisob (batafsil)'!$J$5:$J$301,'Hisob (batafsil)'!$B$5:$B$301,$A16,'Hisob (batafsil)'!$C$5:$C$301,"Yoritish") -> 168 | M16: =SUMIFS('Hisob (batafsil)'!$J$5:$J$301,'Hisob (batafsil)'!$B$5:$B$301,$A16,'Hisob (batafsil)'!$C$5:$C$301,"Kamera tizimi") -> 0 | N16: =SUMIFS('Hisob (batafsil)'!$J$5:$J$301,'Hisob (batafsil)'!$B$5:$B$301,$A16,'Hisob (batafsil)'!$C$5:$C$301,"Logotip") -> 0 | O16: =SUMIFS('Hisob (batafsil)'!$J$5:$J$301,'Hisob (batafsil)'!$B$5:$B$301,$A16,'Hisob (batafsil)'!$C$5:$C$301,"Matli plyonka") -> 0 | P16: =SUMIFS('Hisob (batafsil)'!$J$5:$J$301,'Hisob (batafsil)'!$B$5:$B$301,$A16,'Hisob (batafsil)'!$C$5:$C$301,"Yong'in xavfsizligi") -> 0 | Q16: =SUMIFS('Hisob (batafsil)'!$J$5:$J$301,'Hisob (batafsil)'!$B$5:$B$301,$A16,'Hisob (batafsil)'!$C$5:$C$301,"Buzish ishlari") -> 0 | R16: =SUMIFS('Hisob (batafsil)'!$J$5:$J$301,'Hisob (batafsil)'!$B$5:$B$301,$A16,'Hisob (batafsil)'!$C$5:$C$301,"Santexnika") -> 0 | S16: =SUMIFS('Hisob (batafsil)'!$J$5:$J$301,'Hisob (batafsil)'!$B$5:$B$301,$A16,'Hisob (batafsil)'!$C$5:$C$301,"Kafel") -> 0 | T16: =SUMIFS('Hisob (batafsil)'!$J$5:$J$301,'Hisob (batafsil)'!$B$5:$B$301,$A16,'Hisob (batafsil)'!$C$5:$C$301,"Konditsioner va ventilyatsiya") -> 0 | U16: =SUMIFS('Hisob (batafsil)'!$J$5:$J$301,'Hisob (batafsil)'!$B$5:$B$301,$A16,'Hisob (batafsil)'!$C$5:$C$301,"Mebel va interyer") -> 0 | V16: =SUMIFS('Hisob (batafsil)'!$J$5:$J$301,'Hisob (batafsil)'!$B$5:$B$301,$A16,'Hisob (batafsil)'!$C$5:$C$301,"E'lon va e'tirof doskalari") -> 0 | W16: =C16+E16+G16+I16+K16+L16+M16+N16+O16+P16+Q16+R16+S16+T16+U16+V16 -> 3170.85
A17: 2-qavat: o'quv xonalari — jami | B17: =SUM(B10:B16) -> 62.5 | C17: =SUM(C10:C16) -> 3437.5 | D17: =SUM(D10:D16) -> 166.925 | E17: =SUM(E10:E16) -> 2003.1 | F17: =SUM(F10:F16) -> 373.8 | G17: =SUM(G10:G16) -> 5793.9 | H17: =SUM(H10:H16) -> 7 | I17: =SUM(I10:I16) -> 7224 | ... W17: =SUM(W10:W16) -> 19634.5
A19: 2-qavat: ofis xonalari
A20: Offline sotuv (XZ1) | B20: =SUMIFS('Hisob (batafsil)'!$G$5:$G$301,'Hisob (batafsil)'!$B$5:$B$301,$A20,'Hisob (batafsil)'!$C$5:$C$301,"Shisha devor") -> 7 | C20: =SUMIFS('Hisob (batafsil)'!$J$5:$J$301,'Hisob (batafsil)'!$B$5:$B$301,$A20,'Hisob (batafsil)'!$C$5:$C$301,"Shisha devor") -> 385 | D20: =SUMIFS('Hisob (batafsil)'!$G$5:$G$301,'Hisob (batafsil)'!$B$5:$B$301,$A20,'Hisob (batafsil)'!$C$5:$C$301,"Gips karton (GKL)") -> 34.3 | E20: =SUMIFS('Hisob (batafsil)'!$J$5:$J$301,'Hisob (batafsil)'!$B$5:$B$301,$A20,'Hisob (batafsil)'!$C$5:$C$301,"Gips karton (GKL)") -> 411.6 | F20: =SUMIFS('Hisob (batafsil)'!$G$5:$G$301,'Hisob (batafsil)'!$B$5:$B$301,$A20,'Hisob (batafsil)'!$C$5:$C$301,"Bambuk panel") -> 39.2 | G20: =SUMIFS('Hisob (batafsil)'!$J$5:$J$301,'Hisob (batafsil)'!$B$5:$B$301,$A20,'Hisob (batafsil)'!$C$5:$C$301,"Bambuk panel") -> 607.6 | H20: =SUMIFS('Hisob (batafsil)'!$G$5:$G$301,'Hisob (batafsil)'!$B$5:$B$301,$A20,'Hisob (batafsil)'!$C$5:$C$301,"Interaktiv doska") -> 0 | I20: =SUMIFS('Hisob (batafsil)'!$J$5:$J$301,'Hisob (batafsil)'!$B$5:$B$301,$A20,'Hisob (batafsil)'!$C$5:$C$301,"Interaktiv doska") -> 0 | J20: =SUMIFS('Hisob (batafsil)'!$G$5:$G$301,'Hisob (batafsil)'!$B$5:$B$301,$A20,'Hisob (batafsil)'!$C$5:$C$301,"Perila") -> 0 | K20: =SUMIFS('Hisob (batafsil)'!$J$5:$J$301,'Hisob (batafsil)'!$B$5:$B$301,$A20,'Hisob (batafsil)'!$C$5:$C$301,"Perila") -> 0 | L20: =SUMIFS('Hisob (batafsil)'!$J$5:$J$301,'Hisob (batafsil)'!$B$5:$B$301,$A20,'Hisob (batafsil)'!$C$5:$C$301,"Yoritish") -> 168 | M20: =SUMIFS('Hisob (batafsil)'!$J$5:$J$301,'Hisob (batafsil)'!$B$5:$B$301,$A20,'Hisob (batafsil)'!$C$5:$C$301,"Kamera tizimi") -> 0 | N20: =SUMIFS('Hisob (batafsil)'!$J$5:$J$301,'Hisob (batafsil)'!$B$5:$B$301,$A20,'Hisob (batafsil)'!$C$5:$C$301,"Logotip") -> 0 | O20: =SUMIFS('Hisob (batafsil)'!$J$5:$J$301,'Hisob (batafsil)'!$B$5:$B$301,$A20,'Hisob (batafsil)'!$C$5:$C$301,"Matli plyonka") -> 0 | P20: =SUMIFS('Hisob (batafsil)'!$J$5:$J$301,'Hisob (batafsil)'!$B$5:$B$301,$A20,'Hisob (batafsil)'!$C$5:$C$301,"Yong'in xavfsizligi") -> 0 | Q20: =SUMIFS('Hisob (batafsil)'!$J$5:$J$301,'Hisob (batafsil)'!$B$5:$B$301,$A20,'Hisob (batafsil)'!$C$5:$C$301,"Buzish ishlari") -> 0 | R20: =SUMIFS('Hisob (batafsil)'!$J$5:$J$301,'Hisob (batafsil)'!$B$5:$B$301,$A20,'Hisob (batafsil)'!$C$5:$C$301,"Santexnika") -> 0 | S20: =SUMIFS('Hisob (batafsil)'!$J$5:$J$301,'Hisob (batafsil)'!$B$5:$B$301,$A20,'Hisob (batafsil)'!$C$5:$C$301,"Kafel") -> 0 | T20: =SUMIFS('Hisob (batafsil)'!$J$5:$J$301,'Hisob (batafsil)'!$B$5:$B$301,$A20,'Hisob (batafsil)'!$C$5:$C$301,"Konditsioner va ventilyatsiya") -> 0 | U20: =SUMIFS('Hisob (batafsil)'!$J$5:$J$301,'Hisob (batafsil)'!$B$5:$B$301,$A20,'Hisob (batafsil)'!$C$5:$C$301,"Mebel va interyer") -> 2340 | V20: =SUMIFS('Hisob (batafsil)'!$J$5:$J$301,'Hisob (batafsil)'!$B$5:$B$301,$A20,'Hisob (batafsil)'!$C$5:$C$301,"E'lon va e'tirof doskalari") -> 0 | W20: =C20+E20+G20+I20+K20+L20+M20+N20+O20+P20+Q20+R20+S20+T20+U20+V20 -> 3912.2
A21: Admin (XZ2) | B21: =SUMIFS('Hisob (batafsil)'!$G$5:$G$301,'Hisob (batafsil)'!$B$5:$B$301,$A21,'Hisob (batafsil)'!$C$5:$C$301,"Shisha devor") -> 7 | C21: =SUMIFS('Hisob (batafsil)'!$J$5:$J$301,'Hisob (batafsil)'!$B$5:$B$301,$A21,'Hisob (batafsil)'!$C$5:$C$301,"Shisha devor") -> 385 | D21: =SUMIFS('Hisob (batafsil)'!$G$5:$G$301,'Hisob (batafsil)'!$B$5:$B$301,$A21,'Hisob (batafsil)'!$C$5:$C$301,"Gips karton (GKL)") -> 35.35 | E21: =SUMIFS('Hisob (batafsil)'!$J$5:$J$301,'Hisob (batafsil)'!$B$5:$B$301,$A21,'Hisob (batafsil)'!$C$5:$C$301,"Gips karton (GKL)") -> 424.2 | F21: =SUMIFS('Hisob (batafsil)'!$G$5:$G$301,'Hisob (batafsil)'!$B$5:$B$301,$A21,'Hisob (batafsil)'!$C$5:$C$301,"Bambuk panel") -> 39.2 | G21: =SUMIFS('Hisob (batafsil)'!$J$5:$J$301,'Hisob (batafsil)'!$B$5:$B$301,$A21,'Hisob (batafsil)'!$C$5:$C$301,"Bambuk panel") -> 607.6 | H21: =SUMIFS('Hisob (batafsil)'!$G$5:$G$301,'Hisob (batafsil)'!$B$5:$B$301,$A21,'Hisob (batafsil)'!$C$5:$C$301,"Interaktiv doska") -> 0 | I21: =SUMIFS('Hisob (batafsil)'!$J$5:$J$301,'Hisob (batafsil)'!$B$5:$B$301,$A21,'Hisob (batafsil)'!$C$5:$C$301,"Interaktiv doska") -> 0 | J21: =SUMIFS('Hisob (batafsil)'!$G$5:$G$301,'Hisob (batafsil)'!$B$5:$B$301,$A21,'Hisob (batafsil)'!$C$5:$C$301,"Perila") -> 0 | K21: =SUMIFS('Hisob (batafsil)'!$J$5:$J$301,'Hisob (batafsil)'!$B$5:$B$301,$A21,'Hisob (batafsil)'!$C$5:$C$301,"Perila") -> 0 | L21: =SUMIFS('Hisob (batafsil)'!$J$5:$J$301,'Hisob (batafsil)'!$B$5:$B$301,$A21,'Hisob (batafsil)'!$C$5:$C$301,"Yoritish") -> 168 | M21: =SUMIFS('Hisob (batafsil)'!$J$5:$J$301,'Hisob (batafsil)'!$B$5:$B$301,$A21,'Hisob (batafsil)'!$C$5:$C$301,"Kamera tizimi") -> 0 | N21: =SUMIFS('Hisob (batafsil)'!$J$5:$J$301,'Hisob (batafsil)'!$B$5:$B$301,$A21,'Hisob (batafsil)'!$C$5:$C$301,"Logotip") -> 0 | O21: =SUMIFS('Hisob (batafsil)'!$J$5:$J$301,'Hisob (batafsil)'!$B$5:$B$301,$A21,'Hisob (batafsil)'!$C$5:$C$301,"Matli plyonka") -> 0 | P21: =SUMIFS('Hisob (batafsil)'!$J$5:$J$301,'Hisob (batafsil)'!$B$5:$B$301,$A21,'Hisob (batafsil)'!$C$5:$C$301,"Yong'in xavfsizligi") -> 0 | Q21: =SUMIFS('Hisob (batafsil)'!$J$5:$J$301,'Hisob (batafsil)'!$B$5:$B$301,$A21,'Hisob (batafsil)'!$C$5:$C$301,"Buzish ishlari") -> 0 | R21: =SUMIFS('Hisob (batafsil)'!$J$5:$J$301,'Hisob (batafsil)'!$B$5:$B$301,$A21,'Hisob (batafsil)'!$C$5:$C$301,"Santexnika") -> 0 | S21: =SUMIFS('Hisob (batafsil)'!$J$5:$J$301,'Hisob (batafsil)'!$B$5:$B$301,$A21,'Hisob (batafsil)'!$C$5:$C$301,"Kafel") -> 0 | T21: =SUMIFS('Hisob (batafsil)'!$J$5:$J$301,'Hisob (batafsil)'!$B$5:$B$301,$A21,'Hisob (batafsil)'!$C$5:$C$301,"Konditsioner va ventilyatsiya") -> 0 | U21: =SUMIFS('Hisob (batafsil)'!$J$5:$J$301,'Hisob (batafsil)'!$B$5:$B$301,$A21,'Hisob (batafsil)'!$C$5:$C$301,"Mebel va interyer") -> 1470 | V21: =SUMIFS('Hisob (batafsil)'!$J$5:$J$301,'Hisob (batafsil)'!$B$5:$B$301,$A21,'Hisob (batafsil)'!$C$5:$C$301,"E'lon va e'tirof doskalari") -> 0 | W21: =C21+E21+G21+I21+K21+L21+M21+N21+O21+P21+Q21+R21+S21+T21+U21+V21 -> 3054.8
A22: Ustozlar xonasi (XZ3) | B22: =SUMIFS('Hisob (batafsil)'!$G$5:$G$301,'Hisob (batafsil)'!$B$5:$B$301,$A22,'Hisob (batafsil)'!$C$5:$C$301,"Shisha devor") -> 7.125 | C22: =SUMIFS('Hisob (batafsil)'!$J$5:$J$301,'Hisob (batafsil)'!$B$5:$B$301,$A22,'Hisob (batafsil)'!$C$5:$C$301,"Shisha devor") -> 391.875 | D22: =SUMIFS('Hisob (batafsil)'!$G$5:$G$301,'Hisob (batafsil)'!$B$5:$B$301,$A22,'Hisob (batafsil)'!$C$5:$C$301,"Gips karton (GKL)") -> 35.575 | E22: =SUMIFS('Hisob (batafsil)'!$J$5:$J$301,'Hisob (batafsil)'!$B$5:$B$301,$A22,'Hisob (batafsil)'!$C$5:$C$301,"Gips karton (GKL)") -> 426.9 | F22: =SUMIFS('Hisob (batafsil)'!$G$5:$G$301,'Hisob (batafsil)'!$B$5:$B$301,$A22,'Hisob (batafsil)'!$C$5:$C$301,"Bambuk panel") -> 39.2 | G22: =SUMIFS('Hisob (batafsil)'!$J$5:$J$301,'Hisob (batafsil)'!$B$5:$B$301,$A22,'Hisob (batafsil)'!$C$5:$C$301,"Bambuk panel") -> 607.6 | H22: =SUMIFS('Hisob (batafsil)'!$G$5:$G$301,'Hisob (batafsil)'!$B$5:$B$301,$A22,'Hisob (batafsil)'!$C$5:$C$301,"Interaktiv doska") -> 0 | I22: =SUMIFS('Hisob (batafsil)'!$J$5:$J$301,'Hisob (batafsil)'!$B$5:$B$301,$A22,'Hisob (batafsil)'!$C$5:$C$301,"Interaktiv doska") -> 0 | J22: =SUMIFS('Hisob (batafsil)'!$G$5:$G$301,'Hisob (batafsil)'!$B$5:$B$301,$A22,'Hisob (batafsil)'!$C$5:$C$301,"Perila") -> 0 | K22: =SUMIFS('Hisob (batafsil)'!$J$5:$J$301,'Hisob (batafsil)'!$B$5:$B$301,$A22,'Hisob (batafsil)'!$C$5:$C$301,"Perila") -> 0 | L22: =SUMIFS('Hisob (batafsil)'!$J$5:$J$301,'Hisob (batafsil)'!$B$5:$B$301,$A22,'Hisob (batafsil)'!$C$5:$C$301,"Yoritish") -> 168 | M22: =SUMIFS('Hisob (batafsil)'!$J$5:$J$301,'Hisob (batafsil)'!$B$5:$B$301,$A22,'Hisob (batafsil)'!$C$5:$C$301,"Kamera tizimi") -> 0 | N22: =SUMIFS('Hisob (batafsil)'!$J$5:$J$301,'Hisob (batafsil)'!$B$5:$B$301,$A22,'Hisob (batafsil)'!$C$5:$C$301,"Logotip") -> 0 | O22: =SUMIFS('Hisob (batafsil)'!$J$5:$J$301,'Hisob (batafsil)'!$B$5:$B$301,$A22,'Hisob (batafsil)'!$C$5:$C$301,"Matli plyonka") -> 0 | P22: =SUMIFS('Hisob (batafsil)'!$J$5:$J$301,'Hisob (batafsil)'!$B$5:$B$301,$A22,'Hisob (batafsil)'!$C$5:$C$301,"Yong'in xavfsizligi") -> 0 | Q22: =SUMIFS('Hisob (batafsil)'!$J$5:$J$301,'Hisob (batafsil)'!$B$5:$B$301,$A22,'Hisob (batafsil)'!$C$5:$C$301,"Buzish ishlari") -> 0 | R22: =SUMIFS('Hisob (batafsil)'!$J$5:$J$301,'Hisob (batafsil)'!$B$5:$B$301,$A22,'Hisob (batafsil)'!$C$5:$C$301,"Santexnika") -> 0 | S22: =SUMIFS('Hisob (batafsil)'!$J$5:$J$301,'Hisob (batafsil)'!$B$5:$B$301,$A22,'Hisob (batafsil)'!$C$5:$C$301,"Kafel") -> 0 | T22: =SUMIFS('Hisob (batafsil)'!$J$5:$J$301,'Hisob (batafsil)'!$B$5:$B$301,$A22,'Hisob (batafsil)'!$C$5:$C$301,"Konditsioner va ventilyatsiya") -> 0 | U22: =SUMIFS('Hisob (batafsil)'!$J$5:$J$301,'Hisob (batafsil)'!$B$5:$B$301,$A22,'Hisob (batafsil)'!$C$5:$C$301,"Mebel va interyer") -> 0 | V22: =SUMIFS('Hisob (batafsil)'!$J$5:$J$301,'Hisob (batafsil)'!$B$5:$B$301,$A22,'Hisob (batafsil)'!$C$5:$C$301,"E'lon va e'tirof doskalari") -> 0 | W22: =C22+E22+G22+I22+K22+L22+M22+N22+O22+P22+Q22+R22+S22+T22+U22+V22 -> 1594.375
A23: Call-markaz (XZ4) | B23: =SUMIFS('Hisob (batafsil)'!$G$5:$G$301,'Hisob (batafsil)'!$B$5:$B$301,$A23,'Hisob (batafsil)'!$C$5:$C$301,"Shisha devor") -> 7.125 | C23: =SUMIFS('Hisob (batafsil)'!$J$5:$J$301,'Hisob (batafsil)'!$B$5:$B$301,$A23,'Hisob (batafsil)'!$C$5:$C$301,"Shisha devor") -> 391.875 | D23: =SUMIFS('Hisob (batafsil)'!$G$5:$G$301,'Hisob (batafsil)'!$B$5:$B$301,$A23,'Hisob (batafsil)'!$C$5:$C$301,"Gips karton (GKL)") -> 35.925 | E23: =SUMIFS('Hisob (batafsil)'!$J$5:$J$301,'Hisob (batafsil)'!$B$5:$B$301,$A23,'Hisob (batafsil)'!$C$5:$C$301,"Gips karton (GKL)") -> 431.1 | F23: =SUMIFS('Hisob (batafsil)'!$G$5:$G$301,'Hisob (batafsil)'!$B$5:$B$301,$A23,'Hisob (batafsil)'!$C$5:$C$301,"Bambuk panel") -> 39.2 | G23: =SUMIFS('Hisob (batafsil)'!$J$5:$J$301,'Hisob (batafsil)'!$B$5:$B$301,$A23,'Hisob (batafsil)'!$C$5:$C$301,"Bambuk panel") -> 607.6 | H23: =SUMIFS('Hisob (batafsil)'!$G$5:$G$301,'Hisob (batafsil)'!$B$5:$B$301,$A23,'Hisob (batafsil)'!$C$5:$C$301,"Interaktiv doska") -> 0 | I23: =SUMIFS('Hisob (batafsil)'!$J$5:$J$301,'Hisob (batafsil)'!$B$5:$B$301,$A23,'Hisob (batafsil)'!$C$5:$C$301,"Interaktiv doska") -> 0 | J23: =SUMIFS('Hisob (batafsil)'!$G$5:$G$301,'Hisob (batafsil)'!$B$5:$B$301,$A23,'Hisob (batafsil)'!$C$5:$C$301,"Perila") -> 0 | K23: =SUMIFS('Hisob (batafsil)'!$J$5:$J$301,'Hisob (batafsil)'!$B$5:$B$301,$A23,'Hisob (batafsil)'!$C$5:$C$301,"Perila") -> 0 | L23: =SUMIFS('Hisob (batafsil)'!$J$5:$J$301,'Hisob (batafsil)'!$B$5:$B$301,$A23,'Hisob (batafsil)'!$C$5:$C$301,"Yoritish") -> 168 | M23: =SUMIFS('Hisob (batafsil)'!$J$5:$J$301,'Hisob (batafsil)'!$B$5:$B$301,$A23,'Hisob (batafsil)'!$C$5:$C$301,"Kamera tizimi") -> 0 | N23: =SUMIFS('Hisob (batafsil)'!$J$5:$J$301,'Hisob (batafsil)'!$B$5:$B$301,$A23,'Hisob (batafsil)'!$C$5:$C$301,"Logotip") -> 0 | O23: =SUMIFS('Hisob (batafsil)'!$J$5:$J$301,'Hisob (batafsil)'!$B$5:$B$301,$A23,'Hisob (batafsil)'!$C$5:$C$301,"Matli plyonka") -> 0 | P23: =SUMIFS('Hisob (batafsil)'!$J$5:$J$301,'Hisob (batafsil)'!$B$5:$B$301,$A23,'Hisob (batafsil)'!$C$5:$C$301,"Yong'in xavfsizligi") -> 0 | Q23: =SUMIFS('Hisob (batafsil)'!$J$5:$J$301,'Hisob (batafsil)'!$B$5:$B$301,$A23,'Hisob (batafsil)'!$C$5:$C$301,"Buzish ishlari") -> 0 | R23: =SUMIFS('Hisob (batafsil)'!$J$5:$J$301,'Hisob (batafsil)'!$B$5:$B$301,$A23,'Hisob (batafsil)'!$C$5:$C$301,"Santexnika") -> 0 | S23: =SUMIFS('Hisob (batafsil)'!$J$5:$J$301,'Hisob (batafsil)'!$B$5:$B$301,$A23,'Hisob (batafsil)'!$C$5:$C$301,"Kafel") -> 0 | T23: =SUMIFS('Hisob (batafsil)'!$J$5:$J$301,'Hisob (batafsil)'!$B$5:$B$301,$A23,'Hisob (batafsil)'!$C$5:$C$301,"Konditsioner va ventilyatsiya") -> 0 | U23: =SUMIFS('Hisob (batafsil)'!$J$5:$J$301,'Hisob (batafsil)'!$B$5:$B$301,$A23,'Hisob (batafsil)'!$C$5:$C$301,"Mebel va interyer") -> 0 | V23: =SUMIFS('Hisob (batafsil)'!$J$5:$J$301,'Hisob (batafsil)'!$B$5:$B$301,$A23,'Hisob (batafsil)'!$C$5:$C$301,"E'lon va e'tirof doskalari") -> 0 | W23: =C23+E23+G23+I23+K23+L23+M23+N23+O23+P23+Q23+R23+S23+T23+U23+V23 -> 1598.575
A24: CEO xonasi (12-xona) | B24: =SUMIFS('Hisob (batafsil)'!$G$5:$G$301,'Hisob (batafsil)'!$B$5:$B$301,$A24,'Hisob (batafsil)'!$C$5:$C$301,"Shisha devor") -> 0 | C24: =SUMIFS('Hisob (batafsil)'!$J$5:$J$301,'Hisob (batafsil)'!$B$5:$B$301,$A24,'Hisob (batafsil)'!$C$5:$C$301,"Shisha devor") -> 0 | D24: =SUMIFS('Hisob (batafsil)'!$G$5:$G$301,'Hisob (batafsil)'!$B$5:$B$301,$A24,'Hisob (batafsil)'!$C$5:$C$301,"Gips karton (GKL)") -> 0 | E24: =SUMIFS('Hisob (batafsil)'!$J$5:$J$301,'Hisob (batafsil)'!$B$5:$B$301,$A24,'Hisob (batafsil)'!$C$5:$C$301,"Gips karton (GKL)") -> 0 | F24: =SUMIFS('Hisob (batafsil)'!$G$5:$G$301,'Hisob (batafsil)'!$B$5:$B$301,$A24,'Hisob (batafsil)'!$C$5:$C$301,"Bambuk panel") -> 29.26 | G24: =SUMIFS('Hisob (batafsil)'!$J$5:$J$301,'Hisob (batafsil)'!$B$5:$B$301,$A24,'Hisob (batafsil)'!$C$5:$C$301,"Bambuk panel") -> 453.53 | H24: =SUMIFS('Hisob (batafsil)'!$G$5:$G$301,'Hisob (batafsil)'!$B$5:$B$301,$A24,'Hisob (batafsil)'!$C$5:$C$301,"Interaktiv doska") -> 0 | I24: =SUMIFS('Hisob (batafsil)'!$J$5:$J$301,'Hisob (batafsil)'!$B$5:$B$301,$A24,'Hisob (batafsil)'!$C$5:$C$301,"Interaktiv doska") -> 0 | J24: =SUMIFS('Hisob (batafsil)'!$G$5:$G$301,'Hisob (batafsil)'!$B$5:$B$301,$A24,'Hisob (batafsil)'!$C$5:$C$301,"Perila") -> 0 | K24: =SUMIFS('Hisob (batafsil)'!$J$5:$J$301,'Hisob (batafsil)'!$B$5:$B$301,$A24,'Hisob (batafsil)'!$C$5:$C$301,"Perila") -> 0 | L24: =SUMIFS('Hisob (batafsil)'!$J$5:$J$301,'Hisob (batafsil)'!$B$5:$B$301,$A24,'Hisob (batafsil)'!$C$5:$C$301,"Yoritish") -> 168 | M24: =SUMIFS('Hisob (batafsil)'!$J$5:$J$301,'Hisob (batafsil)'!$B$5:$B$301,$A24,'Hisob (batafsil)'!$C$5:$C$301,"Kamera tizimi") -> 0 | N24: =SUMIFS('Hisob (batafsil)'!$J$5:$J$301,'Hisob (batafsil)'!$B$5:$B$301,$A24,'Hisob (batafsil)'!$C$5:$C$301,"Logotip") -> 0 | O24: =SUMIFS('Hisob (batafsil)'!$J$5:$J$301,'Hisob (batafsil)'!$B$5:$B$301,$A24,'Hisob (batafsil)'!$C$5:$C$301,"Matli plyonka") -> 0 | P24: =SUMIFS('Hisob (batafsil)'!$J$5:$J$301,'Hisob (batafsil)'!$B$5:$B$301,$A24,'Hisob (batafsil)'!$C$5:$C$301,"Yong'in xavfsizligi") -> 0 | Q24: =SUMIFS('Hisob (batafsil)'!$J$5:$J$301,'Hisob (batafsil)'!$B$5:$B$301,$A24,'Hisob (batafsil)'!$C$5:$C$301,"Buzish ishlari") -> 0 | R24: =SUMIFS('Hisob (batafsil)'!$J$5:$J$301,'Hisob (batafsil)'!$B$5:$B$301,$A24,'Hisob (batafsil)'!$C$5:$C$301,"Santexnika") -> 0 | S24: =SUMIFS('Hisob (batafsil)'!$J$5:$J$301,'Hisob (batafsil)'!$B$5:$B$301,$A24,'Hisob (batafsil)'!$C$5:$C$301,"Kafel") -> 0 | T24: =SUMIFS('Hisob (batafsil)'!$J$5:$J$301,'Hisob (batafsil)'!$B$5:$B$301,$A24,'Hisob (batafsil)'!$C$5:$C$301,"Konditsioner va ventilyatsiya") -> 0 | U24: =SUMIFS('Hisob (batafsil)'!$J$5:$J$301,'Hisob (batafsil)'!$B$5:$B$301,$A24,'Hisob (batafsil)'!$C$5:$C$301,"Mebel va interyer") -> 0 | V24: =SUMIFS('Hisob (batafsil)'!$J$5:$J$301,'Hisob (batafsil)'!$B$5:$B$301,$A24,'Hisob (batafsil)'!$C$5:$C$301,"E'lon va e'tirof doskalari") -> 0 | W24: =C24+E24+G24+I24+K24+L24+M24+N24+O24+P24+Q24+R24+S24+T24+U24+V24 -> 621.53
A25: 2-qavat: ofis xonalari — jami | B25: =SUM(B20:B24) -> 28.25 | C25: =SUM(C20:C24) -> 1553.75 | D25: =SUM(D20:D24) -> 141.15 | E25: =SUM(E20:E24) -> 1693.8 | F25: =SUM(F20:F24) -> 186.06 | G25: =SUM(G20:G24) -> 2883.93 | H25: =SUM(H20:H24) -> 0 | I25: =SUM(I20:I24) -> 0 | ... W25: =SUM(W20:W24) -> 10781.48
A27: 2-qavat: umumiy joylar
A28: K1 koridori | B28: =SUMIFS('Hisob (batafsil)'!$G$5:$G$301,'Hisob (batafsil)'!$B$5:$B$301,$A28,'Hisob (batafsil)'!$C$5:$C$301,"Shisha devor") -> 0 | C28: =SUMIFS('Hisob (batafsil)'!$J$5:$J$301,'Hisob (batafsil)'!$B$5:$B$301,$A28,'Hisob (batafsil)'!$C$5:$C$301,"Shisha devor") -> 0 | D28: =SUMIFS('Hisob (batafsil)'!$G$5:$G$301,'Hisob (batafsil)'!$B$5:$B$301,$A28,'Hisob (batafsil)'!$C$5:$C$301,"Gips karton (GKL)") -> 52 | E28: =SUMIFS('Hisob (batafsil)'!$J$5:$J$301,'Hisob (batafsil)'!$B$5:$B$301,$A28,'Hisob (batafsil)'!$C$5:$C$301,"Gips karton (GKL)") -> 624 | F28: =SUMIFS('Hisob (batafsil)'!$G$5:$G$301,'Hisob (batafsil)'!$B$5:$B$301,$A28,'Hisob (batafsil)'!$C$5:$C$301,"Bambuk panel") -> 0 | G28: =SUMIFS('Hisob (batafsil)'!$J$5:$J$301,'Hisob (batafsil)'!$B$5:$B$301,$A28,'Hisob (batafsil)'!$C$5:$C$301,"Bambuk panel") -> 0 | H28: =SUMIFS('Hisob (batafsil)'!$G$5:$G$301,'Hisob (batafsil)'!$B$5:$B$301,$A28,'Hisob (batafsil)'!$C$5:$C$301,"Interaktiv doska") -> 0 | I28: =SUMIFS('Hisob (batafsil)'!$J$5:$J$301,'Hisob (batafsil)'!$B$5:$B$301,$A28,'Hisob (batafsil)'!$C$5:$C$301,"Interaktiv doska") -> 0 | J28: =SUMIFS('Hisob (batafsil)'!$G$5:$G$301,'Hisob (batafsil)'!$B$5:$B$301,$A28,'Hisob (batafsil)'!$C$5:$C$301,"Perila") -> 0 | K28: =SUMIFS('Hisob (batafsil)'!$J$5:$J$301,'Hisob (batafsil)'!$B$5:$B$301,$A28,'Hisob (batafsil)'!$C$5:$C$301,"Perila") -> 0 | L28: =SUMIFS('Hisob (batafsil)'!$J$5:$J$301,'Hisob (batafsil)'!$B$5:$B$301,$A28,'Hisob (batafsil)'!$C$5:$C$301,"Yoritish") -> 336 | M28: =SUMIFS('Hisob (batafsil)'!$J$5:$J$301,'Hisob (batafsil)'!$B$5:$B$301,$A28,'Hisob (batafsil)'!$C$5:$C$301,"Kamera tizimi") -> 0 | N28: =SUMIFS('Hisob (batafsil)'!$J$5:$J$301,'Hisob (batafsil)'!$B$5:$B$301,$A28,'Hisob (batafsil)'!$C$5:$C$301,"Logotip") -> 0 | O28: =SUMIFS('Hisob (batafsil)'!$J$5:$J$301,'Hisob (batafsil)'!$B$5:$B$301,$A28,'Hisob (batafsil)'!$C$5:$C$301,"Matli plyonka") -> 0 | P28: =SUMIFS('Hisob (batafsil)'!$J$5:$J$301,'Hisob (batafsil)'!$B$5:$B$301,$A28,'Hisob (batafsil)'!$C$5:$C$301,"Yong'in xavfsizligi") -> 0 | Q28: =SUMIFS('Hisob (batafsil)'!$J$5:$J$301,'Hisob (batafsil)'!$B$5:$B$301,$A28,'Hisob (batafsil)'!$C$5:$C$301,"Buzish ishlari") -> 0 | R28: =SUMIFS('Hisob (batafsil)'!$J$5:$J$301,'Hisob (batafsil)'!$B$5:$B$301,$A28,'Hisob (batafsil)'!$C$5:$C$301,"Santexnika") -> 0 | S28: =SUMIFS('Hisob (batafsil)'!$J$5:$J$301,'Hisob (batafsil)'!$B$5:$B$301,$A28,'Hisob (batafsil)'!$C$5:$C$301,"Kafel") -> 0 | T28: =SUMIFS('Hisob (batafsil)'!$J$5:$J$301,'Hisob (batafsil)'!$B$5:$B$301,$A28,'Hisob (batafsil)'!$C$5:$C$301,"Konditsioner va ventilyatsiya") -> 0 | U28: =SUMIFS('Hisob (batafsil)'!$J$5:$J$301,'Hisob (batafsil)'!$B$5:$B$301,$A28,'Hisob (batafsil)'!$C$5:$C$301,"Mebel va interyer") -> 0 | V28: =SUMIFS('Hisob (batafsil)'!$J$5:$J$301,'Hisob (batafsil)'!$B$5:$B$301,$A28,'Hisob (batafsil)'!$C$5:$C$301,"E'lon va e'tirof doskalari") -> 370 | W28: =C28+E28+G28+I28+K28+L28+M28+N28+O28+P28+Q28+R28+S28+T28+U28+V28 -> 1330
A29: K2 koridori | B29: =SUMIFS('Hisob (batafsil)'!$G$5:$G$301,'Hisob (batafsil)'!$B$5:$B$301,$A29,'Hisob (batafsil)'!$C$5:$C$301,"Shisha devor") -> 0 | C29: =SUMIFS('Hisob (batafsil)'!$J$5:$J$301,'Hisob (batafsil)'!$B$5:$B$301,$A29,'Hisob (batafsil)'!$C$5:$C$301,"Shisha devor") -> 0 | D29: =SUMIFS('Hisob (batafsil)'!$G$5:$G$301,'Hisob (batafsil)'!$B$5:$B$301,$A29,'Hisob (batafsil)'!$C$5:$C$301,"Gips karton (GKL)") -> 50.1 | E29: =SUMIFS('Hisob (batafsil)'!$J$5:$J$301,'Hisob (batafsil)'!$B$5:$B$301,$A29,'Hisob (batafsil)'!$C$5:$C$301,"Gips karton (GKL)") -> 601.2 | F29: =SUMIFS('Hisob (batafsil)'!$G$5:$G$301,'Hisob (batafsil)'!$B$5:$B$301,$A29,'Hisob (batafsil)'!$C$5:$C$301,"Bambuk panel") -> 0 | G29: =SUMIFS('Hisob (batafsil)'!$J$5:$J$301,'Hisob (batafsil)'!$B$5:$B$301,$A29,'Hisob (batafsil)'!$C$5:$C$301,"Bambuk panel") -> 0 | H29: =SUMIFS('Hisob (batafsil)'!$G$5:$G$301,'Hisob (batafsil)'!$B$5:$B$301,$A29,'Hisob (batafsil)'!$C$5:$C$301,"Interaktiv doska") -> 0 | I29: =SUMIFS('Hisob (batafsil)'!$J$5:$J$301,'Hisob (batafsil)'!$B$5:$B$301,$A29,'Hisob (batafsil)'!$C$5:$C$301,"Interaktiv doska") -> 0 | J29: =SUMIFS('Hisob (batafsil)'!$G$5:$G$301,'Hisob (batafsil)'!$B$5:$B$301,$A29,'Hisob (batafsil)'!$C$5:$C$301,"Perila") -> 0 | K29: =SUMIFS('Hisob (batafsil)'!$J$5:$J$301,'Hisob (batafsil)'!$B$5:$B$301,$A29,'Hisob (batafsil)'!$C$5:$C$301,"Perila") -> 0 | L29: =SUMIFS('Hisob (batafsil)'!$J$5:$J$301,'Hisob (batafsil)'!$B$5:$B$301,$A29,'Hisob (batafsil)'!$C$5:$C$301,"Yoritish") -> 336 | M29: =SUMIFS('Hisob (batafsil)'!$J$5:$J$301,'Hisob (batafsil)'!$B$5:$B$301,$A29,'Hisob (batafsil)'!$C$5:$C$301,"Kamera tizimi") -> 0 | N29: =SUMIFS('Hisob (batafsil)'!$J$5:$J$301,'Hisob (batafsil)'!$B$5:$B$301,$A29,'Hisob (batafsil)'!$C$5:$C$301,"Logotip") -> 0 | O29: =SUMIFS('Hisob (batafsil)'!$J$5:$J$301,'Hisob (batafsil)'!$B$5:$B$301,$A29,'Hisob (batafsil)'!$C$5:$C$301,"Matli plyonka") -> 0 | P29: =SUMIFS('Hisob (batafsil)'!$J$5:$J$301,'Hisob (batafsil)'!$B$5:$B$301,$A29,'Hisob (batafsil)'!$C$5:$C$301,"Yong'in xavfsizligi") -> 0 | Q29: =SUMIFS('Hisob (batafsil)'!$J$5:$J$301,'Hisob (batafsil)'!$B$5:$B$301,$A29,'Hisob (batafsil)'!$C$5:$C$301,"Buzish ishlari") -> 0 | R29: =SUMIFS('Hisob (batafsil)'!$J$5:$J$301,'Hisob (batafsil)'!$B$5:$B$301,$A29,'Hisob (batafsil)'!$C$5:$C$301,"Santexnika") -> 0 | S29: =SUMIFS('Hisob (batafsil)'!$J$5:$J$301,'Hisob (batafsil)'!$B$5:$B$301,$A29,'Hisob (batafsil)'!$C$5:$C$301,"Kafel") -> 0 | T29: =SUMIFS('Hisob (batafsil)'!$J$5:$J$301,'Hisob (batafsil)'!$B$5:$B$301,$A29,'Hisob (batafsil)'!$C$5:$C$301,"Konditsioner va ventilyatsiya") -> 0 | U29: =SUMIFS('Hisob (batafsil)'!$J$5:$J$301,'Hisob (batafsil)'!$B$5:$B$301,$A29,'Hisob (batafsil)'!$C$5:$C$301,"Mebel va interyer") -> 0 | V29: =SUMIFS('Hisob (batafsil)'!$J$5:$J$301,'Hisob (batafsil)'!$B$5:$B$301,$A29,'Hisob (batafsil)'!$C$5:$C$301,"E'lon va e'tirof doskalari") -> 370 | W29: =C29+E29+G29+I29+K29+L29+M29+N29+O29+P29+Q29+R29+S29+T29+U29+V29 -> 1307.2
A30: Koworking zali | B30: =SUMIFS('Hisob (batafsil)'!$G$5:$G$301,'Hisob (batafsil)'!$B$5:$B$301,$A30,'Hisob (batafsil)'!$C$5:$C$301,"Shisha devor") -> 0 | C30: =SUMIFS('Hisob (batafsil)'!$J$5:$J$301,'Hisob (batafsil)'!$B$5:$B$301,$A30,'Hisob (batafsil)'!$C$5:$C$301,"Shisha devor") -> 0 | D30: =SUMIFS('Hisob (batafsil)'!$G$5:$G$301,'Hisob (batafsil)'!$B$5:$B$301,$A30,'Hisob (batafsil)'!$C$5:$C$301,"Gips karton (GKL)") -> 9.625 | E30: =SUMIFS('Hisob (batafsil)'!$J$5:$J$301,'Hisob (batafsil)'!$B$5:$B$301,$A30,'Hisob (batafsil)'!$C$5:$C$301,"Gips karton (GKL)") -> 115.5 | F30: =SUMIFS('Hisob (batafsil)'!$G$5:$G$301,'Hisob (batafsil)'!$B$5:$B$301,$A30,'Hisob (batafsil)'!$C$5:$C$301,"Bambuk panel") -> 0 | G30: =SUMIFS('Hisob (batafsil)'!$J$5:$J$301,'Hisob (batafsil)'!$B$5:$B$301,$A30,'Hisob (batafsil)'!$C$5:$C$301,"Bambuk panel") -> 0 | H30: =SUMIFS('Hisob (batafsil)'!$G$5:$G$301,'Hisob (batafsil)'!$B$5:$B$301,$A30,'Hisob (batafsil)'!$C$5:$C$301,"Interaktiv doska") -> 0 | I30: =SUMIFS('Hisob (batafsil)'!$J$5:$J$301,'Hisob (batafsil)'!$B$5:$B$301,$A30,'Hisob (batafsil)'!$C$5:$C$301,"Interaktiv doska") -> 0 | J30: =SUMIFS('Hisob (batafsil)'!$G$5:$G$301,'Hisob (batafsil)'!$B$5:$B$301,$A30,'Hisob (batafsil)'!$C$5:$C$301,"Perila") -> 0 | K30: =SUMIFS('Hisob (batafsil)'!$J$5:$J$301,'Hisob (batafsil)'!$B$5:$B$301,$A30,'Hisob (batafsil)'!$C$5:$C$301,"Perila") -> 0 | L30: =SUMIFS('Hisob (batafsil)'!$J$5:$J$301,'Hisob (batafsil)'!$B$5:$B$301,$A30,'Hisob (batafsil)'!$C$5:$C$301,"Yoritish") -> 336 | M30: =SUMIFS('Hisob (batafsil)'!$J$5:$J$301,'Hisob (batafsil)'!$B$5:$B$301,$A30,'Hisob (batafsil)'!$C$5:$C$301,"Kamera tizimi") -> 0 | N30: =SUMIFS('Hisob (batafsil)'!$J$5:$J$301,'Hisob (batafsil)'!$B$5:$B$301,$A30,'Hisob (batafsil)'!$C$5:$C$301,"Logotip") -> 0 | O30: =SUMIFS('Hisob (batafsil)'!$J$5:$J$301,'Hisob (batafsil)'!$B$5:$B$301,$A30,'Hisob (batafsil)'!$C$5:$C$301,"Matli plyonka") -> 0 | P30: =SUMIFS('Hisob (batafsil)'!$J$5:$J$301,'Hisob (batafsil)'!$B$5:$B$301,$A30,'Hisob (batafsil)'!$C$5:$C$301,"Yong'in xavfsizligi") -> 0 | Q30: =SUMIFS('Hisob (batafsil)'!$J$5:$J$301,'Hisob (batafsil)'!$B$5:$B$301,$A30,'Hisob (batafsil)'!$C$5:$C$301,"Buzish ishlari") -> 0 | R30: =SUMIFS('Hisob (batafsil)'!$J$5:$J$301,'Hisob (batafsil)'!$B$5:$B$301,$A30,'Hisob (batafsil)'!$C$5:$C$301,"Santexnika") -> 0 | S30: =SUMIFS('Hisob (batafsil)'!$J$5:$J$301,'Hisob (batafsil)'!$B$5:$B$301,$A30,'Hisob (batafsil)'!$C$5:$C$301,"Kafel") -> 0 | T30: =SUMIFS('Hisob (batafsil)'!$J$5:$J$301,'Hisob (batafsil)'!$B$5:$B$301,$A30,'Hisob (batafsil)'!$C$5:$C$301,"Konditsioner va ventilyatsiya") -> 0 | U30: =SUMIFS('Hisob (batafsil)'!$J$5:$J$301,'Hisob (batafsil)'!$B$5:$B$301,$A30,'Hisob (batafsil)'!$C$5:$C$301,"Mebel va interyer") -> 0 | V30: =SUMIFS('Hisob (batafsil)'!$J$5:$J$301,'Hisob (batafsil)'!$B$5:$B$301,$A30,'Hisob (batafsil)'!$C$5:$C$301,"E'lon va e'tirof doskalari") -> 0 | W30: =C30+E30+G30+I30+K30+L30+M30+N30+O30+P30+Q30+R30+S30+T30+U30+V30 -> 451.5
A31: Kirish zali | B31: =SUMIFS('Hisob (batafsil)'!$G$5:$G$301,'Hisob (batafsil)'!$B$5:$B$301,$A31,'Hisob (batafsil)'!$C$5:$C$301,"Shisha devor") -> 0 | C31: =SUMIFS('Hisob (batafsil)'!$J$5:$J$301,'Hisob (batafsil)'!$B$5:$B$301,$A31,'Hisob (batafsil)'!$C$5:$C$301,"Shisha devor") -> 0 | D31: =SUMIFS('Hisob (batafsil)'!$G$5:$G$301,'Hisob (batafsil)'!$B$5:$B$301,$A31,'Hisob (batafsil)'!$C$5:$C$301,"Gips karton (GKL)") -> 9.1 | E31: =SUMIFS('Hisob (batafsil)'!$J$5:$J$301,'Hisob (batafsil)'!$B$5:$B$301,$A31,'Hisob (batafsil)'!$C$5:$C$301,"Gips karton (GKL)") -> 109.2 | F31: =SUMIFS('Hisob (batafsil)'!$G$5:$G$301,'Hisob (batafsil)'!$B$5:$B$301,$A31,'Hisob (batafsil)'!$C$5:$C$301,"Bambuk panel") -> 0 | G31: =SUMIFS('Hisob (batafsil)'!$J$5:$J$301,'Hisob (batafsil)'!$B$5:$B$301,$A31,'Hisob (batafsil)'!$C$5:$C$301,"Bambuk panel") -> 0 | H31: =SUMIFS('Hisob (batafsil)'!$G$5:$G$301,'Hisob (batafsil)'!$B$5:$B$301,$A31,'Hisob (batafsil)'!$C$5:$C$301,"Interaktiv doska") -> 0 | I31: =SUMIFS('Hisob (batafsil)'!$J$5:$J$301,'Hisob (batafsil)'!$B$5:$B$301,$A31,'Hisob (batafsil)'!$C$5:$C$301,"Interaktiv doska") -> 0 | J31: =SUMIFS('Hisob (batafsil)'!$G$5:$G$301,'Hisob (batafsil)'!$B$5:$B$301,$A31,'Hisob (batafsil)'!$C$5:$C$301,"Perila") -> 0 | K31: =SUMIFS('Hisob (batafsil)'!$J$5:$J$301,'Hisob (batafsil)'!$B$5:$B$301,$A31,'Hisob (batafsil)'!$C$5:$C$301,"Perila") -> 0 | L31: =SUMIFS('Hisob (batafsil)'!$J$5:$J$301,'Hisob (batafsil)'!$B$5:$B$301,$A31,'Hisob (batafsil)'!$C$5:$C$301,"Yoritish") -> 0 | M31: =SUMIFS('Hisob (batafsil)'!$J$5:$J$301,'Hisob (batafsil)'!$B$5:$B$301,$A31,'Hisob (batafsil)'!$C$5:$C$301,"Kamera tizimi") -> 0 | N31: =SUMIFS('Hisob (batafsil)'!$J$5:$J$301,'Hisob (batafsil)'!$B$5:$B$301,$A31,'Hisob (batafsil)'!$C$5:$C$301,"Logotip") -> 0 | O31: =SUMIFS('Hisob (batafsil)'!$J$5:$J$301,'Hisob (batafsil)'!$B$5:$B$301,$A31,'Hisob (batafsil)'!$C$5:$C$301,"Matli plyonka") -> 0 | P31: =SUMIFS('Hisob (batafsil)'!$J$5:$J$301,'Hisob (batafsil)'!$B$5:$B$301,$A31,'Hisob (batafsil)'!$C$5:$C$301,"Yong'in xavfsizligi") -> 0 | Q31: =SUMIFS('Hisob (batafsil)'!$J$5:$J$301,'Hisob (batafsil)'!$B$5:$B$301,$A31,'Hisob (batafsil)'!$C$5:$C$301,"Buzish ishlari") -> 0 | R31: =SUMIFS('Hisob (batafsil)'!$J$5:$J$301,'Hisob (batafsil)'!$B$5:$B$301,$A31,'Hisob (batafsil)'!$C$5:$C$301,"Santexnika") -> 0 | S31: =SUMIFS('Hisob (batafsil)'!$J$5:$J$301,'Hisob (batafsil)'!$B$5:$B$301,$A31,'Hisob (batafsil)'!$C$5:$C$301,"Kafel") -> 0 | T31: =SUMIFS('Hisob (batafsil)'!$J$5:$J$301,'Hisob (batafsil)'!$B$5:$B$301,$A31,'Hisob (batafsil)'!$C$5:$C$301,"Konditsioner va ventilyatsiya") -> 0 | U31: =SUMIFS('Hisob (batafsil)'!$J$5:$J$301,'Hisob (batafsil)'!$B$5:$B$301,$A31,'Hisob (batafsil)'!$C$5:$C$301,"Mebel va interyer") -> 0 | V31: =SUMIFS('Hisob (batafsil)'!$J$5:$J$301,'Hisob (batafsil)'!$B$5:$B$301,$A31,'Hisob (batafsil)'!$C$5:$C$301,"E'lon va e'tirof doskalari") -> 0 | W31: =C31+E31+G31+I31+K31+L31+M31+N31+O31+P31+Q31+R31+S31+T31+U31+V31 -> 109.2
